Workbook
Name rngApproaches: Ranges!$B$4:$H$4
Name rngBasicInfo: Input!$C$9:$C$11
Name rngCountInterval: Input!$I$9
Name rngExits: Ranges!$B$18:$H$24
Name rngMovements: Ranges!$B$8:$H$14
Name rngSurveyPeriods: Input!$I$12:$L$14
Name rngVehicleTypes: Input!$E$10:$F$16
Name Slicer_Survey_Period: #N/A
Name Slicer_Survey_Period1: #N/A

Sheet Input
B2: Turning Count Template
B4: Fill in blue cells. Leave blank if not required.
B7: Basic Info | E7: Vehicle Types | H7: Time Periods
B9: Intersection: | C9: Buchanans Road_Carmen Road_Intersection | E9: Vehicle Type | F9: HCV? | H9: Count Interval | I9: 15 | J9: minutes
B10: Conditions: | C10: Fine | D10: 1 | E10: Cars
B11: Date: | C11: 44971 | D11: 2 | E11: Other Vehicles | I11: Survey Period 1 | J11: Survey Period 2 | K11: Survey Period 3 | L11: Survey Period 4
D12: 3 | E12: Cyclists | H12: Name | I12: AM | J12: INT | K12: PM
C13: Note: do not use "/" in Intersection Name | D13: 4 | H13: Start Time | I13: 0.29166667 | J13: 0.54166667 | K13: 0.66666667
D14: 5 | H14: End Time | I14: 0.36458333 | J14: 0.57291667 | K14: 0.73958333
D15: 6
D16: 7
B18: Movements
B20: Approach 1 | C20: Carmen Road North
B22: Movement 1 | C22: Left into Buchanans Road East | D22: Exit to: | E22: Buchanans Road East
B23: Movement 2 | C23: Thru to Carmen Road South | D23: Exit to: | E23: Carmen Road South
B24: Movement 3 | C24: Right into Buchanans Road West | D24: Exit to: | E24: Buchanans Road West
B25: Movement 4 | C25: U-Turn | D25: Exit to: | E25: Carmen Road North
B26: Movement 5 | D26: Exit to:
B27: Movement 6 | D27: Exit to:
B28: Movement 7 | D28: Exit to:
B31: Approach 2 | C31: Buchanans Road East
B33: Movement 1 | C33: Left into Carmen Road South | D33: Exit to: | E33: Carmen Road South
B34: Movement 2 | C34: Thru to Buchanans Road West | D34: Exit to: | E34: Buchanans Road West
B35: Movement 3 | C35: Right into Carmen Road North | D35: Exit to: | E35: Carmen Road North
B36: Movement 4 | D36: Exit to:
B37: Movement 5 | D37: Exit to:
B38: Movement 6 | D38: Exit to:
B39: Movement 7 | D39: Exit to:
B42: Approach 3 | C42: Carmen Road South
B44: Movement 1 | C44: Left into Buchanans Road West | D44: Exit to: | E44: Buchanans Road West
B45: Movement 2 | C45: Thru to Carmen Road North | D45: Exit to: | E45: Carmen Road North
B46: Movement 3 | C46: Right into Buchanans Road East | D46: Exit to: | E46: Buchanans Road East
B47: Movement 4 | C47: U-Turn | D47: Exit to: | E47: Carmen Road South
B48: Movement 5 | D48: Exit to:
B49: Movement 6 | D49: Exit to:
B50: Movement 7 | D50: Exit to:
B53: Approach 4 | C53: Buchanans Road West
B55: Movement 1 | C55: Left into Carmen Road North | D55: Exit to: | E55: Carmen Road North
B56: Movement 2 | C56: Thru to Buchanans Road East | D56: Exit to: | E56: Buchanans Road East
B57: Movement 3 | C57: Right into Carmen Road South | D57: Exit to: | E57: Carmen Road South
...

Sheet Ranges
B2: Approaches
B4: =Input!C20 -> Carmen Road North | C4: =Input!C31 -> Buchanans Road East | D4: =Input!C42 -> Carmen Road South | E4: =Input!C53 -> Buchanans Road West | F4: =Input!C64 -> 0 | G4: =Input!C75 -> 0 | H4: =Input!C86 -> 0
B6: Movements
B8: =Input!C22 -> Left into Buchanans Road East | C8: =Input!C33 -> Left into Carmen Road South | D8: =Input!C44 -> Left into Buchanans Road West | E8: =Input!C55 -> Left into Carmen Road North | F8: =Input!C66 -> 0 | G8: =Input!C77 -> 0 | H8: =Input!C88 -> 0
B9: =Input!C23 -> Thru to Carmen Road South | C9: =Input!C34 -> Thru to Buchanans Road West | D9: =Input!C45 -> Thru to Carmen Road North | E9: =Input!C56 -> Thru to Buchanans Road East | F9: =Input!C67 -> 0 | G9: =Input!C78 -> 0 | H9: =Input!C89 -> 0
B10: =Input!C24 -> Right into Buchanans Road West | C10: =Input!C35 -> Right into Carmen Road North | D10: =Input!C46 -> Right into Buchanans Road East | E10: =Input!C57 -> Right into Carmen Road South | F10: =Input!C68 -> 0 | G10: =Input!C79 -> 0 | H10: =Input!C90 -> 0
B11: =Input!C25 -> U-Turn | C11: =Input!C36 -> 0 | D11: =Input!C47 -> U-Turn | E11: =Input!C58 -> 0 | F11: =Input!C69 -> 0 | G11: =Input!C80 -> 0 | H11: =Input!C91 -> 0
B12: =Input!C26 -> 0 | C12: =Input!C37 -> 0 | D12: =Input!C48 -> 0 | E12: =Input!C59 -> 0 | F12: =Input!C70 -> 0 | G12: =Input!C81 -> 0 | H12: =Input!C92 -> 0
B13: =Input!C27 -> 0 | C13: =Input!C38 -> 0 | D13: =Input!C49 -> 0 | E13: =Input!C60 -> 0 | F13: =Input!C71 -> 0 | G13: =Input!C82 -> 0 | H13: =Input!C93 -> 0
B14: =Input!C28 -> 0 | C14: =Input!C39 -> 0 | D14: =Input!C50 -> 0 | E14: =Input!C61 -> 0 | F14: =Input!C72 -> 0 | G14: =Input!C83 -> 0 | H14: =Input!C94 -> 0
B16: Exits
B18: =Input!E22 -> Buchanans Road East | C18: =Input!E33 -> Carmen Road South | D18: =Input!E44 -> Buchanans Road West | E18: =Input!E55 -> Carmen Road North | F18: =Input!E66 -> 0 | G18: =Input!E77 -> 0 | H18: =Input!E88 -> 0
B19: =Input!E23 -> Carmen Road South | C19: =Input!E34 -> Buchanans Road West | D19: =Input!E45 -> Carmen Road North | E19: =Input!E56 -> Buchanans Road East | F19: =Input!E67 -> 0 | G19: =Input!E78 -> 0 | H19: =Input!E89 -> 0
B20: =Input!E24 -> Buchanans Road West | C20: =Input!E35 -> Carmen Road North | D20: =Input!E46 -> Buchanans Road East | E20: =Input!E57 -> Carmen Road South | F20: =Input!E68 -> 0 | G20: =Input!E79 -> 0 | H20: =Input!E90 -> 0
B21: =Input!E25 -> Carmen Road North | C21: =Input!E36 -> 0 | D21: =Input!E47 -> Carmen Road South | E21: =Input!E58 -> 0 | F21: =Input!E69 -> 0 | G21: =Input!E80 -> 0 | H21: =Input!E91 -> 0
B22: =Input!E26 -> 0 | C22: =Input!E37 -> 0 | D22: =Input!E48 -> 0 | E22: =Input!E59 -> 0 | F22: =Input!E70 -> 0 | G22: =Input!E81 -> 0 | H22: =Input!E92 -> 0
B23: =Input!E27 -> 0 | C23: =Input!E38 -> 0 | D23: =Input!E49 -> 0 | E23: =Input!E60 -> 0 | F23: =Input!E71 -> 0 | G23: =Input!E82 -> 0 | H23: =Input!E93 -> 0
B24: =Input!E28 -> 0 | C24: =Input!E39 -> 0 | D24: =Input!E50 -> 0 | E24: =Input!E61 -> 0 | F24: =Input!E72 -> 0 | G24: =Input!E83 -> 0 | H24: =Input!E94 -> 0

Sheet Table
A1: Buchanans Road_Carmen Road_Intersection Fine 14/02/2023
C5: Carmen Road North | O5: Buchanans Road East | X5: Carmen Road South | AJ5: Buchanans Road West
C6: Left into Buchanans Road East | F6: Thru to Carmen Road South | I6: Right into Buchanans Road West | L6: U-Turn | O6: Left into Carmen Road South | R6: Thru to Buchanans Road West | U6: Right into Carmen Road North | X6: Left into Buchanans Road West | AA6: Thru to Carmen Road North | AD6: Right into Buchanans Road East | AG6: U-Turn | AJ6: Left into Carmen Road North | AM6: Thru to Buchanans Road East | AP6: Right into Carmen Road South
A7: Period | B7: Time | C7: Cars | D7: Other Vehicles | E7: Cyclists | F7: Cars | G7: Other Vehicles | H7: Cyclists | I7: Cars | J7: Other Vehicles | K7: Cyclists | L7: Cars | M7: Other Vehicles | N7: Cyclists | O7: Cars | P7: Other Vehicles | Q7: Cyclists | R7: Cars | S7: Other Vehicles | T7: Cyclists | U7: Cars | V7: Other Vehicles | W7: Cyclists | X7: Cars | Y7: Other Vehicles | Z7: Cyclists | AA7: Cars | AB7: Other Vehicles | AC7: Cyclists | AD7: Cars | AE7: Other Vehicles | AF7: Cyclists | AG7: Cars | AH7: Other Vehicles | AI7: Cyclists | AJ7: Cars | AK7: Other Vehicles | AL7: Cyclists | AM7: Cars | AN7: Other Vehicles | AO7: Cyclists | AP7: Cars | AQ7: Other Vehicles | AR7: Cyclists
A8: AM | B8: 0.29166667 | C8: 16 | D8: 1 | E8: 0 | F8: 262 | G8: 13 | H8: 0 | I8: 29 | J8: 2 | K8: 0 | L8: 0 | M8: 0 | N8: 0 | O8: 21 | P8: 1 | Q8: 0 | R8: 32 | S8: 2 | T8: 0 | U8: 17 | V8: 0 | W8: 0 | X8: 8 | Y8: 1 | Z8: 0 | AA8: 154 | AB8: 15 | AC8: 0 | AD8: 10 | AE8: 1 | AF8: 0 | AG8: 1 | AH8: 0 | AI8: 0 | AJ8: 37 | AK8: 7 | AL8: 0 | AM8: 55 | AN8: 3 | AO8: 1 | AP8: 15 | AQ8: 1 | AR8: 0
A9: AM | B9: 0.30208333 | C9: 26 | D9: 0 | E9: 0 | F9: 303 | G9: 21 | H9: 0 | I9: 33 | J9: 1 | K9: 0 | L9: 0 | M9: 0 | N9: 0 | O9: 21 | P9: 0 | Q9: 0 | R9: 24 | S9: 1 | T9: 0 | U9: 13 | V9: 2 | W9: 0 | X9: 12 | Y9: 0 | Z9: 0 | AA9: 193 | AB9: 17 | AC9: 0 | AD9: 22 | AE9: 2 | AF9: 0 | AG9: 2 | AH9: 0 | AI9: 0 | AJ9: 33 | AK9: 1 | AL9: 1 | AM9: 67 | AN9: 2 | AO9: 0 | AP9: 26 | AQ9: 1 | AR9: 0
A10: AM | B10: 0.3125 | C10: 18 | D10: 0 | E10: 0 | F10: 245 | G10: 12 | H10: 1 | I10: 36 | J10: 0 | K10: 0 | L10: 0 | M10: 0 | N10: 0 | O10: 17 | P10: 0 | Q10: 0 | R10: 37 | S10: 1 | T10: 0 | U10: 19 | V10: 2 | W10: 0 | X10: 6 | Y10: 1 | Z10: 0 | AA10: 208 | AB10: 18 | AC10: 1 | AD10: 12 | AE10: 2 | AF10: 0 | AG10: 0 | AH10: 0 | AI10: 0 | AJ10: 37 | AK10: 2 | AL10: 0 | AM10: 89 | AN10: 3 | AO10: 0 | AP10: 18 | AQ10: 2 | AR10: 0
A11: AM | B11: 0.32291667 | C11: 25 | D11: 0 | E11: 0 | F11: 298 | G11: 20 | H11: 2 | I11: 26 | J11: 1 | K11: 0 | L11: 0 | M11: 0 | N11: 0 | O11: 29 | P11: 1 | Q11: 0 | R11: 29 | S11: 2 | T11: 1 | U11: 13 | V11: 1 | W11: 0 | X11: 11 | Y11: 2 | Z11: 0 | AA11: 209 | AB11: 13 | AC11: 1 | AD11: 15 | AE11: 0 | AF11: 0 | AG11: 3 | AH11: 0 | AI11: 0 | AJ11: 23 | AK11: 2 | AL11: 0 | AM11: 67 | AN11: 3 | AO11: 0 | AP11: 36 | AQ11: 0 | AR11: 0
A12: AM | B12: 0.33333333 | C12: 15 | D12: 0 | E12: 0 | F12: 234 | G12: 19 | H12: 0 | I12: 30 | J12: 2 | K12: 0 | L12: 0 | M12: 0 | N12: 0 | O12: 24 | P12: 1 | Q12: 0 | R12: 28 | S12: 0 | T12: 0 | U12: 13 | V12: 2 | W12: 0 | X12: 10 | Y12: 2 | Z12: 0 | AA12: 208 | AB12: 14 | AC12: 2 | AD12: 22 | AE12: 1 | AF12: 0 | AG12: 3 | AH12: 0 | AI12: 0 | AJ12: 29 | AK12: 3 | AL12: 0 | AM12: 80 | AN12: 2 | AO12: 0 | AP12: 16 | AQ12: 2 | AR12: 1
A13: AM | B13: 0.34375 | C13: 20 | D13: 1 | E13: 0 | F13: 243 | G13: 18 | H13: 0 | I13: 41 | J13: 0 | K13: 0 | L13: 0 | M13: 0 | N13: 0 | O13: 28 | P13: 0 | Q13: 0 | R13: 43 | S13: 5 | T13: 0 | U13: 14 | V13: 3 | W13: 0 | X13: 25 | Y13: 0 | Z13: 0 | AA13: 200 | AB13: 13 | AC13: 0 | AD13: 16 | AE13: 1 | AF13: 0 | AG13: 4 | AH13: 0 | AI13: 0 | AJ13: 26 | AK13: 3 | AL13: 0 | AM13: 65 | AN13: 1 | AO13: 0 | AP13: 22 | AQ13: 4 | AR13: 0
A14: AM | B14: 0.35416667 | C14: 24 | D14: 1 | E14: 0 | F14: 236 | G14: 22 | H14: 0 | I14: 30 | J14: 2 | K14: 0 | L14: 0 | M14: 0 | N14: 0 | O14: 24 | P14: 3 | Q14: 0 | R14: 36 | S14: 4 | T14: 0 | U14: 11 | V14: 2 | W14: 0 | X14: 22 | Y14: 1 | Z14: 0 | AA14: 224 | AB14: 30 | AC14: 0 | AD14: 12 | AE14: 1 | AF14: 0 | AG14: 3 | AH14: 0 | AI14: 0 | AJ14: 42 | AK14: 1 | AL14: 0 | AM14: 60 | AN14: 1 | AO14: 0 | AP14: 30 | AQ14: 2 | AR14: 0
A15: AM | B15: 0.36458333 | C15: 12 | D15: 1 | E15: 0 | F15: 221 | G15: 28 | H15: 2 | I15: 29 | J15: 3 | K15: 0 | L15: 0 | M15: 0 | N15: 0 | O15: 18 | P15: 1 | Q15: 0 | R15: 28 | S15: 1 | T15: 0 | U15: 13 | V15: 1 | W15: 0 | X15: 23 | Y15: 1 | Z15: 1 | AA15: 145 | AB15: 21 | AC15: 0 | AD15: 19 | AE15: 3 | AF15: 0 | AG15: 2 | AH15: 0 | AI15: 0 | AJ15: 27 | AK15: 0 | AL15: 0 | AM15: 37 | AN15: 3 | AO15: 2 | AP15: 33 | AQ15: 0 | AR15: 0
A17: INT | B17: 0.54166667 | C17: 9 | D17: 0 | E17: 0 | F17: 173 | G17: 15 | H17: 0 | I17: 25 | J17: 1 | K17: 0 | L17: 0 | M17: 0 | N17: 0 | O17: 18 | P17: 0 | Q17: 0 | R17: 39 | S17: 2 | T17: 0 | U17: 13 | V17: 1 | W17: 0 | X17: 20 | Y17: 1 | Z17: 0 | AA17: 175 | AB17: 18 | AC17: 0 | AD17: 20 | AE17: 1 | AF17: 0 | AG17: 2 | AH17: 0 | AI17: 0 | AJ17: 29 | AK17: 1 | AL17: 0 | AM17: 27 | AN17: 1 | AO17: 0 | AP17: 19 | AQ17: 1 | AR17: 0
A18: INT | B18: 0.55208333 | C18: 9 | D18: 0 | E18: 1 | F18: 216 | G18: 21 | H18: 1 | I18: 20 | J18: 3 | K18: 0 | L18: 0 | M18: 0 | N18: 0 | O18: 22 | P18: 2 | Q18: 0 | R18: 54 | S18: 3 | T18: 1 | U18: 14 | V18: 1 | W18: 0 | X18: 21 | Y18: 0 | Z18: 0 | AA18: 178 | AB18: 10 | AC18: 0 | AD18: 18 | AE18: 1 | AF18: 0 | AG18: 2 | AH18: 0 | AI18: 0 | AJ18: 27 | AK18: 1 | AL18: 1 | AM18: 31 | AN18: 3 | AO18: 0 | AP18: 25 | AQ18: 3 | AR18: 0
A19: INT | B19: 0.5625 | C19: 10 | D19: 1 | E19: 0 | F19: 174 | G19: 16 | H19: 0 | I19: 31 | J19: 3 | K19: 0 | L19: 0 | M19: 0 | N19: 0 | O19: 26 | P19: 2 | Q19: 0 | R19: 35 | S19: 3 | T19: 0 | U19: 19 | V19: 2 | W19: 0 | X19: 20 | Y19: 0 | Z19: 0 | AA19: 169 | AB19: 19 | AC19: 0 | AD19: 24 | AE19: 1 | AF19: 0 | AG19: 1 | AH19: 0 | AI19: 0 | AJ19: 20 | AK19: 3 | AL19: 0 | AM19: 34 | AN19: 3 | AO19: 0 | AP19: 18 | AQ19: 1 | AR19: 0
A20: INT | B20: 0.57291667 | C20: 9 | D20: 1 | E20: 0 | F20: 189 | G20: 17 | H20: 0 | I20: 26 | J20: 3 | K20: 0 | L20: 0 | M20: 0 | N20: 0 | O20: 31 | P20: 0 | Q20: 0 | R20: 45 | S20: 6 | T20: 0 | U20: 19 | V20: 2 | W20: 0 | X20: 20 | Y20: 2 | Z20: 0 | AA20: 178 | AB20: 16 | AC20: 0 | AD20: 28 | AE20: 1 | AF20: 0 | AG20: 2 | AH20: 0 | AI20: 0 | AJ20: 17 | AK20: 4 | AL20: 0 | AM20: 33 | AN20: 5 | AO20: 0 | AP20: 21 | AQ20: 3 | AR20: 0
... A29: PM | B29: 0.73958333 | C29: 12 | D29: 0 | E29: 0 | F29: 177 | G29: 10 | H29: 0 | I29: 36 | J29: 4 | K29: 0 | L29: 1 | M29: 0 | N29: 0 | O29: 13 | P29: 3 | Q29: 0 | R29: 54 | S29: 3 | T29: 0 | U29: 13 | V29: 0 | W29: 0 | X29: 39 | Y29: 0 | Z29: 0 | AA29: 143 | AB29: 6 | AC29: 1 | AD29: 10 | AE29: 0 | AF29: 0 | AG29: 1 | AH29: 0 | AI29: 0 | AJ29: 23 | AK29: 0 | AL29: 0 | AM29: 31 | AN29: 3 | AO29: 0 | AP29: 26 | AQ29: 0 | AR29: 0

Sheet PivotData
A1: Approach | B1: Movement | C1: Exit | D1: Vehicle | E1: Survey Period | F1: Time | G1: Count | H1: Time Grouped | I1: Peak Marker
A2: Carmen Road North | B2: Left into Buchanans Road East | C2: Buchanans Road East | D2: Cars | E2: AM | F2: 0.29166667 | G2: 16 | H2: =FLOOR(tblPivotData[[#This Row],[Time]],Summary!$B$6/1440) -> 0.29166667 | I2: =INDEX(PeakCalc!$L$10:$L$303,MATCH(tblPivotData[[#This Row],[Time]],PeakCalc!$G$10:$G$303,0)) -> 0
A3: Carmen Road North | B3: Left into Buchanans Road East | C3: Buchanans Road East | D3: Cars | E3: AM | F3: 0.30208333 | G3: 26 | H3: =FLOOR(tblPivotData[[#This Row],[Time]],Summary!$B$6/1440) -> 0.30208333 | I3: =INDEX(PeakCalc!$L$10:$L$303,MATCH(tblPivotData[[#This Row],[Time]],PeakCalc!$G$10:$G$303,0)) -> 0
A4: Carmen Road North | B4: Left into Buchanans Road East | C4: Buchanans Road East | D4: Cars | E4: AM | F4: 0.3125 | G4: 18 | H4: =FLOOR(tblPivotData[[#This Row],[Time]],Summary!$B$6/1440) -> 0.3125 | I4: =INDEX(PeakCalc!$L$10:$L$303,MATCH(tblPivotData[[#This Row],[Time]],PeakCalc!$G$10:$G$303,0)) -> 0
A5: Carmen Road North | B5: Left into Buchanans Road East | C5: Buchanans Road East | D5: Cars | E5: AM | F5: 0.32291667 | G5: 25 | H5: =FLOOR(tblPivotData[[#This Row],[Time]],Summary!$B$6/1440) -> 0.32291667 | I5: =INDEX(PeakCalc!$L$10:$L$303,MATCH(tblPivotData[[#This Row],[Time]],PeakCalc!$G$10:$G$303,0)) -> 1
A6: Carmen Road North | B6: Left into Buchanans Road East | C6: Buchanans Road East | D6: Cars | E6: AM | F6: 0.33333333 | G6: 15 | H6: =FLOOR(tblPivotData[[#This Row],[Time]],Summary!$B$6/1440) -> 0.33333333 | I6: =INDEX(PeakCalc!$L$10:$L$303,MATCH(tblPivotData[[#This Row],[Time]],PeakCalc!$G$10:$G$303,0)) -> 1
A7: Carmen Road North | B7: Left into Buchanans Road East | C7: Buchanans Road East | D7: Cars | E7: AM | F7: 0.34375 | G7: 20 | H7: =FLOOR(tblPivotData[[#This Row],[Time]],Summary!$B$6/1440) -> 0.34375 | I7: =INDEX(PeakCalc!$L$10:$L$303,MATCH(tblPivotData[[#This Row],[Time]],PeakCalc!$G$10:$G$303,0)) -> 1
A8: Carmen Road North | B8: Left into Buchanans Road East | C8: Buchanans Road East | D8: Cars | E8: AM | F8: 0.35416667 | G8: 24 | H8: =FLOOR(tblPivotData[[#This Row],[Time]],Summary!$B$6/1440) -> 0.35416667 | I8: =INDEX(PeakCalc!$L$10:$L$303,MATCH(tblPivotData[[#This Row],[Time]],PeakCalc!$G$10:$G$303,0)) -> 1
A9: Carmen Road North | B9: Left into Buchanans Road East | C9: Buchanans Road East | D9: Cars | E9: AM | F9: 0.36458333 | G9: 12 | H9: =FLOOR(tblPivotData[[#This Row],[Time]],Summary!$B$6/1440) -> 0.36458333 | I9: =INDEX(PeakCalc!$L$10:$L$303,MATCH(tblPivotData[[#This Row],[Time]],PeakCalc!$G$10:$G$303,0)) -> 0
A10: Carmen Road North | B10: Left into Buchanans Road East | C10: Buchanans Road East | D10: Cars | E10: INT | F10: 0.54166667 | G10: 9 | H10: =FLOOR(tblPivotData[[#This Row],[Time]],Summary!$B$6/1440) -> 0.54166667 | I10: =INDEX(PeakCalc!$L$10:$L$303,MATCH(tblPivotData[[#This Row],[Time]],PeakCalc!$G$10:$G$303,0)) -> 1
A11: Carmen Road North | B11: Left into Buchanans Road East | C11: Buchanans Road East | D11: Cars | E11: INT | F11: 0.55208333 | G11: 9 | H11: =FLOOR(tblPivotData[[#This Row],[Time]],Summary!$B$6/1440) -> 0.55208333 | I11: =INDEX(PeakCalc!$L$10:$L$303,MATCH(tblPivotData[[#This Row],[Time]],PeakCalc!$G$10:$G$303,0)) -> 1
A12: Carmen Road North | B12: Left into Buchanans Road East | C12: Buchanans Road East | D12: Cars | E12: INT | F12: 0.5625 | G12: 10 | H12: =FLOOR(tblPivotData[[#This Row],[Time]],Summary!$B$6/1440) -> 0.5625 | I12: =INDEX(PeakCalc!$L$10:$L$303,MATCH(tblPivotData[[#This Row],[Time]],PeakCalc!$G$10:$G$303,0)) -> 1
A13: Carmen Road North | B13: Left into Buchanans Road East | C13: Buchanans Road East | D13: Cars | E13: INT | F13: 0.57291667 | G13: 9 | H13: =FLOOR(tblPivotData[[#This Row],[Time]],Summary!$B$6/1440) -> 0.57291667 | I13: =INDEX(PeakCalc!$L$10:$L$303,MATCH(tblPivotData[[#This Row],[Time]],PeakCalc!$G$10:$G$303,0)) -> 1
... A841: Buchanans Road West | B841: Right into Carmen Road South | C841: Carmen Road South | D841: Cyclists | E841: PM | F841: 0.73958333 | G841: 0 | H841: =FLOOR(tblPivotData[[#This Row],[Time]],Summary!$B$6/1440) -> 0.73958333 | I841: =INDEX(PeakCalc!$L$10:$L$303,MATCH(tblPivotData[[#This Row],[Time]],PeakCalc!$G$10:$G$303,0)) -> 0

Sheet SummaryCalc
B2: Interval | C2: =rngCountInterval -> 15
B5: Options to group time by
B7: Existing intervals | E7: Selection
B8: 5 | C8: 15 | E8: =C2 -> 15
B10: 5 | C10: 15 | E10: =INDEX($B10:$C10,1,MATCH(E$8,$B$8:$C$8,0)) -> 15
B11: 10 | C11: 30 | E11: =INDEX($B11:$C11,1,MATCH(E$8,$B$8:$C$8,0)) -> 30
B12: 15 | C12: 60 | E12: =INDEX($B12:$C12,1,MATCH(E$8,$B$8:$C$8,0)) -> 60
B13: 20 | C13: - | E13: =INDEX($B13:$C13,1,MATCH(E$8,$B$8:$C$8,0)) -> -
B14: 30 | C14: - | E14: =INDEX($B14:$C14,1,MATCH(E$8,$B$8:$C$8,0)) -> -
B15: 60 | C15: - | E15: =INDEX($B15:$C15,1,MATCH(E$8,$B$8:$C$8,0)) -> -

Sheet Summary
B2: Summary Table
B4: Select time interval to group by
B6: 15 | C6: minutes
B8: Then right click on any cell in the table, and click Refresh
C11: Carmen Road North | S11: Carmen Road North Total | T11: Buchanans Road East | AF11: Buchanans Road East Total | AG11: Carmen Road South | AW11: Carmen Road South Total | AX11: Buchanans Road West | BJ11: Buchanans Road West Total | BK11: Grand Total
C12: Left into Buchanans Road East | F12: Left into Buchanans Road East Total | G12: Thru to Carmen Road South | J12: Thru to Carmen Road South Total | K12: Right into Buchanans Road West | N12: Right into Buchanans Road West Total | O12: U-Turn | R12: U-Turn Total | T12: Left into Carmen Road South | W12: Left into Carmen Road South Total | X12: Thru to Buchanans Road West | AA12: Thru to Buchanans Road West Total | AB12: Right into Carmen Road North | AE12: Right into Carmen Road North Total | AG12: U-Turn | AJ12: U-Turn Total | AK12: Left into Buchanans Road West | AN12: Left into Buchanans Road West Total | AO12: Thru to Carmen Road North | AR12: Thru to Carmen Road North Total | AS12: Right into Buchanans Road East | AV12: Right into Buchanans Road East Total | AX12: Left into Carmen Road North | BA12: Left into Carmen Road North Total | BB12: Thru to Buchanans Road East | BE12: Thru to Buchanans Road East Total | BF12: Right into Carmen Road South | BI12: Right into Carmen Road South Total
C13: Cars | D13: Other Vehicles | E13: Cyclists | G13: Cars | H13: Other Vehicles | I13: Cyclists | K13: Cars | L13: Other Vehicles | M13: Cyclists | O13: Cars | P13: Other Vehicles | Q13: Cyclists | T13: Cars | U13: Other Vehicles | V13: Cyclists | X13: Cars | Y13: Other Vehicles | Z13: Cyclists | AB13: Cars | AC13: Other Vehicles | AD13: Cyclists | AG13: Cars | AH13: Other Vehicles | AI13: Cyclists | AK13: Cars | AL13: Other Vehicles | AM13: Cyclists | AO13: Cars | AP13: Other Vehicles | AQ13: Cyclists | AS13: Cars | AT13: Other Vehicles | AU13: Cyclists | AX13: Cars | AY13: Other Vehicles | AZ13: Cyclists | BB13: Cars | BC13: Other Vehicles | BD13: Cyclists | BF13: Cars | BG13: Other Vehicles | BH13: Cyclists
B14: AM | C14: 156 | D14: 4 | E14: 0 | F14: 160 | G14: 2042 | H14: 153 | I14: 5 | J14: 2200 | K14: 254 | L14: 11 | M14: 0 | N14: 265 | O14: 0 | P14: 0 | Q14: 0 | R14: 0 | S14: 2625 | T14: 182 | U14: 7 | V14: 0 | W14: 189 | X14: 257 | Y14: 16 | Z14: 1 | AA14: 274 | AB14: 113 | AC14: 13 | AD14: 0 | AE14: 126 | AF14: 589 | AG14: 18 | AH14: 0 | AI14: 0 | AJ14: 18 | AK14: 117 | AL14: 8 | AM14: 1 | AN14: 126 | AO14: 1541 | AP14: 141 | AQ14: 4 | AR14: 1686 | AS14: 128 | AT14: 11 | AU14: 0 | AV14: 139 | AW14: 1969 | AX14: 254 | AY14: 19 | AZ14: 1 | BA14: 274 | BB14: 520 | BC14: 18 | BD14: 3 | BE14: 541 | BF14: 196 | BG14: 12 | BH14: 1 | BI14: 209 | BJ14: 1024 | BK14: 6207
B15: 0.29166667 | C15: 16 | D15: 1 | E15: 0 | F15: 17 | G15: 262 | H15: 13 | I15: 0 | J15: 275 | K15: 29 | L15: 2 | M15: 0 | N15: 31 | O15: 0 | P15: 0 | Q15: 0 | R15: 0 | S15: 323 | T15: 21 | U15: 1 | V15: 0 | W15: 22 | X15: 32 | Y15: 2 | Z15: 0 | AA15: 34 | AB15: 17 | AC15: 0 | AD15: 0 | AE15: 17 | AF15: 73 | AG15: 1 | AH15: 0 | AI15: 0 | AJ15: 1 | AK15: 8 | AL15: 1 | AM15: 0 | AN15: 9 | AO15: 154 | AP15: 15 | AQ15: 0 | AR15: 169 | AS15: 10 | AT15: 1 | AU15: 0 | AV15: 11 | AW15: 190 | AX15: 37 | AY15: 7 | AZ15: 0 | BA15: 44 | BB15: 55 | BC15: 3 | BD15: 1 | BE15: 59 | BF15: 15 | BG15: 1 | BH15: 0 | BI15: 16 | BJ15: 119 | BK15: 705
B16: 0.30208333 | C16: 26 | D16: 0 | E16: 0 | F16: 26 | G16: 303 | H16: 21 | I16: 0 | J16: 324 | K16: 33 | L16: 1 | M16: 0 | N16: 34 | O16: 0 | P16: 0 | Q16: 0 | R16: 0 | S16: 384 | T16: 21 | U16: 0 | V16: 0 | W16: 21 | X16: 24 | Y16: 1 | Z16: 0 | AA16: 25 | AB16: 13 | AC16: 2 | AD16: 0 | AE16: 15 | AF16: 61 | AG16: 2 | AH16: 0 | AI16: 0 | AJ16: 2 | AK16: 12 | AL16: 0 | AM16: 0 | AN16: 12 | AO16: 193 | AP16: 17 | AQ16: 0 | AR16: 210 | AS16: 22 | AT16: 2 | AU16: 0 | AV16: 24 | AW16: 248 | AX16: 33 | AY16: 1 | AZ16: 1 | BA16: 35 | BB16: 67 | BC16: 2 | BD16: 0 | BE16: 69 | BF16: 26 | BG16: 1 | BH16: 0 | BI16: 27 | BJ16: 131 | BK16: 824
B17: 0.3125 | C17: 18 | D17: 0 | E17: 0 | F17: 18 | G17: 245 | H17: 12 | I17: 1 | J17: 258 | K17: 36 | L17: 0 | M17: 0 | N17: 36 | O17: 0 | P17: 0 | Q17: 0 | R17: 0 | S17: 312 | T17: 17 | U17: 0 | V17: 0 | W17: 17 | X17: 37 | Y17: 1 | Z17: 0 | AA17: 38 | AB17: 19 | AC17: 2 | AD17: 0 | AE17: 21 | AF17: 76 | AG17: 0 | AH17: 0 | AI17: 0 | AJ17: 0 | AK17: 6 | AL17: 1 | AM17: 0 | AN17: 7 | AO17: 208 | AP17: 18 | AQ17: 1 | AR17: 227 | AS17: 12 | AT17: 2 | AU17: 0 | AV17: 14 | AW17: 248 | AX17: 37 | AY17: 2 | AZ17: 0 | BA17: 39 | BB17: 89 | BC17: 3 | BD17: 0 | BE17: 92 | BF17: 18 | BG17: 2 | BH17: 0 | BI17: 20 | BJ17: 151 | BK17: 787
B18: 0.32291667 | C18: 25 | D18: 0 | E18: 0 | F18: 25 | G18: 298 | H18: 20 | I18: 2 | J18: 320 | K18: 26 | L18: 1 | M18: 0 | N18: 27 | O18: 0 | P18: 0 | Q18: 0 | R18: 0 | S18: 372 | T18: 29 | U18: 1 | V18: 0 | W18: 30 | X18: 29 | Y18: 2 | Z18: 1 | AA18: 32 | AB18: 13 | AC18: 1 | AD18: 0 | AE18: 14 | AF18: 76 | AG18: 3 | AH18: 0 | AI18: 0 | AJ18: 3 | AK18: 11 | AL18: 2 | AM18: 0 | AN18: 13 | AO18: 209 | AP18: 13 | AQ18: 1 | AR18: 223 | AS18: 15 | AT18: 0 | AU18: 0 | AV18: 15 | AW18: 254 | AX18: 23 | AY18: 2 | AZ18: 0 | BA18: 25 | BB18: 67 | BC18: 3 | BD18: 0 | BE18: 70 | BF18: 36 | BG18: 0 | BH18: 0 | BI18: 36 | BJ18: 131 | BK18: 833
B19: 0.33333333 | C19: 15 | D19: 0 | E19: 0 | F19: 15 | G19: 234 | H19: 19 | I19: 0 | J19: 253 | K19: 30 | L19: 2 | M19: 0 | N19: 32 | O19: 0 | P19: 0 | Q19: 0 | R19: 0 | S19: 300 | T19: 24 | U19: 1 | V19: 0 | W19: 25 | X19: 28 | Y19: 0 | Z19: 0 | AA19: 28 | AB19: 13 | AC19: 2 | AD19: 0 | AE19: 15 | AF19: 68 | AG19: 3 | AH19: 0 | AI19: 0 | AJ19: 3 | AK19: 10 | AL19: 2 | AM19: 0 | AN19: 12 | AO19: 208 | AP19: 14 | AQ19: 2 | AR19: 224 | AS19: 22 | AT19: 1 | AU19: 0 | AV19: 23 | AW19: 262 | AX19: 29 | AY19: 3 | AZ19: 0 | BA19: 32 | BB19: 80 | BC19: 2 | BD19: 0 | BE19: 82 | BF19: 16 | BG19: 2 | BH19: 1 | BI19: 19 | BJ19: 133 | BK19: 763
B20: 0.34375 | C20: 20 | D20: 1 | E20: 0 | F20: 21 | G20: 243 | H20: 18 | I20: 0 | J20: 261 | K20: 41 | L20: 0 | M20: 0 | N20: 41 | O20: 0 | P20: 0 | Q20: 0 | R20: 0 | S20: 323 | T20: 28 | U20: 0 | V20: 0 | W20: 28 | X20: 43 | Y20: 5 | Z20: 0 | AA20: 48 | AB20: 14 | AC20: 3 | AD20: 0 | AE20: 17 | AF20: 93 | AG20: 4 | AH20: 0 | AI20: 0 | AJ20: 4 | AK20: 25 | AL20: 0 | AM20: 0 | AN20: 25 | AO20: 200 | AP20: 13 | AQ20: 0 | AR20: 213 | AS20: 16 | AT20: 1 | AU20: 0 | AV20: 17 | AW20: 259 | AX20: 26 | AY20: 3 | AZ20: 0 | BA20: 29 | BB20: 65 | BC20: 1 | BD20: 0 | BE20: 66 | BF20: 22 | BG20: 4 | BH20: 0 | BI20: 26 | BJ20: 121 | BK20: 796
B21: 0.35416667 | C21: 24 | D21: 1 | E21: 0 | F21: 25 | G21: 236 | H21: 22 | I21: 0 | J21: 258 | K21: 30 | L21: 2 | M21: 0 | N21: 32 | O21: 0 | P21: 0 | Q21: 0 | R21: 0 | S21: 315 | T21: 24 | U21: 3 | V21: 0 | W21: 27 | X21: 36 | Y21: 4 | Z21: 0 | AA21: 40 | AB21: 11 | AC21: 2 | AD21: 0 | AE21: 13 | AF21: 80 | AG21: 3 | AH21: 0 | AI21: 0 | AJ21: 3 | AK21: 22 | AL21: 1 | AM21: 0 | AN21: 23 | AO21: 224 | AP21: 30 | AQ21: 0 | AR21: 254 | AS21: 12 | AT21: 1 | AU21: 0 | AV21: 13 | AW21: 293 | AX21: 42 | AY21: 1 | AZ21: 0 | BA21: 43 | BB21: 60 | BC21: 1 | BD21: 0 | BE21: 61 | BF21: 30 | BG21: 2 | BH21: 0 | BI21: 32 | BJ21: 136 | BK21: 824
B22: 0.36458333 | C22: 12 | D22: 1 | E22: 0 | F22: 13 | G22: 221 | H22: 28 | I22: 2 | J22: 251 | K22: 29 | L22: 3 | M22: 0 | N22: 32 | O22: 0 | P22: 0 | Q22: 0 | R22: 0 | S22: 296 | T22: 18 | U22: 1 | V22: 0 | W22: 19 | X22: 28 | Y22: 1 | Z22: 0 | AA22: 29 | AB22: 13 | AC22: 1 | AD22: 0 | AE22: 14 | AF22: 62 | AG22: 2 | AH22: 0 | AI22: 0 | AJ22: 2 | AK22: 23 | AL22: 1 | AM22: 1 | AN22: 25 | AO22: 145 | AP22: 21 | AQ22: 0 | AR22: 166 | AS22: 19 | AT22: 3 | AU22: 0 | AV22: 22 | AW22: 215 | AX22: 27 | AY22: 0 | AZ22: 0 | BA22: 27 | BB22: 37 | BC22: 3 | BD22: 2 | BE22: 42 | BF22: 33 | BG22: 0 | BH22: 0 | BI22: 33 | BJ22: 102 | BK22: 675
B23: PM | C23: 143 | D23: 3 | E23: 0 | F23: 146 | G23: 1731 | H23: 84 | I23: 5 | J23: 1820 | K23: 352 | L23: 18 | M23: 1 | N23: 371 | O23: 3 | P23: 0 | Q23: 0 | R23: 3 | S23: 2340 | T23: 201 | U23: 6 | V23: 0 | W23: 207 | X23: 642 | Y23: 24 | Z23: 3 | AA23: 669 | AB23: 197 | AC23: 8 | AD23: 0 | AE23: 205 | AF23: 1081 | AG23: 15 | AH23: 1 | AI23: 0 | AJ23: 16 | AK23: 460 | AL23: 3 | AM23: 0 | AN23: 463 | AO23: 1933 | AP23: 76 | AQ23: 7 | AR23: 2016 | AS23: 177 | AT23: 4 | AU23: 0 | AV23: 181 | AW23: 2676 | AX23: 232 | AY23: 5 | AZ23: 0 | BA23: 237 | BB23: 298 | BC23: 16 | BD23: 1 | BE23: 315 | BF23: 179 | BG23: 1 | BH23: 0 | BI23: 180 | BJ23: 732 | BK23: 6829
B24: 0.66666667 | C24: 16 | D24: 0 | E24: 0 | F24: 16 | G24: 192 | H24: 18 | I24: 1 | J24: 211 | K24: 45 | L24: 2 | M24: 0 | N24: 47 | O24: 1 | P24: 0 | Q24: 0 | R24: 1 | S24: 275 | T24: 22 | U24: 0 | V24: 0 | W24: 22 | X24: 72 | Y24: 2 | Z24: 0 | AA24: 74 | AB24: 38 | AC24: 5 | AD24: 0 | AE24: 43 | AF24: 139 | AG24: 3 | AH24: 1 | AI24: 0 | AJ24: 4 | AK24: 41 | AL24: 0 | AM24: 0 | AN24: 41 | AO24: 318 | AP24: 17 | AQ24: 0 | AR24: 335 | AS24: 16 | AT24: 1 | AU24: 0 | AV24: 17 | AW24: 397 | AX24: 37 | AY24: 1 | AZ24: 0 | BA24: 38 | BB24: 26 | BC24: 5 | BD24: 0 | BE24: 31 | BF24: 25 | BG24: 0 | BH24: 0 | BI24: 25 | BJ24: 94 | BK24: 905
B25: 0.67708333 | C25: 12 | D25: 1 | E25: 0 | F25: 13 | G25: 236 | H25: 10 | I25: 2 | J25: 248 | K25: 37 | L25: 6 | M25: 0 | N25: 43 | O25: 0 | P25: 0 | Q25: 0 | R25: 0 | S25: 304 | T25: 33 | U25: 1 | V25: 0 | W25: 34 | X25: 81 | Y25: 8 | Z25: 0 | AA25: 89 | AB25: 18 | AC25: 0 | AD25: 0 | AE25: 18 | AF25: 141 | AG25: 3 | AH25: 0 | AI25: 0 | AJ25: 3 | AK25: 41 | AL25: 0 | AM25: 0 | AN25: 41 | AO25: 266 | AP25: 9 | AQ25: 2 | AR25: 277 | AS25: 15 | AT25: 0 | AU25: 0 | AV25: 15 | AW25: 336 | AX25: 40 | AY25: 0 | AZ25: 0 | BA25: 40 | BB25: 36 | BC25: 1 | BD25: 0 | BE25: 37 | BF25: 26 | BG25: 0 | BH25: 0 | BI25: 26 | BJ25: 103 | BK25: 884
B26: 0.6875 | C26: 22 | D26: 1 | E26: 0 | F26: 23 | G26: 263 | H26: 12 | I26: 0 | J26: 275 | K26: 64 | L26: 1 | M26: 0 | N26: 65 | O26: 0 | P26: 0 | Q26: 0 | R26: 0 | S26: 363 | T26: 32 | U26: 1 | V26: 0 | W26: 33 | X26: 88 | Y26: 1 | Z26: 0 | AA26: 89 | AB26: 29 | AC26: 0 | AD26: 0 | AE26: 29 | AF26: 151 | AG26: 2 | AH26: 0 | AI26: 0 | AJ26: 2 | AK26: 64 | AL26: 1 | AM26: 0 | AN26: 65 | AO26: 282 | AP26: 14 | AQ26: 1 | AR26: 297 | AS26: 26 | AT26: 1 | AU26: 0 | AV26: 27 | AW26: 391 | AX26: 33 | AY26: 0 | AZ26: 0 | BA26: 33 | BB26: 35 | BC26: 2 | BD26: 0 | BE26: 37 | BF26: 22 | BG26: 0 | BH26: 0 | BI26: 22 | BJ26: 92 | BK26: 997
B27: 0.69791667 | C27: 18 | D27: 0 | E27: 0 | F27: 18 | G27: 206 | H27: 10 | I27: 1 | J27: 217 | K27: 44 | L27: 1 | M27: 1 | N27: 46 | O27: 0 | P27: 0 | Q27: 0 | R27: 0 | S27: 281 | T27: 21 | U27: 0 | V27: 0 | W27: 21 | X27: 87 | Y27: 4 | Z27: 1 | AA27: 92 | AB27: 35 | AC27: 0 | AD27: 0 | AE27: 35 | AF27: 148 | AG27: 1 | AH27: 0 | AI27: 0 | AJ27: 1 | AK27: 66 | AL27: 1 | AM27: 0 | AN27: 67 | AO27: 264 | AP27: 10 | AQ27: 1 | AR27: 275 | AS27: 17 | AT27: 0 | AU27: 0 | AV27: 17 | AW27: 360 | AX27: 26 | AY27: 3 | AZ27: 0 | BA27: 29 | BB27: 43 | BC27: 2 | BD27: 0 | BE27: 45 | BF27: 16 | BG27: 1 | BH27: 0 | BI27: 17 | BJ27: 91 | BK27: 880
B28: 0.70833333 | C28: 19 | D28: 0 | E28: 0 | F28: 19 | G28: 239 | H28: 6 | I28: 0 | J28: 245 | K28: 50 | L28: 2 | M28: 0 | N28: 52 | O28: 1 | P28: 0 | Q28: 0 | R28: 1 | S28: 317 | T28: 32 | U28: 0 | V28: 0 | W28: 32 | X28: 100 | Y28: 4 | Z28: 0 | AA28: 104 | AB28: 28 | AC28: 0 | AD28: 0 | AE28: 28 | AF28: 164 | AG28: 2 | AH28: 0 | AI28: 0 | AJ28: 2 | AK28: 72 | AL28: 1 | AM28: 0 | AN28: 73 | AO28: 231 | AP28: 8 | AQ28: 0 | AR28: 239 | AS28: 28 | AT28: 0 | AU28: 0 | AV28: 28 | AW28: 342 | AX28: 24 | AY28: 1 | AZ28: 0 | BA28: 25 | BB28: 41 | BC28: 2 | BD28: 1 | BE28: 44 | BF28: 19 | BG28: 0 | BH28: 0 | BI28: 19 | BJ28: 88 | BK28: 911
B29: 0.71875 | C29: 21 | D29: 1 | E29: 0 | F29: 22 | G29: 209 | H29: 10 | I29: 0 | J29: 219 | K29: 36 | L29: 0 | M29: 0 | N29: 36 | O29: 0 | P29: 0 | Q29: 0 | R29: 0 | S29: 277 | T29: 21 | U29: 1 | V29: 0 | W29: 22 | X29: 87 | Y29: 1 | Z29: 2 | AA29: 90 | AB29: 17 | AC29: 1 | AD29: 0 | AE29: 18 | AF29: 130 | AG29: 0 | AH29: 0 | AI29: 0 | AJ29: 0 | AK29: 71 | AL29: 0 | AM29: 0 | AN29: 71 | AO29: 221 | AP29: 6 | AQ29: 0 | AR29: 227 | AS29: 39 | AT29: 2 | AU29: 0 | AV29: 41 | AW29: 339 | AX29: 26 | AY29: 0 | AZ29: 0 | BA29: 26 | BB29: 43 | BC29: 1 | BD29: 0 | BE29: 44 | BF29: 20 | BG29: 0 | BH29: 0 | BI29: 20 | BJ29: 90 | BK29: 836
B30: 0.72916667 | C30: 23 | D30: 0 | E30: 0 | F30: 23 | G30: 209 | H30: 8 | I30: 1 | J30: 218 | K30: 40 | L30: 2 | M30: 0 | N30: 42 | O30: 0 | P30: 0 | Q30: 0 | R30: 0 | S30: 283 | T30: 27 | U30: 0 | V30: 0 | W30: 27 | X30: 73 | Y30: 1 | Z30: 0 | AA30: 74 | AB30: 19 | AC30: 2 | AD30: 0 | AE30: 21 | AF30: 122 | AG30: 3 | AH30: 0 | AI30: 0 | AJ30: 3 | AK30: 66 | AL30: 0 | AM30: 0 | AN30: 66 | AO30: 208 | AP30: 6 | AQ30: 2 | AR30: 216 | AS30: 26 | AT30: 0 | AU30: 0 | AV30: 26 | AW30: 311 | AX30: 23 | AY30: 0 | AZ30: 0 | BA30: 23 | BB30: 43 | BC30: 0 | BD30: 0 | BE30: 43 | BF30: 25 | BG30: 0 | BH30: 0 | BI30: 25 | BJ30: 91 | BK30: 807
B31: 0.73958333 | C31: 12 | D31: 0 | E31: 0 | F31: 12 | G31: 177 | H31: 10 | I31: 0 | J31: 187 | K31: 36 | L31: 4 | M31: 0 | N31: 40 | O31: 1 | P31: 0 | Q31: 0 | R31: 1 | S31: 240 | T31: 13 | U31: 3 | V31: 0 | W31: 16 | X31: 54 | Y31: 3 | Z31: 0 | AA31: 57 | AB31: 13 | AC31: 0 | AD31: 0 | AE31: 13 | AF31: 86 | AG31: 1 | AH31: 0 | AI31: 0 | AJ31: 1 | AK31: 39 | AL31: 0 | AM31: 0 | AN31: 39 | AO31: 143 | AP31: 6 | AQ31: 1 | AR31: 150 | AS31: 10 | AT31: 0 | AU31: 0 | AV31: 10 | AW31: 200 | AX31: 23 | AY31: 0 | AZ31: 0 | BA31: 23 | BB31: 31 | BC31: 3 | BD31: 0 | BE31: 34 | BF31: 26 | BG31: 0 | BH31: 0 | BI31: 26 | BJ31: 83 | BK31: 609
B32: INT | C32: 37 | D32: 2 | E32: 1 | F32: 40 | G32: 752 | H32: 69 | I32: 1 | J32: 822 | K32: 102 | L32: 10 | M32: 0 | N32: 112 | O32: 0 | P32: 0 | Q32: 0 | R32: 0 | S32: 974 | T32: 97 | U32: 4 | V32: 0 | W32: 101 | X32: 173 | Y32: 14 | Z32: 1 | AA32: 188 | AB32: 65 | AC32: 6 | AD32: 0 | AE32: 71 | AF32: 360 | AG32: 7 | AH32: 0 | AI32: 0 | AJ32: 7 | AK32: 81 | AL32: 3 | AM32: 0 | AN32: 84 | AO32: 700 | AP32: 63 | AQ32: 0 | AR32: 763 | AS32: 90 | AT32: 4 | AU32: 0 | AV32: 94 | AW32: 948 | AX32: 93 | AY32: 9 | AZ32: 1 | BA32: 103 | BB32: 125 | BC32: 12 | BD32: 0 | BE32: 137 | BF32: 83 | BG32: 8 | BH32: 0 | BI32: 91 | BJ32: 331 | BK32: 2613
B33: 0.54166667 | C33: 9 | D33: 0 | E33: 0 | F33: 9 | G33: 173 | H33: 15 | I33: 0 | J33: 188 | K33: 25 | L33: 1 | M33: 0 | N33: 26 | O33: 0 | P33: 0 | Q33: 0 | R33: 0 | S33: 223 | T33: 18 | U33: 0 | V33: 0 | W33: 18 | X33: 39 | Y33: 2 | Z33: 0 | AA33: 41 | AB33: 13 | AC33: 1 | AD33: 0 | AE33: 14 | AF33: 73 | AG33: 2 | AH33: 0 | AI33: 0 | AJ33: 2 | AK33: 20 | AL33: 1 | AM33: 0 | AN33: 21 | AO33: 175 | AP33: 18 | AQ33: 0 | AR33: 193 | AS33: 20 | AT33: 1 | AU33: 0 | AV33: 21 | AW33: 237 | AX33: 29 | AY33: 1 | AZ33: 0 | BA33: 30 | BB33: 27 | BC33: 1 | BD33: 0 | BE33: 28 | BF33: 19 | BG33: 1 | BH33: 0 | BI33: 20 | BJ33: 78 | BK33: 611
B34: 0.55208333 | C34: 9 | D34: 0 | E34: 1 | F34: 10 | G34: 216 | H34: 21 | I34: 1 | J34: 238 | K34: 20 | L34: 3 | M34: 0 | N34: 23 | O34: 0 | P34: 0 | Q34: 0 | R34: 0 | S34: 271 | T34: 22 | U34: 2 | V34: 0 | W34: 24 | X34: 54 | Y34: 3 | Z34: 1 | AA34: 58 | AB34: 14 | AC34: 1 | AD34: 0 | AE34: 15 | AF34: 97 | AG34: 2 | AH34: 0 | AI34: 0 | AJ34: 2 | AK34: 21 | AL34: 0 | AM34: 0 | AN34: 21 | AO34: 178 | AP34: 10 | AQ34: 0 | AR34: 188 | AS34: 18 | AT34: 1 | AU34: 0 | AV34: 19 | AW34: 230 | AX34: 27 | AY34: 1 | AZ34: 1 | BA34: 29 | BB34: 31 | BC34: 3 | BD34: 0 | BE34: 34 | BF34: 25 | BG34: 3 | BH34: 0 | BI34: 28 | BJ34: 91 | BK34: 689
B35: 0.5625 | C35: 10 | D35: 1 | E35: 0 | F35: 11 | G35: 174 | H35: 16 | I35: 0 | J35: 190 | K35: 31 | L35: 3 | M35: 0 | N35: 34 | O35: 0 | P35: 0 | Q35: 0 | R35: 0 | S35: 235 | T35: 26 | U35: 2 | V35: 0 | W35: 28 | X35: 35 | Y35: 3 | Z35: 0 | AA35: 38 | AB35: 19 | AC35: 2 | AD35: 0 | AE35: 21 | AF35: 87 | AG35: 1 | AH35: 0 | AI35: 0 | AJ35: 1 | AK35: 20 | AL35: 0 | AM35: 0 | AN35: 20 | AO35: 169 | AP35: 19 | AQ35: 0 | AR35: 188 | AS35: 24 | AT35: 1 | AU35: 0 | AV35: 25 | AW35: 234 | AX35: 20 | AY35: 3 | AZ35: 0 | BA35: 23 | BB35: 34 | BC35: 3 | BD35: 0 | BE35: 37 | BF35: 18 | BG35: 1 | BH35: 0 | BI35: 19 | BJ35: 79 | BK35: 635
B36: 0.57291667 | C36: 9 | D36: 1 | E36: 0 | F36: 10 | G36: 189 | H36: 17 | I36: 0 | J36: 206 | K36: 26 | L36: 3 | M36: 0 | N36: 29 | O36: 0 | P36: 0 | Q36: 0 | R36: 0 | S36: 245 | T36: 31 | U36: 0 | V36: 0 | W36: 31 | X36: 45 | Y36: 6 | Z36: 0 | AA36: 51 | AB36: 19 | AC36: 2 | AD36: 0 | AE36: 21 | AF36: 103 | AG36: 2 | AH36: 0 | AI36: 0 | AJ36: 2 | AK36: 20 | AL36: 2 | AM36: 0 | AN36: 22 | AO36: 178 | AP36: 16 | AQ36: 0 | AR36: 194 | AS36: 28 | AT36: 1 | AU36: 0 | AV36: 29 | AW36: 247 | AX36: 17 | AY36: 4 | AZ36: 0 | BA36: 21 | BB36: 33 | BC36: 5 | BD36: 0 | BE36: 38 | BF36: 21 | BG36: 3 | BH36: 0 | BI36: 24 | BJ36: 83 | BK36: 678

Sheet PeakCalc
A1: Time interval | B1: =A12-A11 -> 0.010416667 | H1: Hourly totals | N1: Graph data
B3: Period 1 | C3: Period 2 | D3: Period 3 | E3: Period 4 | H3: Period 1 | I3: Period 2 | J3: Period 3 | K3: Period 4
G5: Max Qty | H5: =MAX(H11:H303) -> 3216 | I5: =MAX(I11:I303) -> 2613 | J5: =MAX(J11:J303) -> 3672 | K5: =MAX(K11:K303) -> 0 | N5: Max Qty | O5: =INDEX($H5:$K5,1,MATCH($O$4,$H$10:$K$10,0)) -> 0
G6: Max Start Time | H6: =IF(H5=0,0,H7-1/24) -> 0.32291667 | I6: =IF(I5=0,0,I7-1/24) -> 0.54166667 | J6: =IF(J5=0,0,J7-1/24) -> 0.67708333 | K6: =IF(K5=0,0,K7-1/24) -> 0 | N6: Max Start Time | O6: =INDEX($H6:$K6,1,MATCH($O$4,$H$10:$K$10,0)) -> 0
G7: Max End Time | H7: =IF(H5=0,0,INDEX($G$11:$G$303,MATCH(H$5,H$11:H$303,0))+$B$1) -> 0.36458333 | I7: =IF(I5=0,0,INDEX($G$11:$G$303,MATCH(I$5,I$11:I$303,0))+$B$1) -> 0.58333333 | J7: =IF(J5=0,0,INDEX($G$11:$G$303,MATCH(J$5,J$11:J$303,0))+$B$1) -> 0.71875 | K7: =IF(K5=0,0,INDEX($G$11:$G$303,MATCH(K$5,K$11:K$303,0))+$B$1) -> 0 | N7: Max End Time | O7: =INDEX($H7:$K7,1,MATCH($O$4,$H$10:$K$10,0)) -> 0
G8: Sentence | H8: =IF(H5=0,"","The peak hour for " &H10&" is "&H5&" vehicles between " & TEXT(H6, "hh:mm")& " and " &TEXT(H7,"hh:mm")) -> The peak hour for AM is 3216 vehicles between 07:45 and 08:45 | I8: =IF(I5=0,"","The peak hour for " &I10&" is "&I5&" vehicles between " & TEXT(I6, "hh:mm")& " and " &TEXT(I7,"hh:mm")) -> The peak hour for INT is 2613 vehicles between 13:00 and 14:00 | J8: =IF(J5=0,"","The peak hour for " &J10&" is "&J5&" vehicles between " & TEXT(J6, "hh:mm")& " and " &TEXT(J7,"hh:mm")) -> The peak hour for PM is 3672 vehicles between 16:15 and 17:15 | K8: =IF(K5=0,"","The peak hour for " &K10&" is "&K5&" vehicles between " & TEXT(K6, "hh:mm")& " and " &TEXT(K7,"hh:mm")) | N8: Graph Title | O8: ="Vehicle Count and Peak Hour "&U8 -> Vehicle Count and Peak Hour for AM Period | S8: Survey Period | T8: AM | U8: =IF(T8="(All)","","for "&T8&" Period") -> for AM Period
A9: Sum of Count | B9: Column Labels
A10: Row Labels | B10: AM | C10: INT | D10: PM | H10: =B10 -> AM | I10: =C10 -> INT | J10: =D10 -> PM | K10: =E10 -> 0 | L10: Peak marker | N10: Survey Period | O10: Time | P10: Total | Q10: Peak | S10: Row Labels | T10: Overall | U10: Peak Hour
A11: 0.29166667 | B11: 705 | G11: =A11 -> 0.29166667 | H11: =IF(B11<>0,SUMIF($G$11:$G11,">"&$G11-1/24,B$11:B11),0) -> 705 | I11: =IF(C11<>0,SUMIF($G$11:$G11,">"&$G11-1/24,C$11:C11),0) -> 0 | J11: =IF(D11<>0,SUMIF($G$11:$G11,">"&$G11-1/24,D$11:D11),0) -> 0 | K11: =IF(E11<>0,SUMIF($G$11:$G11,">"&$G11-1/24,E$11:E11),0) -> 0 | L11: =IF(OR(AND(G11>=$H$6-0.0001,G11<$H$7-0.0001),AND(G11>=$I$6-0.0001,G11<$I$7-0.0001),AND(G11>=$J$6-0.0001,G11<$J$7-0.0001),AND(G11>=$K$6-0.0001,G11<$K$7-0.0001)),1,0) -> 0 | N11: =IFERROR(INDEX($B$10:$E$10,1,MATCH(999999,$B11:$E11)),"-") -> AM | O11: =IF(G11=0,"",G11) -> 0.29166667 | P11: =SUM(B11:E11) -> 705 | Q11: =P11*L11 -> 0 | S11: 0.29166667 | T11: 705 | U11: 0
A12: 0.30208333 | B12: 824 | G12: =A12 -> 0.30208333 | H12: =IF(B12<>0,SUMIF($G$11:$G12,">"&$G12-1/24,B$11:B12),0) -> 1529 | I12: =IF(C12<>0,SUMIF($G$11:$G12,">"&$G12-1/24,C$11:C12),0) -> 0 | J12: =IF(D12<>0,SUMIF($G$11:$G12,">"&$G12-1/24,D$11:D12),0) -> 0 | K12: =IF(E12<>0,SUMIF($G$11:$G12,">"&$G12-1/24,E$11:E12),0) -> 0 | L12: =IF(OR(AND(G12>=$H$6-0.0001,G12<$H$7-0.0001),AND(G12>=$I$6-0.0001,G12<$I$7-0.0001),AND(G12>=$J$6-0.0001,G12<$J$7-0.0001),AND(G12>=$K$6-0.0001,G12<$K$7-0.0001)),1,0) -> 0 | N12: =IFERROR(INDEX($B$10:$E$10,1,MATCH(999999,$B12:$E12)),"-") -> AM | O12: =IF(G12=0,"",G12) -> 0.30208333 | P12: =SUM(B12:E12) -> 824 | Q12: =P12*L12 -> 0 | S12: 0.30208333 | T12: 824 | U12: 0
A13: 0.3125 | B13: 787 | G13: =A13 -> 0.3125 | H13: =IF(B13<>0,SUMIF($G$11:$G13,">"&$G13-1/24,B$11:B13),0) -> 2316 | I13: =IF(C13<>0,SUMIF($G$11:$G13,">"&$G13-1/24,C$11:C13),0) -> 0 | J13: =IF(D13<>0,SUMIF($G$11:$G13,">"&$G13-1/24,D$11:D13),0) -> 0 | K13: =IF(E13<>0,SUMIF($G$11:$G13,">"&$G13-1/24,E$11:E13),0) -> 0 | L13: =IF(OR(AND(G13>=$H$6-0.0001,G13<$H$7-0.0001),AND(G13>=$I$6-0.0001,G13<$I$7-0.0001),AND(G13>=$J$6-0.0001,G13<$J$7-0.0001),AND(G13>=$K$6-0.0001,G13<$K$7-0.0001)),1,0) -> 0 | N13: =IFERROR(INDEX($B$10:$E$10,1,MATCH(999999,$B13:$E13)),"-") -> AM | O13: =IF(G13=0,"",G13) -> 0.3125 | P13: =SUM(B13:E13) -> 787 | Q13: =P13*L13 -> 0 | S13: 0.3125 | T13: 787 | U13: 0
A14: 0.32291667 | B14: 833 | G14: =A14 -> 0.32291667 | H14: =IF(B14<>0,SUMIF($G$11:$G14,">"&$G14-1/24,B$11:B14),0) -> 3149 | I14: =IF(C14<>0,SUMIF($G$11:$G14,">"&$G14-1/24,C$11:C14),0) -> 0 | J14: =IF(D14<>0,SUMIF($G$11:$G14,">"&$G14-1/24,D$11:D14),0) -> 0 | K14: =IF(E14<>0,SUMIF($G$11:$G14,">"&$G14-1/24,E$11:E14),0) -> 0 | L14: =IF(OR(AND(G14>=$H$6-0.0001,G14<$H$7-0.0001),AND(G14>=$I$6-0.0001,G14<$I$7-0.0001),AND(G14>=$J$6-0.0001,G14<$J$7-0.0001),AND(G14>=$K$6-0.0001,G14<$K$7-0.0001)),1,0) -> 1 | N14: =IFERROR(INDEX($B$10:$E$10,1,MATCH(999999,$B14:$E14)),"-") -> AM | O14: =IF(G14=0,"",G14) -> 0.32291667 | P14: =SUM(B14:E14) -> 833 | Q14: =P14*L14 -> 833 | S14: 0.32291667 | T14: 833 | U14: 833
A15: 0.33333333 | B15: 763 | G15: =A15 -> 0.33333333 | H15: =IF(B15<>0,SUMIF($G$11:$G15,">"&$G15-1/24,B$11:B15),0) -> 3207 | I15: =IF(C15<>0,SUMIF($G$11:$G15,">"&$G15-1/24,C$11:C15),0) -> 0 | J15: =IF(D15<>0,SUMIF($G$11:$G15,">"&$G15-1/24,D$11:D15),0) -> 0 | K15: =IF(E15<>0,SUMIF($G$11:$G15,">"&$G15-1/24,E$11:E15),0) -> 0 | L15: =IF(OR(AND(G15>=$H$6-0.0001,G15<$H$7-0.0001),AND(G15>=$I$6-0.0001,G15<$I$7-0.0001),AND(G15>=$J$6-0.0001,G15<$J$7-0.0001),AND(G15>=$K$6-0.0001,G15<$K$7-0.0001)),1,0) -> 1 | N15: =IFERROR(INDEX($B$10:$E$10,1,MATCH(999999,$B15:$E15)),"-") -> AM | O15: =IF(G15=0,"",G15) -> 0.33333333 | P15: =SUM(B15:E15) -> 763 | Q15: =P15*L15 -> 763 | S15: 0.33333333 | T15: 763 | U15: 763
A16: 0.34375 | B16: 796 | G16: =A16 -> 0.34375 | H16: =IF(B16<>0,SUMIF($G$11:$G16,">"&$G16-1/24,B$11:B16),0) -> 3179 | I16: =IF(C16<>0,SUMIF($G$11:$G16,">"&$G16-1/24,C$11:C16),0) -> 0 | J16: =IF(D16<>0,SUMIF($G$11:$G16,">"&$G16-1/24,D$11:D16),0) -> 0 | K16: =IF(E16<>0,SUMIF($G$11:$G16,">"&$G16-1/24,E$11:E16),0) -> 0 | L16: =IF(OR(AND(G16>=$H$6-0.0001,G16<$H$7-0.0001),AND(G16>=$I$6-0.0001,G16<$I$7-0.0001),AND(G16>=$J$6-0.0001,G16<$J$7-0.0001),AND(G16>=$K$6-0.0001,G16<$K$7-0.0001)),1,0) -> 1 | N16: =IFERROR(INDEX($B$10:$E$10,1,MATCH(999999,$B16:$E16)),"-") -> AM | O16: =IF(G16=0,"",G16) -> 0.34375 | P16: =SUM(B16:E16) -> 796 | Q16: =P16*L16 -> 796 | S16: 0.34375 | T16: 796 | U16: 796
A17: 0.35416667 | B17: 824 | G17: =A17 -> 0.35416667 | H17: =IF(B17<>0,SUMIF($G$11:$G17,">"&$G17-1/24,B$11:B17),0) -> 3216 | I17: =IF(C17<>0,SUMIF($G$11:$G17,">"&$G17-1/24,C$11:C17),0) -> 0 | J17: =IF(D17<>0,SUMIF($G$11:$G17,">"&$G17-1/24,D$11:D17),0) -> 0 | K17: =IF(E17<>0,SUMIF($G$11:$G17,">"&$G17-1/24,E$11:E17),0) -> 0 | L17: =IF(OR(AND(G17>=$H$6-0.0001,G17<$H$7-0.0001),AND(G17>=$I$6-0.0001,G17<$I$7-0.0001),AND(G17>=$J$6-0.0001,G17<$J$7-0.0001),AND(G17>=$K$6-0.0001,G17<$K$7-0.0001)),1,0) -> 1 | N17: =IFERROR(INDEX($B$10:$E$10,1,MATCH(999999,$B17:$E17)),"-") -> AM | O17: =IF(G17=0,"",G17) -> 0.35416667 | P17: =SUM(B17:E17) -> 824 | Q17: =P17*L17 -> 824 | S17: 0.35416667 | T17: 824 | U17: 824
A18: 0.36458333 | B18: 675 | G18: =A18 -> 0.36458333 | H18: =IF(B18<>0,SUMIF($G$11:$G18,">"&$G18-1/24,B$11:B18),0) -> 3058 | I18: =IF(C18<>0,SUMIF($G$11:$G18,">"&$G18-1/24,C$11:C18),0) -> 0 | J18: =IF(D18<>0,SUMIF($G$11:$G18,">"&$G18-1/24,D$11:D18),0) -> 0 | K18: =IF(E18<>0,SUMIF($G$11:$G18,">"&$G18-1/24,E$11:E18),0) -> 0 | L18: =IF(OR(AND(G18>=$H$6-0.0001,G18<$H$7-0.0001),AND(G18>=$I$6-0.0001,G18<$I$7-0.0001),AND(G18>=$J$6-0.0001,G18<$J$7-0.0001),AND(G18>=$K$6-0.0001,G18<$K$7-0.0001)),1,0) -> 0 | N18: =IFERROR(INDEX($B$10:$E$10,1,MATCH(999999,$B18:$E18)),"-") -> AM | O18: =IF(G18=0,"",G18) -> 0.36458333 | P18: =SUM(B18:E18) -> 675 | Q18: =P18*L18 -> 0 | S18: 0.36458333 | T18: 675 | U18: 0
A19: 0.54166667 | C19: 611 | G19: =A19 -> 0.54166667 | H19: =IF(B19<>0,SUMIF($G$11:$G19,">"&$G19-1/24,B$11:B19),0) -> 0 | I19: =IF(C19<>0,SUMIF($G$11:$G19,">"&$G19-1/24,C$11:C19),0) -> 611 | J19: =IF(D19<>0,SUMIF($G$11:$G19,">"&$G19-1/24,D$11:D19),0) -> 0 | K19: =IF(E19<>0,SUMIF($G$11:$G19,">"&$G19-1/24,E$11:E19),0) -> 0 | L19: =IF(OR(AND(G19>=$H$6-0.0001,G19<$H$7-0.0001),AND(G19>=$I$6-0.0001,G19<$I$7-0.0001),AND(G19>=$J$6-0.0001,G19<$J$7-0.0001),AND(G19>=$K$6-0.0001,G19<$K$7-0.0001)),1,0) -> 1 | N19: =IFERROR(INDEX($B$10:$E$10,1,MATCH(999999,$B19:$E19)),"-") -> INT | O19: =IF(G19=0,"",G19) -> 0.54166667 | P19: =SUM(B19:E19) -> 611 | Q19: =P19*L19 -> 611 | S19: Grand Total | T19: 6207 | U19: 3216
A20: 0.55208333 | C20: 689 | G20: =A20 -> 0.55208333 | H20: =IF(B20<>0,SUMIF($G$11:$G20,">"&$G20-1/24,B$11:B20),0) -> 0 | I20: =IF(C20<>0,SUMIF($G$11:$G20,">"&$G20-1/24,C$11:C20),0) -> 1300 | J20: =IF(D20<>0,SUMIF($G$11:$G20,">"&$G20-1/24,D$11:D20),0) -> 0 | K20: =IF(E20<>0,SUMIF($G$11:$G20,">"&$G20-1/24,E$11:E20),0) -> 0 | L20: =IF(OR(AND(G20>=$H$6-0.0001,G20<$H$7-0.0001),AND(G20>=$I$6-0.0001,G20<$I$7-0.0001),AND(G20>=$J$6-0.0001,G20<$J$7-0.0001),AND(G20>=$K$6-0.0001,G20<$K$7-0.0001)),1,0) -> 1 | N20: =IFERROR(INDEX($B$10:$E$10,1,MATCH(999999,$B20:$E20)),"-") -> INT | O20: =IF(G20=0,"",G20) -> 0.55208333 | P20: =SUM(B20:E20) -> 689 | Q20: =P20*L20 -> 689
A21: 0.5625 | C21: 635 | G21: =A21 -> 0.5625 | H21: =IF(B21<>0,SUMIF($G$11:$G21,">"&$G21-1/24,B$11:B21),0) -> 0 | I21: =IF(C21<>0,SUMIF($G$11:$G21,">"&$G21-1/24,C$11:C21),0) -> 1935 | J21: =IF(D21<>0,SUMIF($G$11:$G21,">"&$G21-1/24,D$11:D21),0) -> 0 | K21: =IF(E21<>0,SUMIF($G$11:$G21,">"&$G21-1/24,E$11:E21),0) -> 0 | L21: =IF(OR(AND(G21>=$H$6-0.0001,G21<$H$7-0.0001),AND(G21>=$I$6-0.0001,G21<$I$7-0.0001),AND(G21>=$J$6-0.0001,G21<$J$7-0.0001),AND(G21>=$K$6-0.0001,G21<$K$7-0.0001)),1,0) -> 1 | N21: =IFERROR(INDEX($B$10:$E$10,1,MATCH(999999,$B21:$E21)),"-") -> INT | O21: =IF(G21=0,"",G21) -> 0.5625 | P21: =SUM(B21:E21) -> 635 | Q21: =P21*L21 -> 635
A22: 0.57291667 | C22: 678 | G22: =A22 -> 0.57291667 | H22: =IF(B22<>0,SUMIF($G$11:$G22,">"&$G22-1/24,B$11:B22),0) -> 0 | I22: =IF(C22<>0,SUMIF($G$11:$G22,">"&$G22-1/24,C$11:C22),0) -> 2613 | J22: =IF(D22<>0,SUMIF($G$11:$G22,">"&$G22-1/24,D$11:D22),0) -> 0 | K22: =IF(E22<>0,SUMIF($G$11:$G22,">"&$G22-1/24,E$11:E22),0) -> 0 | L22: =IF(OR(AND(G22>=$H$6-0.0001,G22<$H$7-0.0001),AND(G22>=$I$6-0.0001,G22<$I$7-0.0001),AND(G22>=$J$6-0.0001,G22<$J$7-0.0001),AND(G22>=$K$6-0.0001,G22<$K$7-0.0001)),1,0) -> 1 | N22: =IFERROR(INDEX($B$10:$E$10,1,MATCH(999999,$B22:$E22)),"-") -> INT | O22: =IF(G22=0,"",G22) -> 0.57291667 | P22: =SUM(B22:E22) -> 678 | Q22: =P22*L22 -> 678
A23: 0.66666667 | D23: 905 | G23: =A23 -> 0.66666667 | H23: =IF(B23<>0,SUMIF($G$11:$G23,">"&$G23-1/24,B$11:B23),0) -> 0 | I23: =IF(C23<>0,SUMIF($G$11:$G23,">"&$G23-1/24,C$11:C23),0) -> 0 | J23: =IF(D23<>0,SUMIF($G$11:$G23,">"&$G23-1/24,D$11:D23),0) -> 905 | K23: =IF(E23<>0,SUMIF($G$11:$G23,">"&$G23-1/24,E$11:E23),0) -> 0 | L23: =IF(OR(AND(G23>=$H$6-0.0001,G23<$H$7-0.0001),AND(G23>=$I$6-0.0001,G23<$I$7-0.0001),AND(G23>=$J$6-0.0001,G23<$J$7-0.0001),AND(G23>=$K$6-0.0001,G23<$K$7-0.0001)),1,0) -> 0 | N23: =IFERROR(INDEX($B$10:$E$10,1,MATCH(999999,$B23:$E23)),"-") -> PM | O23: =IF(G23=0,"",G23) -> 0.66666667 | P23: =SUM(B23:E23) -> 905 | Q23: =P23*L23 -> 0
A24: 0.67708333 | D24: 884 | G24: =A24 -> 0.67708333 | H24: =IF(B24<>0,SUMIF($G$11:$G24,">"&$G24-1/24,B$11:B24),0) -> 0 | I24: =IF(C24<>0,SUMIF($G$11:$G24,">"&$G24-1/24,C$11:C24),0) -> 0 | J24: =IF(D24<>0,SUMIF($G$11:$G24,">"&$G24-1/24,D$11:D24),0) -> 1789 | K24: =IF(E24<>0,SUMIF($G$11:$G24,">"&$G24-1/24,E$11:E24),0) -> 0 | L24: =IF(OR(AND(G24>=$H$6-0.0001,G24<$H$7-0.0001),AND(G24>=$I$6-0.0001,G24<$I$7-0.0001),AND(G24>=$J$6-0.0001,G24<$J$7-0.0001),AND(G24>=$K$6-0.0001,G24<$K$7-0.0001)),1,0) -> 1 | N24: =IFERROR(INDEX($B$10:$E$10,1,MATCH(999999,$B24:$E24)),"-") -> PM | O24: =IF(G24=0,"",G24) -> 0.67708333 | P24: =SUM(B24:E24) -> 884 | Q24: =P24*L24 -> 884
A25: 0.6875 | D25: 997 | G25: =A25 -> 0.6875 | H25: =IF(B25<>0,SUMIF($G$11:$G25,">"&$G25-1/24,B$11:B25),0) -> 0 | I25: =IF(C25<>0,SUMIF($G$11:$G25,">"&$G25-1/24,C$11:C25),0) -> 0 | J25: =IF(D25<>0,SUMIF($G$11:$G25,">"&$G25-1/24,D$11:D25),0) -> 2786 | K25: =IF(E25<>0,SUMIF($G$11:$G25,">"&$G25-1/24,E$11:E25),0) -> 0 | L25: =IF(OR(AND(G25>=$H$6-0.0001,G25<$H$7-0.0001),AND(G25>=$I$6-0.0001,G25<$I$7-0.0001),AND(G25>=$J$6-0.0001,G25<$J$7-0.0001),AND(G25>=$K$6-0.0001,G25<$K$7-0.0001)),1,0) -> 1 | N25: =IFERROR(INDEX($B$10:$E$10,1,MATCH(999999,$B25:$E25)),"-") -> PM | O25: =IF(G25=0,"",G25) -> 0.6875 | P25: =SUM(B25:E25) -> 997 | Q25: =P25*L25 -> 997
A26: 0.69791667 | D26: 880 | G26: =A26 -> 0.69791667 | H26: =IF(B26<>0,SUMIF($G$11:$G26,">"&$G26-1/24,B$11:B26),0) -> 0 | I26: =IF(C26<>0,SUMIF($G$11:$G26,">"&$G26-1/24,C$11:C26),0) -> 0 | J26: =IF(D26<>0,SUMIF($G$11:$G26,">"&$G26-1/24,D$11:D26),0) -> 3666 | K26: =IF(E26<>0,SUMIF($G$11:$G26,">"&$G26-1/24,E$11:E26),0) -> 0 | L26: =IF(OR(AND(G26>=$H$6-0.0001,G26<$H$7-0.0001),AND(G26>=$I$6-0.0001,G26<$I$7-0.0001),AND(G26>=$J$6-0.0001,G26<$J$7-0.0001),AND(G26>=$K$6-0.0001,G26<$K$7-0.0001)),1,0) -> 1 | N26: =IFERROR(INDEX($B$10:$E$10,1,MATCH(999999,$B26:$E26)),"-") -> PM | O26: =IF(G26=0,"",G26) -> 0.69791667 | P26: =SUM(B26:E26) -> 880 | Q26: =P26*L26 -> 880
A27: 0.70833333 | D27: 911 | G27: =A27 -> 0.70833333 | H27: =IF(B27<>0,SUMIF($G$11:$G27,">"&$G27-1/24,B$11:B27),0) -> 0 | I27: =IF(C27<>0,SUMIF($G$11:$G27,">"&$G27-1/24,C$11:C27),0) -> 0 | J27: =IF(D27<>0,SUMIF($G$11:$G27,">"&$G27-1/24,D$11:D27),0) -> 3672 | K27: =IF(E27<>0,SUMIF($G$11:$G27,">"&$G27-1/24,E$11:E27),0) -> 0 | L27: =IF(OR(AND(G27>=$H$6-0.0001,G27<$H$7-0.0001),AND(G27>=$I$6-0.0001,G27<$I$7-0.0001),AND(G27>=$J$6-0.0001,G27<$J$7-0.0001),AND(G27>=$K$6-0.0001,G27<$K$7-0.0001)),1,0) -> 1 | N27: =IFERROR(INDEX($B$10:$E$10,1,MATCH(999999,$B27:$E27)),"-") -> PM | O27: =IF(G27=0,"",G27) -> 0.70833333 | P27: =SUM(B27:E27) -> 911 | Q27: =P27*L27 -> 911
A28: 0.71875 | D28: 836 | G28: =A28 -> 0.71875 | H28: =IF(B28<>0,SUMIF($G$11:$G28,">"&$G28-1/24,B$11:B28),0) -> 0 | I28: =IF(C28<>0,SUMIF($G$11:$G28,">"&$G28-1/24,C$11:C28),0) -> 0 | J28: =IF(D28<>0,SUMIF($G$11:$G28,">"&$G28-1/24,D$11:D28),0) -> 3624 | K28: =IF(E28<>0,SUMIF($G$11:$G28,">"&$G28-1/24,E$11:E28),0) -> 0 | L28: =IF(OR(AND(G28>=$H$6-0.0001,G28<$H$7-0.0001),AND(G28>=$I$6-0.0001,G28<$I$7-0.0001),AND(G28>=$J$6-0.0001,G28<$J$7-0.0001),AND(G28>=$K$6-0.0001,G28<$K$7-0.0001)),1,0) -> 0 | N28: =IFERROR(INDEX($B$10:$E$10,1,MATCH(999999,$B28:$E28)),"-") -> PM | O28: =IF(G28=0,"",G28) -> 0.71875 | P28: =SUM(B28:E28) -> 836 | Q28: =P28*L28 -> 0
A29: 0.72916667 | D29: 807 | G29: =A29 -> 0.72916667 | H29: =IF(B29<>0,SUMIF($G$11:$G29,">"&$G29-1/24,B$11:B29),0) -> 0 | I29: =IF(C29<>0,SUMIF($G$11:$G29,">"&$G29-1/24,C$11:C29),0) -> 0 | J29: =IF(D29<>0,SUMIF($G$11:$G29,">"&$G29-1/24,D$11:D29),0) -> 3434 | K29: =IF(E29<>0,SUMIF($G$11:$G29,">"&$G29-1/24,E$11:E29),0) -> 0 | L29: =IF(OR(AND(G29>=$H$6-0.0001,G29<$H$7-0.0001),AND(G29>=$I$6-0.0001,G29<$I$7-0.0001),AND(G29>=$J$6-0.0001,G29<$J$7-0.0001),AND(G29>=$K$6-0.0001,G29<$K$7-0.0001)),1,0) -> 0 | N29: =IFERROR(INDEX($B$10:$E$10,1,MATCH(999999,$B29:$E29)),"-") -> PM | O29: =IF(G29=0,"",G29) -> 0.72916667 | P29: =SUM(B29:E29) -> 807 | Q29: =P29*L29 -> 0
A30: 0.73958333 | D30: 609 | G30: =A30 -> 0.73958333 | H30: =IF(B30<>0,SUMIF($G$11:$G30,">"&$G30-1/24,B$11:B30),0) -> 0 | I30: =IF(C30<>0,SUMIF($G$11:$G30,">"&$G30-1/24,C$11:C30),0) -> 0 | J30: =IF(D30<>0,SUMIF($G$11:$G30,">"&$G30-1/24,D$11:D30),0) -> 3163 | K30: =IF(E30<>0,SUMIF($G$11:$G30,">"&$G30-1/24,E$11:E30),0) -> 0 | L30: =IF(OR(AND(G30>=$H$6-0.0001,G30<$H$7-0.0001),AND(G30>=$I$6-0.0001,G30<$I$7-0.0001),AND(G30>=$J$6-0.0001,G30<$J$7-0.0001),AND(G30>=$K$6-0.0001,G30<$K$7-0.0001)),1,0) -> 0 | N30: =IFERROR(INDEX($B$10:$E$10,1,MATCH(999999,$B30:$E30)),"-") -> PM | O30: =IF(G30=0,"",G30) -> 0.73958333 | P30: =SUM(B30:E30) -> 609 | Q30: =P30*L30 -> 0
G31: =A31 -> 0 | H31: =IF(B31<>0,SUMIF($G$11:$G31,">"&$G31-1/24,B$11:B31),0) -> 0 | I31: =IF(C31<>0,SUMIF($G$11:$G31,">"&$G31-1/24,C$11:C31),0) -> 0 | J31: =IF(D31<>0,SUMIF($G$11:$G31,">"&$G31-1/24,D$11:D31),0) -> 0 | K31: =IF(E31<>0,SUMIF($G$11:$G31,">"&$G31-1/24,E$11:E31),0) -> 0 | L31: =IF(OR(AND(G31>=$H$6-0.0001,G31<$H$7-0.0001),AND(G31>=$I$6-0.0001,G31<$I$7-0.0001),AND(G31>=$J$6-0.0001,G31<$J$7-0.0001),AND(G31>=$K$6-0.0001,G31<$K$7-0.0001)),1,0) -> 0 | N31: =IFERROR(INDEX($B$10:$E$10,1,MATCH(999999,$B31:$E31)),"-") -> - | O31: =IF(G31=0,"",G31) | P31: =SUM(B31:E31) -> 0 | Q31: =P31*L31 -> 0
G32: =A32 -> 0 | H32: =IF(B32<>0,SUMIF($G$11:$G32,">"&$G32-1/24,B$11:B32),0) -> 0 | I32: =IF(C32<>0,SUMIF($G$11:$G32,">"&$G32-1/24,C$11:C32),0) -> 0 | J32: =IF(D32<>0,SUMIF($G$11:$G32,">"&$G32-1/24,D$11:D32),0) -> 0 | K32: =IF(E32<>0,SUMIF($G$11:$G32,">"&$G32-1/24,E$11:E32),0) -> 0 | L32: =IF(OR(AND(G32>=$H$6-0.0001,G32<$H$7-0.0001),AND(G32>=$I$6-0.0001,G32<$I$7-0.0001),AND(G32>=$J$6-0.0001,G32<$J$7-0.0001),AND(G32>=$K$6-0.0001,G32<$K$7-0.0001)),1,0) -> 0 | N32: =IFERROR(INDEX($B$10:$E$10,1,MATCH(999999,$B32:$E32)),"-") -> - | O32: =IF(G32=0,"",G32) | P32: =SUM(B32:E32) -> 0 | Q32: =P32*L32 -> 0
G33: =A33 -> 0 | H33: =IF(B33<>0,SUMIF($G$11:$G33,">"&$G33-1/24,B$11:B33),0) -> 0 | I33: =IF(C33<>0,SUMIF($G$11:$G33,">"&$G33-1/24,C$11:C33),0) -> 0 | J33: =IF(D33<>0,SUMIF($G$11:$G33,">"&$G33-1/24,D$11:D33),0) -> 0 | K33: =IF(E33<>0,SUMIF($G$11:$G33,">"&$G33-1/24,E$11:E33),0) -> 0 | L33: =IF(OR(AND(G33>=$H$6-0.0001,G33<$H$7-0.0001),AND(G33>=$I$6-0.0001,G33<$I$7-0.0001),AND(G33>=$J$6-0.0001,G33<$J$7-0.0001),AND(G33>=$K$6-0.0001,G33<$K$7-0.0001)),1,0) -> 0 | N33: =IFERROR(INDEX($B$10:$E$10,1,MATCH(999999,$B33:$E33)),"-") -> - | O33: =IF(G33=0,"",G33) | P33: =SUM(B33:E33) -> 0 | Q33: =P33*L33 -> 0
G34: =A34 -> 0 | H34: =IF(B34<>0,SUMIF($G$11:$G34,">"&$G34-1/24,B$11:B34),0) -> 0 | I34: =IF(C34<>0,SUMIF($G$11:$G34,">"&$G34-1/24,C$11:C34),0) -> 0 | J34: =IF(D34<>0,SUMIF($G$11:$G34,">"&$G34-1/24,D$11:D34),0) -> 0 | K34: =IF(E34<>0,SUMIF($G$11:$G34,">"&$G34-1/24,E$11:E34),0) -> 0 | L34: =IF(OR(AND(G34>=$H$6-0.0001,G34<$H$7-0.0001),AND(G34>=$I$6-0.0001,G34<$I$7-0.0001),AND(G34>=$J$6-0.0001,G34<$J$7-0.0001),AND(G34>=$K$6-0.0001,G34<$K$7-0.0001)),1,0) -> 0 | N34: =IFERROR(INDEX($B$10:$E$10,1,MATCH(999999,$B34:$E34)),"-") -> - | O34: =IF(G34=0,"",G34) | P34: =SUM(B34:E34) -> 0 | Q34: =P34*L34 -> 0
G35: =A35 -> 0 | H35: =IF(B35<>0,SUMIF($G$11:$G35,">"&$G35-1/24,B$11:B35),0) -> 0 | I35: =IF(C35<>0,SUMIF($G$11:$G35,">"&$G35-1/24,C$11:C35),0) -> 0 | J35: =IF(D35<>0,SUMIF($G$11:$G35,">"&$G35-1/24,D$11:D35),0) -> 0 | K35: =IF(E35<>0,SUMIF($G$11:$G35,">"&$G35-1/24,E$11:E35),0) -> 0 | L35: =IF(OR(AND(G35>=$H$6-0.0001,G35<$H$7-0.0001),AND(G35>=$I$6-0.0001,G35<$I$7-0.0001),AND(G35>=$J$6-0.0001,G35<$J$7-0.0001),AND(G35>=$K$6-0.0001,G35<$K$7-0.0001)),1,0) -> 0 | N35: =IFERROR(INDEX($B$10:$E$10,1,MATCH(999999,$B35:$E35)),"-") -> - | O35: =IF(G35=0,"",G35) | P35: =SUM(B35:E35) -> 0 | Q35: =P35*L35 -> 0
G36: =A36 -> 0 | H36: =IF(B36<>0,SUMIF($G$11:$G36,">"&$G36-1/24,B$11:B36),0) -> 0 | I36: =IF(C36<>0,SUMIF($G$11:$G36,">"&$G36-1/24,C$11:C36),0) -> 0 | J36: =IF(D36<>0,SUMIF($G$11:$G36,">"&$G36-1/24,D$11:D36),0) -> 0 | K36: =IF(E36<>0,SUMIF($G$11:$G36,">"&$G36-1/24,E$11:E36),0) -> 0 | L36: =IF(OR(AND(G36>=$H$6-0.0001,G36<$H$7-0.0001),AND(G36>=$I$6-0.0001,G36<$I$7-0.0001),AND(G36>=$J$6-0.0001,G36<$J$7-0.0001),AND(G36>=$K$6-0.0001,G36<$K$7-0.0001)),1,0) -> 0 | N36: =IFERROR(INDEX($B$10:$E$10,1,MATCH(999999,$B36:$E36)),"-") -> - | O36: =IF(G36=0,"",G36) | P36: =SUM(B36:E36) -> 0 | Q36: =P36*L36 -> 0
G37: =A37 -> 0 | H37: =IF(B37<>0,SUMIF($G$11:$G37,">"&$G37-1/24,B$11:B37),0) -> 0 | I37: =IF(C37<>0,SUMIF($G$11:$G37,">"&$G37-1/24,C$11:C37),0) -> 0 | J37: =IF(D37<>0,SUMIF($G$11:$G37,">"&$G37-1/24,D$11:D37),0) -> 0 | K37: =IF(E37<>0,SUMIF($G$11:$G37,">"&$G37-1/24,E$11:E37),0) -> 0 | L37: =IF(OR(AND(G37>=$H$6-0.0001,G37<$H$7-0.0001),AND(G37>=$I$6-0.0001,G37<$I$7-0.0001),AND(G37>=$J$6-0.0001,G37<$J$7-0.0001),AND(G37>=$K$6-0.0001,G37<$K$7-0.0001)),1,0) -> 0 | N37: =IFERROR(INDEX($B$10:$E$10,1,MATCH(999999,$B37:$E37)),"-") -> - | O37: =IF(G37=0,"",G37) | P37: =SUM(B37:E37) -> 0 | Q37: =P37*L37 -> 0
G38: =A38 -> 0 | H38: =IF(B38<>0,SUMIF($G$11:$G38,">"&$G38-1/24,B$11:B38),0) -> 0 | I38: =IF(C38<>0,SUMIF($G$11:$G38,">"&$G38-1/24,C$11:C38),0) -> 0 | J38: =IF(D38<>0,SUMIF($G$11:$G38,">"&$G38-1/24,D$11:D38),0) -> 0 | K38: =IF(E38<>0,SUMIF($G$11:$G38,">"&$G38-1/24,E$11:E38),0) -> 0 | L38: =IF(OR(AND(G38>=$H$6-0.0001,G38<$H$7-0.0001),AND(G38>=$I$6-0.0001,G38<$I$7-0.0001),AND(G38>=$J$6-0.0001,G38<$J$7-0.0001),AND(G38>=$K$6-0.0001,G38<$K$7-0.0001)),1,0) -> 0 | N38: =IFERROR(INDEX($B$10:$E$10,1,MATCH(999999,$B38:$E38)),"-") -> - | O38: =IF(G38=0,"",G38) | P38: =SUM(B38:E38) -> 0 | Q38: =P38*L38 -> 0
G39: =A39 -> 0 | H39: =IF(B39<>0,SUMIF($G$11:$G39,">"&$G39-1/24,B$11:B39),0) -> 0 | I39: =IF(C39<>0,SUMIF($G$11:$G39,">"&$G39-1/24,C$11:C39),0) -> 0 | J39: =IF(D39<>0,SUMIF($G$11:$G39,">"&$G39-1/24,D$11:D39),0) -> 0 | K39: =IF(E39<>0,SUMIF($G$11:$G39,">"&$G39-1/24,E$11:E39),0) -> 0 | L39: =IF(OR(AND(G39>=$H$6-0.0001,G39<$H$7-0.0001),AND(G39>=$I$6-0.0001,G39<$I$7-0.0001),AND(G39>=$J$6-0.0001,G39<$J$7-0.0001),AND(G39>=$K$6-0.0001,G39<$K$7-0.0001)),1,0) -> 0 | N39: =IFERROR(INDEX($B$10:$E$10,1,MATCH(999999,$B39:$E39)),"-") -> - | O39: =IF(G39=0,"",G39) | P39: =SUM(B39:E39) -> 0 | Q39: =P39*L39 -> 0
G40: =A40 -> 0 | H40: =IF(B40<>0,SUMIF($G$11:$G40,">"&$G40-1/24,B$11:B40),0) -> 0 | I40: =IF(C40<>0,SUMIF($G$11:$G40,">"&$G40-1/24,C$11:C40),0) -> 0 | J40: =IF(D40<>0,SUMIF($G$11:$G40,">"&$G40-1/24,D$11:D40),0) -> 0 | K40: =IF(E40<>0,SUMIF($G$11:$G40,">"&$G40-1/24,E$11:E40),0) -> 0 | L40: =IF(OR(AND(G40>=$H$6-0.0001,G40<$H$7-0.0001),AND(G40>=$I$6-0.0001,G40<$I$7-0.0001),AND(G40>=$J$6-0.0001,G40<$J$7-0.0001),AND(G40>=$K$6-0.0001,G40<$K$7-0.0001)),1,0) -> 0 | N40: =IFERROR(INDEX($B$10:$E$10,1,MATCH(999999,$B40:$E40)),"-") -> - | O40: =IF(G40=0,"",G40) | P40: =SUM(B40:E40) -> 0 | Q40: =P40*L40 -> 0
G41: =A41 -> 0 | H41: =IF(B41<>0,SUMIF($G$11:$G41,">"&$G41-1/24,B$11:B41),0) -> 0 | I41: =IF(C41<>0,SUMIF($G$11:$G41,">"&$G41-1/24,C$11:C41),0) -> 0 | J41: =IF(D41<>0,SUMIF($G$11:$G41,">"&$G41-1/24,D$11:D41),0) -> 0 | K41: =IF(E41<>0,SUMIF($G$11:$G41,">"&$G41-1/24,E$11:E41),0) -> 0 | L41: =IF(OR(AND(G41>=$H$6-0.0001,G41<$H$7-0.0001),AND(G41>=$I$6-0.0001,G41<$I$7-0.0001),AND(G41>=$J$6-0.0001,G41<$J$7-0.0001),AND(G41>=$K$6-0.0001,G41<$K$7-0.0001)),1,0) -> 0 | N41: =IFERROR(INDEX($B$10:$E$10,1,MATCH(999999,$B41:$E41)),"-") -> - | O41: =IF(G41=0,"",G41) | P41: =SUM(B41:E41) -> 0 | Q41: =P41*L41 -> 0
G42: =A42 -> 0 | H42: =IF(B42<>0,SUMIF($G$11:$G42,">"&$G42-1/24,B$11:B42),0) -> 0 | I42: =IF(C42<>0,SUMIF($G$11:$G42,">"&$G42-1/24,C$11:C42),0) -> 0 | J42: =IF(D42<>0,SUMIF($G$11:$G42,">"&$G42-1/24,D$11:D42),0) -> 0 | K42: =IF(E42<>0,SUMIF($G$11:$G42,">"&$G42-1/24,E$11:E42),0) -> 0 | L42: =IF(OR(AND(G42>=$H$6-0.0001,G42<$H$7-0.0001),AND(G42>=$I$6-0.0001,G42<$I$7-0.0001),AND(G42>=$J$6-0.0001,G42<$J$7-0.0001),AND(G42>=$K$6-0.0001,G42<$K$7-0.0001)),1,0) -> 0 | N42: =IFERROR(INDEX($B$10:$E$10,1,MATCH(999999,$B42:$E42)),"-") -> - | O42: =IF(G42=0,"",G42) | P42: =SUM(B42:E42) -> 0 | Q42: =P42*L42 -> 0
...

Sheet GraphData
B2: Survey Period | C2: AM
E3: ="Vehicle Count for "&$C$2&" Period" -> Vehicle Count for AM Period
B4: Row Labels | C4: Sum of Count | E4: ="Vehicle Count by Approach Leg for "&C2&" Period" -> Vehicle Count by Approach Leg for AM Period
B5: 0.29166667 | C5: 705 | E5: ="Vehicle Count by Exit Leg for "&C2&" Period" -> Vehicle Count by Exit Leg for AM Period
B6: 0.30208333 | C6: 824
B7: 0.3125 | C7: 787
B8: 0.32291667 | C8: 833
B9: 0.33333333 | C9: 763
B10: 0.34375 | C10: 796
B11: 0.35416667 | C11: 824
B12: 0.36458333 | C12: 675

Sheet Graphs
B2: Vehicle Counts
B4: Select Survey Period to view
J24: Approach Leg | S24: Exit Leg
C25: Total | K25: Buchanans Road East | L25: Buchanans Road West | M25: Carmen Road North | N25: Carmen Road South | T25: Buchanans Road East | U25: Buchanans Road West | V25: Carmen Road North | W25: Carmen Road South
B26: 0.29166667 | C26: 705 | J26: 0.29166667 | K26: 73 | L26: 119 | M26: 323 | N26: 190 | S26: 0.29166667 | T26: 87 | U26: 74 | V26: 230 | W26: 314
B27: 0.30208333 | C27: 824 | J27: 0.30208333 | K27: 61 | L27: 131 | M27: 384 | N27: 248 | S27: 0.30208333 | T27: 119 | U27: 71 | V27: 260 | W27: 374
B28: 0.3125 | C28: 787 | J28: 0.3125 | K28: 76 | L28: 151 | M28: 312 | N28: 248 | S28: 0.3125 | T28: 124 | U28: 81 | V28: 287 | W28: 295
B29: 0.32291667 | C29: 833 | J29: 0.32291667 | K29: 76 | L29: 131 | M29: 372 | N29: 254 | S29: 0.32291667 | T29: 110 | U29: 72 | V29: 262 | W29: 389
B30: 0.33333333 | C30: 763 | J30: 0.33333333 | K30: 68 | L30: 133 | M30: 300 | N30: 262 | S30: 0.33333333 | T30: 120 | U30: 72 | V30: 271 | W30: 300
B31: 0.34375 | C31: 796 | J31: 0.34375 | K31: 93 | L31: 121 | M31: 323 | N31: 259 | S31: 0.34375 | T31: 104 | U31: 114 | V31: 259 | W31: 319
B32: 0.35416667 | C32: 824 | J32: 0.35416667 | K32: 80 | L32: 136 | M32: 315 | N32: 293 | S32: 0.35416667 | T32: 99 | U32: 95 | V32: 310 | W32: 320
B33: 0.36458333 | C33: 675 | J33: 0.36458333 | K33: 62 | L33: 102 | M33: 296 | N33: 215 | S33: 0.36458333 | T33: 77 | U33: 86 | V33: 207 | W33: 305
B34: Grand Total | C34: 6207 | J34: Grand Total | K34: 589 | L34: 1024 | M34: 2625 | N34: 1969 | S34: Grand Total | T34: 840 | U34: 665 | V34: 2086 | W34: 2616

Sheet Peak Hour
B2: Peak Hour
B4: =PeakCalc!H8 -> The peak hour for AM is 3216 vehicles between 07:45 and 08:45
