Workbook
Name rngApproaches: Ranges!$B$4:$H$4
Name rngAxisLabels: OFFSET(Graph!$A$9,0,0,COUNTA(Graph!$B$9:$B$10000),1)
Name rngBasicInfo: Input!$C$9:$C$12
Name rngCountInterval: Input!$I$9
Name rngGPS: Input!$C$16
Name rngMovements: Ranges!$B$8:$H$14
Name rngQueueLimits: Graph!$O$5:$BL$10
Name rngSeriesLimit1: OFFSET(Graph!$C$9,0,0,COUNTA(Graph!$B$9:$B$10000),1)
Name rngSeriesLimit2: OFFSET(Graph!$D$9,0,0,COUNTA(Graph!$B$9:$B$10000),1)
Name rngSeriesQueue: OFFSET(Graph!$B$9,0,0,COUNTA(Graph!$B$9:$B$10000),1)
Name rngSurveyPeriods: Input!$I$12:$L$14
Name Slicer_Approach: #N/A
Name Slicer_Movement: #N/A
Name Slicer_Survey_Period: #N/A

Sheet Input
B2: Queue Count Template
B4: Fill in blue cells. Leave blank if not required.
B7: Basic Info | H7: Time Periods
B9: Intersection: | C9: Smith Street_Queue | H9: Count Interval | I9: 5 | J9: minutes
B10: Conditions: | C10: Fine
B11: Date: | C11: Thurs 14/09/2023 | I11: Survey Period 1 | J11: Survey Period 2 | K11: Survey Period 3 | L11: Survey Period 4
B12: Notes: | H12: Name | I12: AM | J12: IP | K12: PM
H13: Start Time | I13: 0.29166667 | J13: 0.45833333 | K13: 0.66666667
C14: Note: do not use "/" or ":" in Intersection Name | H14: End Time | I14: 0.37152778 | J14: 0.53819444 | K14: 0.74652778
B16: GPS (Center)
B18: Movements
B20: Approach 1 | C20: Smith Street North
B22: Queue 1 | C22: Lane 1 Left Turn | E22: Notes
B23: Queue 2 | C23: Lane 2 Right Turn | E23: *Combine Direction & Lane Number if necessary e.g "Thru - Lane 1" and "Thru - Lane 2"
B24: Queue 3
B25: Queue 4
B26: Queue 5
B27: Queue 6
B28: Queue 7
B31: Approach 2 | D31: GPS
B33: Queue 1
B34: Queue 2
B35: Queue 3
B36: Queue 4
B37: Queue 5
B38: Queue 6
B39: Queue 7
B42: Approach 3 | D42: GPS
B44: Queue 1
B45: Queue 2
B46: Queue 3
B47: Queue 4
B48: Queue 5
B49: Queue 6
B50: Queue 7
B53: Approach 4 | D53: GPS
B55: Queue 1
B56: Queue 2
B57: Queue 3
B58: Queue 4
...

Sheet Ranges
B2: Approaches
B4: =Input!C20 -> Smith Street North | C4: =Input!C31 -> 0 | D4: =Input!C42 -> 0 | E4: =Input!C53 -> 0 | F4: =Input!C64 -> 0 | G4: =Input!C75 -> 0 | H4: =Input!C86 -> 0
B6: Lanes
B8: =Input!C22 -> Lane 1 Left Turn | C8: =Input!C33 -> 0 | D8: =Input!C44 -> 0 | E8: =Input!C55 -> 0 | F8: =Input!C66 -> 0 | G8: =Input!C77 -> 0 | H8: =Input!C88 -> 0
B9: =Input!C23 -> Lane 2 Right Turn | C9: =Input!C34 -> 0 | D9: =Input!C45 -> 0 | E9: =Input!C56 -> 0 | F9: =Input!C67 -> 0 | G9: =Input!C78 -> 0 | H9: =Input!C89 -> 0
B10: =Input!C24 -> 0 | C10: =Input!C35 -> 0 | D10: =Input!C46 -> 0 | E10: =Input!C57 -> 0 | F10: =Input!C68 -> 0 | G10: =Input!C79 -> 0 | H10: =Input!C90 -> 0
B11: =Input!C25 -> 0 | C11: =Input!C36 -> 0 | D11: =Input!C47 -> 0 | E11: =Input!C58 -> 0 | F11: =Input!C69 -> 0 | G11: =Input!C80 -> 0 | H11: =Input!C91 -> 0
B12: =Input!C26 -> 0 | C12: =Input!C37 -> 0 | D12: =Input!C48 -> 0 | E12: =Input!C59 -> 0 | F12: =Input!C70 -> 0 | G12: =Input!C81 -> 0 | H12: =Input!C92 -> 0
B13: =Input!C27 -> 0 | C13: =Input!C38 -> 0 | D13: =Input!C49 -> 0 | E13: =Input!C60 -> 0 | F13: =Input!C71 -> 0 | G13: =Input!C82 -> 0 | H13: =Input!C93 -> 0
B14: =Input!C28 -> 0 | C14: =Input!C39 -> 0 | D14: =Input!C50 -> 0 | E14: =Input!C61 -> 0 | F14: =Input!C72 -> 0 | G14: =Input!C83 -> 0 | H14: =Input!C94 -> 0

Sheet Table
A1: Smith Street_Queue Fine Thurs 14/09/2023
B5: AM | F5: IP | J5: PM
B6: Smith Street North | F6: Smith Street North | J6: Smith Street North
A7: Time | B7: Lane 1 Left Turn | C7: Lane 2 Right Turn | E7: Time | F7: Lane 1 Left Turn | G7: Lane 2 Right Turn | I7: Time | J7: Lane 1 Left Turn | K7: Lane 2 Right Turn
A8: 0.29166667 | C8: 1 | E8: 0.45833333 | F8: 2 | I8: 0.66666667 | K8: 1
A9: 0.29513889 | C9: 3 | E9: 0.46180556 | F9: 2 | I9: 0.67013889 | J9: 1 | K9: 2
A10: 0.29861111 | C10: 1 | E10: 0.46527778 | F10: 1 | G10: 2 | I10: 0.67361111 | J10: 1 | K10: 2
A11: 0.30208333 | C11: 1 | E11: 0.46875 | I11: 0.67708333 | J11: 2 | K11: 1
A12: 0.30555556 | C12: 1 | E12: 0.47222222 | G12: 1 | I12: 0.68055556
A13: 0.30902778 | C13: 1 | E13: 0.47569444 | F13: 1 | G13: 1 | I13: 0.68402778 | J13: 2
A14: 0.3125 | E14: 0.47916667 | G14: 1 | I14: 0.6875 | J14: 1
A15: 0.31597222 | E15: 0.48263889 | F15: 1 | I15: 0.69097222 | J15: 1 | K15: 1
A16: 0.31944444 | C16: 1 | E16: 0.48611111 | F16: 1 | I16: 0.69444444 | J16: 1
A17: 0.32291667 | E17: 0.48958333 | F17: 1 | I17: 0.69791667 | J17: 1 | K17: 1
A18: 0.32638889 | B18: 1 | E18: 0.49305556 | F18: 1 | G18: 1 | I18: 0.70138889 | J18: 1
A19: 0.32986111 | E19: 0.49652778 | F19: 4 | G19: 1 | I19: 0.70486111 | J19: 1 | K19: 1
A20: 0.33333333 | B20: 1 | C20: 1 | E20: 0.5 | F20: 1 | G20: 1 | I20: 0.70833333 | J20: 1 | K20: 2
A21: 0.33680556 | B21: 1 | C21: 1 | E21: 0.50347222 | G21: 1 | I21: 0.71180556 | J21: 2 | K21: 1
A22: 0.34027778 | B22: 1 | E22: 0.50694444 | F22: 1 | G22: 1 | I22: 0.71527778 | J22: 1
A23: 0.34375 | B23: 1 | E23: 0.51041667 | F23: 1 | G23: 1 | I23: 0.71875 | J23: 1
A24: 0.34722222 | B24: 1 | C24: 1 | E24: 0.51388889 | F24: 1 | G24: 1 | I24: 0.72222222 | J24: 2 | K24: 1
A25: 0.35069444 | B25: 1 | C25: 1 | E25: 0.51736111 | G25: 1 | I25: 0.72569444 | J25: 2 | K25: 1
A26: 0.35416667 | B26: 3 | E26: 0.52083333 | F26: 1 | I26: 0.72916667 | J26: 1 | K26: 1
A27: 0.35763889 | B27: 4 | C27: 1 | E27: 0.52430556 | F27: 1 | I27: 0.73263889 | J27: 1 | K27: 1
A28: 0.36111111 | B28: 1 | E28: 0.52777778 | F28: 1 | G28: 1 | I28: 0.73611111 | J28: 1
A29: 0.36458333 | B29: 1 | C29: 1 | E29: 0.53125 | F29: 1 | G29: 1 | I29: 0.73958333 | J29: 2 | K29: 1
A30: 0.36805556 | B30: 1 | E30: 0.53472222 | F30: 1 | I30: 0.74305556 | K30: 1
A31: 0.37152778 | B31: 1 | E31: 0.53819444 | F31: 1 | G31: 1 | I31: 0.74652778 | J31: 1 | K31: 1

Sheet Statistics
A2: Key Statistics
A3: Queue Length (cars)
B5: AM | F5: IP | J5: PM
B6: Smith Street North | F6: Smith Street North | J6: Smith Street North
B7: Lane 1 Left Turn | C7: Lane 2 Right Turn | F7: Lane 1 Left Turn | G7: Lane 2 Right Turn | J7: Lane 1 Left Turn | K7: Lane 2 Right Turn
A8: Mean | B8: =IFERROR(AVERAGE(Table!B:B),"-") -> 1.3846154 | C8: =IFERROR(AVERAGE(Table!C:C),"-") -> 1.1538462 | E8: Mean | F8: =IFERROR(AVERAGE(Table!F:F),"-") -> 1.2631579 | G8: =IFERROR(AVERAGE(Table!G:G),"-") -> 1.0666667 | I8: Mean | J8: =IFERROR(AVERAGE(Table!J:J),"-") -> 1.2857143 | K8: =IFERROR(AVERAGE(Table!K:K),"-") -> 1.1875
A9: Minimum | B9: =IFERROR(MIN(Table!B:B),"-") -> 1 | C9: =IFERROR(MIN(Table!C:C),"-") -> 1 | E9: Minimum | F9: =IFERROR(MIN(Table!F:F),"-") -> 1 | G9: =IFERROR(MIN(Table!G:G),"-") -> 1 | I9: Minimum | J9: =IFERROR(MIN(Table!J:J),"-") -> 1 | K9: =IFERROR(MIN(Table!K:K),"-") -> 1
A10: 25th Percentile | B10: =IFERROR(PERCENTILE(Table!B:B,0.25),"-") -> 1 | C10: =IFERROR(PERCENTILE(Table!C:C,0.25),"-") -> 1 | E10: 25th Percentile | F10: =IFERROR(PERCENTILE(Table!F:F,0.25),"-") -> 1 | G10: =IFERROR(PERCENTILE(Table!G:G,0.25),"-") -> 1 | I10: 25th Percentile | J10: =IFERROR(PERCENTILE(Table!J:J,0.25),"-") -> 1 | K10: =IFERROR(PERCENTILE(Table!K:K,0.25),"-") -> 1
A11: 50th Percentile | B11: =IFERROR(PERCENTILE(Table!B:B,0.5),"-") -> 1 | C11: =IFERROR(PERCENTILE(Table!C:C,0.5),"-") -> 1 | E11: 50th Percentile | F11: =IFERROR(PERCENTILE(Table!F:F,0.5),"-") -> 1 | G11: =IFERROR(PERCENTILE(Table!G:G,0.5),"-") -> 1 | I11: 50th Percentile | J11: =IFERROR(PERCENTILE(Table!J:J,0.5),"-") -> 1 | K11: =IFERROR(PERCENTILE(Table!K:K,0.5),"-") -> 1
A12: 75th Percentile | B12: =IFERROR(PERCENTILE(Table!B:B,0.75),"-") -> 1 | C12: =IFERROR(PERCENTILE(Table!C:C,0.75),"-") -> 1 | E12: 75th Percentile | F12: =IFERROR(PERCENTILE(Table!F:F,0.75),"-") -> 1 | G12: =IFERROR(PERCENTILE(Table!G:G,0.75),"-") -> 1 | I12: 75th Percentile | J12: =IFERROR(PERCENTILE(Table!J:J,0.75),"-") -> 2 | K12: =IFERROR(PERCENTILE(Table!K:K,0.75),"-") -> 1
A13: 95th Percentile | B13: =IFERROR(PERCENTILE(Table!B:B,0.95),"-") -> 3.4 | C13: =IFERROR(PERCENTILE(Table!C:C,0.95),"-") -> 1.8 | E13: 95th Percentile | F13: =IFERROR(PERCENTILE(Table!F:F,0.95),"-") -> 2.2 | G13: =IFERROR(PERCENTILE(Table!G:G,0.95),"-") -> 1.3 | I13: 95th Percentile | J13: =IFERROR(PERCENTILE(Table!J:J,0.95),"-") -> 2 | K13: =IFERROR(PERCENTILE(Table!K:K,0.95),"-") -> 2
A14: Maximum | B14: =IFERROR(MAX(Table!B:B),"-") -> 4 | C14: =IFERROR(MAX(Table!C:C),"-") -> 3 | E14: Maximum | F14: =IFERROR(MAX(Table!F:F),"-") -> 4 | G14: =IFERROR(MAX(Table!G:G),"-") -> 2 | I14: Maximum | J14: =IFERROR(MAX(Table!J:J),"-") -> 2 | K14: =IFERROR(MAX(Table!K:K),"-") -> 2
B15: =IF(SUMPRODUCT(ISTEXT(Table!B8:B1500)*1)>0,"Data contains text, statistics may be incorrect!","") | C15: =IF(SUMPRODUCT(ISTEXT(Table!C8:C1500)*1)>0,"Data contains text, statistics may be incorrect!","") | F15: =IF(SUMPRODUCT(ISTEXT(Table!F8:F1500)*1)>0,"Data contains text, statistics may be incorrect!","") | G15: =IF(SUMPRODUCT(ISTEXT(Table!G8:G1500)*1)>0,"Data contains text, statistics may be incorrect!","") | J15: =IF(SUMPRODUCT(ISTEXT(Table!J8:J1500)*1)>0,"Data contains text, statistics may be incorrect!","") | K15: =IF(SUMPRODUCT(ISTEXT(Table!K8:K1500)*1)>0,"Data contains text, statistics may be incorrect!","")
A18: Q1 | B18: =B10 -> 1 | C18: =C10 -> 1 | F18: =F10 -> 1 | G18: =G10 -> 1 | J18: =J10 -> 1 | K18: =K10 -> 1
A19: Q3 | B19: =B12 -> 1 | C19: =C12 -> 1 | F19: =F12 -> 1 | G19: =G12 -> 1 | J19: =J12 -> 2 | K19: =K12 -> 1
A20: Q1-Minimum | B20: =B18-B9 -> 0 | C20: =C18-C9 -> 0 | F20: =F18-F9 -> 0 | G20: =G18-G9 -> 0 | J20: =J18-J9 -> 0 | K20: =K18-K9 -> 0
A21: Q1 | B21: =B18 -> 1 | C21: =C18 -> 1 | F21: =F18 -> 1 | G21: =G18 -> 1 | J21: =J18 -> 1 | K21: =K18 -> 1
A22: Median-Q1 | B22: =B11-B18 -> 0 | C22: =C11-C18 -> 0 | F22: =F11-F18 -> 0 | G22: =G11-G18 -> 0 | J22: =J11-J18 -> 0 | K22: =K11-K18 -> 0
A23: Q3-Median | B23: =B19-B11 -> 0 | C23: =C19-C11 -> 0 | F23: =F19-F11 -> 0 | G23: =G19-G11 -> 0 | J23: =J19-J11 -> 1 | K23: =K19-K11 -> 0
A24: Maximum-Q3 | B24: =B14-B19 -> 3 | C24: =C14-C19 -> 2 | F24: =F14-F19 -> 3 | G24: =G14-G19 -> 1 | J24: =J14-J19 -> 0 | K24: =K14-K19 -> 1

Sheet PivotData
A1: Approach | B1: Movement | C1: Survey Period | D1: Time | E1: Queue Length (cars)
A2: Smith Street North | B2: Lane 1 Left Turn | C2: AM | D2: 0.29166667 | E2: 0
A3: Smith Street North | B3: Lane 1 Left Turn | C3: AM | D3: 0.29513889 | E3: 0
A4: Smith Street North | B4: Lane 1 Left Turn | C4: AM | D4: 0.29861111 | E4: 0
A5: Smith Street North | B5: Lane 1 Left Turn | C5: AM | D5: 0.30208333 | E5: 0
A6: Smith Street North | B6: Lane 1 Left Turn | C6: AM | D6: 0.30555556 | E6: 0
A7: Smith Street North | B7: Lane 1 Left Turn | C7: AM | D7: 0.30902778 | E7: 0
A8: Smith Street North | B8: Lane 1 Left Turn | C8: AM | D8: 0.3125 | E8: 0
A9: Smith Street North | B9: Lane 1 Left Turn | C9: AM | D9: 0.31597222 | E9: 0
A10: Smith Street North | B10: Lane 1 Left Turn | C10: AM | D10: 0.31944444 | E10: 0
A11: Smith Street North | B11: Lane 1 Left Turn | C11: AM | D11: 0.32291667 | E11: 0
A12: Smith Street North | B12: Lane 1 Left Turn | C12: AM | D12: 0.32638889 | E12: 1
A13: Smith Street North | B13: Lane 1 Left Turn | C13: AM | D13: 0.32986111 | E13: 0
... A145: Smith Street North | B145: Lane 2 Right Turn | C145: PM | D145: 0.74652778 | E145: 1

Sheet Graph
A2: Title | B2: ="Surveyed Queue Lengths "&TEXT(Input!C11,"dd/mm/yy")&": "&B4&", "&B5&", "&B6 -> Surveyed Queue Lengths Thurs 14/09/2023: Smith Street North, (All), AM | N2: Queue Limits
N3: Enter queue limits to show on the graph. If no limits are required, leave blank.
A4: Approach | B4: Smith Street North
A5: Movement | B5: (All) | O5: Smith Street North
A6: Survey Period | B6: AM | C6: =INDEX(OFFSET($O$8,0,MATCH($B$4,$O$5:$BL$5,0)-1,1,50),1,MATCH($B$5,OFFSET($O$6,0,MATCH($B$4,$O$5:$BL$5,0)-1,1,50),0)) -> #N/A | D6: =INDEX(OFFSET($O$10,0,MATCH($B$4,$O$5:$BL$5,0)-1,1,50),1,MATCH($B$5,OFFSET($O$6,0,MATCH($B$4,$O$5:$BL$5,0)-1,1,50),0)) -> #N/A | O6: Lane 1 Left Turn | P6: Lane 2 Right Turn
C7: =IF(C6=0,-1,C6) -> #N/A | D7: =IF(D6=0,-1,D6) -> #N/A | N7: Line 1 Name
A8: Row Labels | B8: Sum of Queue Length (cars) | C8: =INDEX(OFFSET($O$7,0,MATCH($B$4,$O$5:$BL$5,0)-1,1,50),1,MATCH($B$5,OFFSET($O$6,0,MATCH($B$4,$O$5:$BL$5,0)-1,1,50),0)) -> #N/A | D8: =INDEX(OFFSET($O$9,0,MATCH($B$4,$O$5:$BL$5,0)-1,1,50),1,MATCH($B$5,OFFSET($O$6,0,MATCH($B$4,$O$5:$BL$5,0)-1,1,50),0)) -> #N/A | E8: Line 1 Labels | F8: Line 2 Labels | N8: Line 1 Value
A9: 0.29166667 | B9: 1 | C9: =$C$7 -> #N/A | D9: =$D$7 -> #N/A | E9: =IF($B10="",C$8,"") | F9: =IF($B10="",D$8,"") | N9: Line 2 Name
A10: 0.29513889 | B10: 3 | C10: =$C$7 -> #N/A | D10: =$D$7 -> #N/A | E10: =IF($B11="",C$8,"") | F10: =IF($B11="",D$8,"") | N10: Line 2 Value
A11: 0.29861111 | B11: 1 | C11: =$C$7 -> #N/A | D11: =$D$7 -> #N/A | E11: =IF($B12="",C$8,"") | F11: =IF($B12="",D$8,"")
A12: 0.30208333 | B12: 1 | C12: =$C$7 -> #N/A | D12: =$D$7 -> #N/A | E12: =IF($B13="",C$8,"") | F12: =IF($B13="",D$8,"")
A13: 0.30555556 | B13: 1 | C13: =$C$7 -> #N/A | D13: =$D$7 -> #N/A | E13: =IF($B14="",C$8,"") | F13: =IF($B14="",D$8,"")
A14: 0.30902778 | B14: 1 | C14: =$C$7 -> #N/A | D14: =$D$7 -> #N/A | E14: =IF($B15="",C$8,"") | F14: =IF($B15="",D$8,"")
A15: 0.3125 | B15: 0 | C15: =$C$7 -> #N/A | D15: =$D$7 -> #N/A | E15: =IF($B16="",C$8,"") | F15: =IF($B16="",D$8,"")
A16: 0.31597222 | B16: 0 | C16: =$C$7 -> #N/A | D16: =$D$7 -> #N/A | E16: =IF($B17="",C$8,"") | F16: =IF($B17="",D$8,"")
A17: 0.31944444 | B17: 1 | C17: =$C$7 -> #N/A | D17: =$D$7 -> #N/A | E17: =IF($B18="",C$8,"") | F17: =IF($B18="",D$8,"")
A18: 0.32291667 | B18: 0 | C18: =$C$7 -> #N/A | D18: =$D$7 -> #N/A | E18: =IF($B19="",C$8,"") | F18: =IF($B19="",D$8,"")
A19: 0.32638889 | B19: 1 | C19: =$C$7 -> #N/A | D19: =$D$7 -> #N/A | E19: =IF($B20="",C$8,"") | F19: =IF($B20="",D$8,"")
A20: 0.32986111 | B20: 0 | C20: =$C$7 -> #N/A | D20: =$D$7 -> #N/A | E20: =IF($B21="",C$8,"") | F20: =IF($B21="",D$8,"")
A21: 0.33333333 | B21: 2 | C21: =$C$7 -> #N/A | D21: =$D$7 -> #N/A | E21: =IF($B22="",C$8,"") | F21: =IF($B22="",D$8,"")
A22: 0.33680556 | B22: 2 | C22: =$C$7 -> #N/A | D22: =$D$7 -> #N/A | E22: =IF($B23="",C$8,"") | F22: =IF($B23="",D$8,"")
... A32: 0.37152778 | B32: 1 | C32: =$C$7 -> #N/A | D32: =$D$7 -> #N/A | E32: =IF($B33="",C$8,"") -> #N/A | F32: =IF($B33="",D$8,"") -> #N/A
C33: =$C$7 -> #N/A | D33: =$D$7 -> #N/A | E33: =IF($B34="",C$8,"") -> #N/A | F33: =IF($B34="",D$8,"") -> #N/A
C34: =$C$7 -> #N/A | D34: =$D$7 -> #N/A | E34: =IF($B35="",C$8,"") -> #N/A | F34: =IF($B35="",D$8,"") -> #N/A
C35: =$C$7 -> #N/A | D35: =$D$7 -> #N/A | E35: =IF($B36="",C$8,"") -> #N/A | F35: =IF($B36="",D$8,"") -> #N/A
C36: =$C$7 -> #N/A | D36: =$D$7 -> #N/A | E36: =IF($B37="",C$8,"") -> #N/A | F36: =IF($B37="",D$8,"") -> #N/A
C37: =$C$7 -> #N/A | D37: =$D$7 -> #N/A | E37: =IF($B38="",C$8,"") -> #N/A | F37: =IF($B38="",D$8,"") -> #N/A
C38: =$C$7 -> #N/A | D38: =$D$7 -> #N/A | E38: =IF($B39="",C$8,"") -> #N/A | F38: =IF($B39="",D$8,"") -> #N/A
C39: =$C$7 -> #N/A | D39: =$D$7 -> #N/A | E39: =IF($B40="",C$8,"") -> #N/A | F39: =IF($B40="",D$8,"") -> #N/A
C40: =$C$7 -> #N/A | D40: =$D$7 -> #N/A | E40: =IF($B41="",C$8,"") -> #N/A | F40: =IF($B41="",D$8,"") -> #N/A
C41: =$C$7 -> #N/A | D41: =$D$7 -> #N/A | E41: =IF($B42="",C$8,"") -> #N/A | F41: =IF($B42="",D$8,"") -> #N/A
C42: =$C$7 -> #N/A | D42: =$D$7 -> #N/A | E42: =IF($B43="",C$8,"") -> #N/A | F42: =IF($B43="",D$8,"") -> #N/A
C43: =$C$7 -> #N/A | D43: =$D$7 -> #N/A | E43: =IF($B44="",C$8,"") -> #N/A | F43: =IF($B44="",D$8,"") -> #N/A
C44: =$C$7 -> #N/A | D44: =$D$7 -> #N/A | E44: =IF($B45="",C$8,"") -> #N/A | F44: =IF($B45="",D$8,"") -> #N/A
... C1408: =$C$7 -> #N/A | D1408: =$D$7 -> #N/A | E1408: =IF($B1409="",C$8,"") -> #N/A | F1408: =IF($B1409="",D$8,"") -> #N/A
