Workbook
Name rngApproaches: Ranges!$B$4:$H$4
Name rngBasicInfo: Input!$C$9:$C$11
Name rngCountInterval: Input!$I$9
Name rngExits: Ranges!$B$18:$H$24
Name rngMovements: Ranges!$B$8:$H$14
Name rngSurveyPeriods: Input!$I$12:$L$14
Name rngVehicleTypes: Input!$E$10:$F$16
Name Slicer_Survey_Period: #N/A
Name Slicer_Survey_Period1: #N/A

Sheet Input
B2: Turning Count Template
B4: Fill in blue cells. Leave blank if not required.
B7: Basic Info | E7: Vehicle Types | H7: Time Periods
B9: Intersection: | C9: Deans Avenue_Riccarton Road_Riccarton Avenue_Intersection | E9: Vehicle Type | F9: HCV? | H9: Count Interval | I9: 15 | J9: minutes
B10: Conditions: | C10: Fine | D10: 1 | E10: Lights
B11: Date: | C11: 44712 | D11: 2 | E11: Buses | I11: Survey Period 1 | J11: Survey Period 2 | K11: Survey Period 3 | L11: Survey Period 4
D12: 3 | E12: Single-Unit Trucks | H12: Name | I12: AM | J12: INT | K12: PM
C13: Note: do not use "/" in Intersection Name | D13: 4 | E13: Articulated Trucks | H13: Start Time | I13: 0.27083333 | J13: 0.45833333 | K13: 0.625
D14: 5 | E14: Bicycles On Road | H14: End Time | I14: 0.38541667 | J14: 0.57291667 | K14: 0.76041667
D15: 6
D16: 7
B18: Movements
B20: Approach 1 | C20: Deans Avenue North
B22: Movement 1 | C22: Left into Riccarton Avenue East | D22: Exit to: | E22: Riccarton Avenue East
B23: Movement 2 | C23: Thru to Deans Avenue South | D23: Exit to: | E23: Deans Avenue South
B24: Movement 3 | C24: Right into Riccarton Road West | D24: Exit to: | E24: Riccarton Road West
B25: Movement 4 | D25: Exit to:
B26: Movement 5 | D26: Exit to:
B27: Movement 6 | D27: Exit to:
B28: Movement 7 | D28: Exit to:
B31: Approach 2 | C31: Riccarton Avenue East
B33: Movement 1 | C33: Left into Deans Avenue South | D33: Exit to: | E33: Deans Avenue South
B34: Movement 2 | C34: Thru to Riccarton Road West | D34: Exit to: | E34: Riccarton Road West
B35: Movement 3 | C35: Right into Deans Avenue North | D35: Exit to: | E35: Deans Avenue North
B36: Movement 4 | D36: Exit to:
B37: Movement 5 | D37: Exit to:
B38: Movement 6 | D38: Exit to:
B39: Movement 7 | D39: Exit to:
B42: Approach 3 | C42: Deans Avenue South
B44: Movement 1 | C44: Left into Riccarton Road West | D44: Exit to: | E44: Riccarton Road West
B45: Movement 2 | C45: Thru to Deans Avenue North | D45: Exit to: | E45: Deans Avenue North
B46: Movement 3 | C46: Right into Riccarton Avenue East | D46: Exit to: | E46: Riccarton Avenue East
B47: Movement 4 | D47: Exit to:
B48: Movement 5 | D48: Exit to:
B49: Movement 6 | D49: Exit to:
B50: Movement 7 | D50: Exit to:
B53: Approach 4 | C53: Riccarton Road West
B55: Movement 1 | C55: Left into Deans Avenue North | D55: Exit to: | E55: Deans Avenue North
B56: Movement 2 | C56: Thru to Riccarton Avenue East | D56: Exit to: | E56: Riccarton Avenue East
B57: Movement 3 | C57: Right into Deans Avenue South | D57: Exit to: | E57: Deans Avenue South
...

Sheet Ranges
B2: Approaches
B4: =Input!C20 -> Deans Avenue North | C4: =Input!C31 -> Riccarton Avenue East | D4: =Input!C42 -> Deans Avenue South | E4: =Input!C53 -> Riccarton Road West | F4: =Input!C64 -> 0 | G4: =Input!C75 -> 0 | H4: =Input!C86 -> 0
B6: Movements
B8: =Input!C22 -> Left into Riccarton Avenue East | C8: =Input!C33 -> Left into Deans Avenue South | D8: =Input!C44 -> Left into Riccarton Road West | E8: =Input!C55 -> Left into Deans Avenue North | F8: =Input!C66 -> 0 | G8: =Input!C77 -> 0 | H8: =Input!C88 -> 0
B9: =Input!C23 -> Thru to Deans Avenue South | C9: =Input!C34 -> Thru to Riccarton Road West | D9: =Input!C45 -> Thru to Deans Avenue North | E9: =Input!C56 -> Thru to Riccarton Avenue East | F9: =Input!C67 -> 0 | G9: =Input!C78 -> 0 | H9: =Input!C89 -> 0
B10: =Input!C24 -> Right into Riccarton Road West | C10: =Input!C35 -> Right into Deans Avenue North | D10: =Input!C46 -> Right into Riccarton Avenue East | E10: =Input!C57 -> Right into Deans Avenue South | F10: =Input!C68 -> 0 | G10: =Input!C79 -> 0 | H10: =Input!C90 -> 0
B11: =Input!C25 -> 0 | C11: =Input!C36 -> 0 | D11: =Input!C47 -> 0 | E11: =Input!C58 -> 0 | F11: =Input!C69 -> 0 | G11: =Input!C80 -> 0 | H11: =Input!C91 -> 0
B12: =Input!C26 -> 0 | C12: =Input!C37 -> 0 | D12: =Input!C48 -> 0 | E12: =Input!C59 -> 0 | F12: =Input!C70 -> 0 | G12: =Input!C81 -> 0 | H12: =Input!C92 -> 0
B13: =Input!C27 -> 0 | C13: =Input!C38 -> 0 | D13: =Input!C49 -> 0 | E13: =Input!C60 -> 0 | F13: =Input!C71 -> 0 | G13: =Input!C82 -> 0 | H13: =Input!C93 -> 0
B14: =Input!C28 -> 0 | C14: =Input!C39 -> 0 | D14: =Input!C50 -> 0 | E14: =Input!C61 -> 0 | F14: =Input!C72 -> 0 | G14: =Input!C83 -> 0 | H14: =Input!C94 -> 0
B16: Exits
B18: =Input!E22 -> Riccarton Avenue East | C18: =Input!E33 -> Deans Avenue South | D18: =Input!E44 -> Riccarton Road West | E18: =Input!E55 -> Deans Avenue North | F18: =Input!E66 -> 0 | G18: =Input!E77 -> 0 | H18: =Input!E88 -> 0
B19: =Input!E23 -> Deans Avenue South | C19: =Input!E34 -> Riccarton Road West | D19: =Input!E45 -> Deans Avenue North | E19: =Input!E56 -> Riccarton Avenue East | F19: =Input!E67 -> 0 | G19: =Input!E78 -> 0 | H19: =Input!E89 -> 0
B20: =Input!E24 -> Riccarton Road West | C20: =Input!E35 -> Deans Avenue North | D20: =Input!E46 -> Riccarton Avenue East | E20: =Input!E57 -> Deans Avenue South | F20: =Input!E68 -> 0 | G20: =Input!E79 -> 0 | H20: =Input!E90 -> 0
B21: =Input!E25 -> 0 | C21: =Input!E36 -> 0 | D21: =Input!E47 -> 0 | E21: =Input!E58 -> 0 | F21: =Input!E69 -> 0 | G21: =Input!E80 -> 0 | H21: =Input!E91 -> 0
B22: =Input!E26 -> 0 | C22: =Input!E37 -> 0 | D22: =Input!E48 -> 0 | E22: =Input!E59 -> 0 | F22: =Input!E70 -> 0 | G22: =Input!E81 -> 0 | H22: =Input!E92 -> 0
B23: =Input!E27 -> 0 | C23: =Input!E38 -> 0 | D23: =Input!E49 -> 0 | E23: =Input!E60 -> 0 | F23: =Input!E71 -> 0 | G23: =Input!E82 -> 0 | H23: =Input!E93 -> 0
B24: =Input!E28 -> 0 | C24: =Input!E39 -> 0 | D24: =Input!E50 -> 0 | E24: =Input!E61 -> 0 | F24: =Input!E72 -> 0 | G24: =Input!E83 -> 0 | H24: =Input!E94 -> 0

Sheet Table
A1: Deans Avenue_Riccarton Road_Riccarton Avenue_Intersection Fine 31/05/2022
C5: Deans Avenue North | R5: Riccarton Avenue East | AG5: Deans Avenue South | AV5: Riccarton Road West
C6: Left into Riccarton Avenue East | H6: Thru to Deans Avenue South | M6: Right into Riccarton Road West | R6: Left into Deans Avenue South | W6: Thru to Riccarton Road West | AB6: Right into Deans Avenue North | AG6: Left into Riccarton Road West | AL6: Thru to Deans Avenue North | AQ6: Right into Riccarton Avenue East | AV6: Left into Deans Avenue North | BA6: Thru to Riccarton Avenue East | BF6: Right into Deans Avenue South
A7: Period | B7: Time | C7: Lights | D7: Buses | E7: Single-Unit Trucks | F7: Articulated Trucks | G7: Bicycles On Road | H7: Lights | I7: Buses | J7: Single-Unit Trucks | K7: Articulated Trucks | L7: Bicycles On Road | M7: Lights | N7: Buses | O7: Single-Unit Trucks | P7: Articulated Trucks | Q7: Bicycles On Road | R7: Lights | S7: Buses | T7: Single-Unit Trucks | U7: Articulated Trucks | V7: Bicycles On Road | W7: Lights | X7: Buses | Y7: Single-Unit Trucks | Z7: Articulated Trucks | AA7: Bicycles On Road | AB7: Lights | AC7: Buses | AD7: Single-Unit Trucks | AE7: Articulated Trucks | AF7: Bicycles On Road | AG7: Lights | AH7: Buses | AI7: Single-Unit Trucks | AJ7: Articulated Trucks | AK7: Bicycles On Road | AL7: Lights | AM7: Buses | AN7: Single-Unit Trucks | AO7: Articulated Trucks | AP7: Bicycles On Road | AQ7: Lights | AR7: Buses | AS7: Single-Unit Trucks | AT7: Articulated Trucks | AU7: Bicycles On Road | AV7: Lights | AW7: Buses | AX7: Single-Unit Trucks | AY7: Articulated Trucks | AZ7: Bicycles On Road | BA7: Lights | BB7: Buses | BC7: Single-Unit Trucks | BD7: Articulated Trucks | BE7: Bicycles On Road | BF7: Lights | BG7: Buses | BH7: Single-Unit Trucks | BI7: Articulated Trucks | BJ7: Bicycles On Road
A8: AM | B8: 0.27083333 | C8: 52 | D8: 0 | E8: 0 | F8: 0 | G8: 1 | H8: 63 | I8: 0 | J8: 2 | K8: 0 | L8: 0 | M8: 28 | N8: 0 | O8: 0 | P8: 0 | Q8: 0 | R8: 8 | S8: 0 | T8: 1 | U8: 0 | V8: 0 | W8: 20 | X8: 2 | Y8: 0 | Z8: 0 | AA8: 0 | AB8: 16 | AC8: 0 | AD8: 0 | AE8: 0 | AF8: 0 | AG8: 3 | AH8: 0 | AI8: 0 | AJ8: 1 | AK8: 0 | AL8: 44 | AM8: 0 | AN8: 2 | AO8: 1 | AP8: 0 | AQ8: 4 | AR8: 0 | AS8: 0 | AT8: 0 | AU8: 0 | AV8: 19 | AW8: 0 | AX8: 0 | AY8: 0 | AZ8: 0 | BA8: 31 | BB8: 2 | BC8: 1 | BD8: 0 | BE8: 0 | BF8: 7 | BG8: 0 | BH8: 0 | BI8: 0 | BJ8: 0
A9: AM | B9: 0.28125 | C9: 61 | D9: 0 | E9: 1 | F9: 0 | G9: 0 | H9: 87 | I9: 0 | J9: 3 | K9: 0 | L9: 0 | M9: 49 | N9: 1 | O9: 1 | P9: 0 | Q9: 0 | R9: 7 | S9: 0 | T9: 0 | U9: 0 | V9: 0 | W9: 16 | X9: 3 | Y9: 0 | Z9: 0 | AA9: 0 | AB9: 18 | AC9: 0 | AD9: 1 | AE9: 0 | AF9: 0 | AG9: 3 | AH9: 0 | AI9: 0 | AJ9: 0 | AK9: 0 | AL9: 29 | AM9: 0 | AN9: 1 | AO9: 0 | AP9: 0 | AQ9: 4 | AR9: 0 | AS9: 0 | AT9: 0 | AU9: 0 | AV9: 36 | AW9: 2 | AX9: 1 | AY9: 0 | AZ9: 0 | BA9: 43 | BB9: 2 | BC9: 0 | BD9: 0 | BE9: 1 | BF9: 4 | BG9: 0 | BH9: 0 | BI9: 0 | BJ9: 0
A10: AM | B10: 0.29166667 | C10: 69 | D10: 0 | E10: 1 | F10: 0 | G10: 0 | H10: 79 | I10: 0 | J10: 4 | K10: 0 | L10: 0 | M10: 56 | N10: 0 | O10: 0 | P10: 0 | Q10: 0 | R10: 14 | S10: 0 | T10: 0 | U10: 0 | V10: 0 | W10: 19 | X10: 3 | Y10: 0 | Z10: 0 | AA10: 0 | AB10: 32 | AC10: 0 | AD10: 0 | AE10: 0 | AF10: 0 | AG10: 3 | AH10: 0 | AI10: 0 | AJ10: 0 | AK10: 1 | AL10: 46 | AM10: 0 | AN10: 0 | AO10: 0 | AP10: 0 | AQ10: 7 | AR10: 0 | AS10: 0 | AT10: 0 | AU10: 0 | AV10: 28 | AW10: 0 | AX10: 0 | AY10: 0 | AZ10: 0 | BA10: 52 | BB10: 4 | BC10: 0 | BD10: 0 | BE10: 2 | BF10: 10 | BG10: 0 | BH10: 0 | BI10: 0 | BJ10: 0
A11: AM | B11: 0.30208333 | C11: 99 | D11: 0 | E11: 0 | F11: 0 | G11: 0 | H11: 99 | I11: 0 | J11: 4 | K11: 0 | L11: 0 | M11: 72 | N11: 1 | O11: 0 | P11: 0 | Q11: 0 | R11: 10 | S11: 0 | T11: 0 | U11: 0 | V11: 0 | W11: 24 | X11: 3 | Y11: 2 | Z11: 0 | AA11: 0 | AB11: 35 | AC11: 1 | AD11: 0 | AE11: 0 | AF11: 0 | AG11: 8 | AH11: 0 | AI11: 0 | AJ11: 0 | AK11: 0 | AL11: 75 | AM11: 0 | AN11: 2 | AO11: 0 | AP11: 0 | AQ11: 10 | AR11: 0 | AS11: 0 | AT11: 0 | AU11: 0 | AV11: 43 | AW11: 0 | AX11: 4 | AY11: 0 | AZ11: 0 | BA11: 48 | BB11: 3 | BC11: 0 | BD11: 0 | BE11: 7 | BF11: 12 | BG11: 0 | BH11: 0 | BI11: 0 | BJ11: 0
A12: AM | B12: 0.3125 | C12: 127 | D12: 0 | E12: 0 | F12: 0 | G12: 6 | H12: 174 | I12: 0 | J12: 1 | K12: 0 | L12: 0 | M12: 74 | N12: 0 | O12: 3 | P12: 0 | Q12: 0 | R12: 10 | S12: 0 | T12: 0 | U12: 0 | V12: 0 | W12: 28 | X12: 4 | Y12: 0 | Z12: 0 | AA12: 1 | AB12: 43 | AC12: 0 | AD12: 0 | AE12: 0 | AF12: 0 | AG12: 15 | AH12: 0 | AI12: 0 | AJ12: 0 | AK12: 0 | AL12: 94 | AM12: 0 | AN12: 2 | AO12: 0 | AP12: 0 | AQ12: 4 | AR12: 0 | AS12: 0 | AT12: 0 | AU12: 0 | AV12: 46 | AW12: 0 | AX12: 0 | AY12: 0 | AZ12: 0 | BA12: 64 | BB12: 3 | BC12: 5 | BD12: 0 | BE12: 9 | BF12: 10 | BG12: 0 | BH12: 0 | BI12: 0 | BJ12: 0
A13: AM | B13: 0.32291667 | C13: 125 | D13: 0 | E13: 0 | F13: 0 | G13: 4 | H13: 169 | I13: 0 | J13: 3 | K13: 0 | L13: 1 | M13: 88 | N13: 1 | O13: 0 | P13: 0 | Q13: 1 | R13: 11 | S13: 0 | T13: 0 | U13: 0 | V13: 0 | W13: 45 | X13: 4 | Y13: 1 | Z13: 0 | AA13: 2 | AB13: 57 | AC13: 1 | AD13: 0 | AE13: 0 | AF13: 0 | AG13: 11 | AH13: 0 | AI13: 2 | AJ13: 0 | AK13: 0 | AL13: 86 | AM13: 0 | AN13: 5 | AO13: 1 | AP13: 0 | AQ13: 13 | AR13: 0 | AS13: 0 | AT13: 0 | AU13: 0 | AV13: 49 | AW13: 0 | AX13: 2 | AY13: 0 | AZ13: 0 | BA13: 98 | BB13: 5 | BC13: 1 | BD13: 0 | BE13: 11 | BF13: 7 | BG13: 0 | BH13: 0 | BI13: 0 | BJ13: 0
A14: AM | B14: 0.33333333 | C14: 129 | D14: 1 | E14: 0 | F14: 0 | G14: 1 | H14: 149 | I14: 0 | J14: 2 | K14: 0 | L14: 0 | M14: 86 | N14: 0 | O14: 0 | P14: 0 | Q14: 0 | R14: 10 | S14: 0 | T14: 0 | U14: 0 | V14: 0 | W14: 28 | X14: 3 | Y14: 3 | Z14: 0 | AA14: 4 | AB14: 41 | AC14: 0 | AD14: 0 | AE14: 0 | AF14: 0 | AG14: 8 | AH14: 0 | AI14: 1 | AJ14: 0 | AK14: 0 | AL14: 99 | AM14: 0 | AN14: 1 | AO14: 0 | AP14: 0 | AQ14: 16 | AR14: 0 | AS14: 0 | AT14: 0 | AU14: 0 | AV14: 67 | AW14: 1 | AX14: 1 | AY14: 0 | AZ14: 0 | BA14: 101 | BB14: 5 | BC14: 0 | BD14: 0 | BE14: 8 | BF14: 18 | BG14: 0 | BH14: 0 | BI14: 0 | BJ14: 0
A15: AM | B15: 0.34375 | C15: 130 | D15: 0 | E15: 1 | F15: 0 | G15: 2 | H15: 166 | I15: 0 | J15: 4 | K15: 1 | L15: 0 | M15: 94 | N15: 1 | O15: 0 | P15: 0 | Q15: 0 | R15: 6 | S15: 0 | T15: 0 | U15: 0 | V15: 0 | W15: 44 | X15: 5 | Y15: 1 | Z15: 0 | AA15: 1 | AB15: 57 | AC15: 1 | AD15: 1 | AE15: 0 | AF15: 0 | AG15: 16 | AH15: 0 | AI15: 0 | AJ15: 0 | AK15: 0 | AL15: 122 | AM15: 1 | AN15: 0 | AO15: 0 | AP15: 0 | AQ15: 17 | AR15: 0 | AS15: 1 | AT15: 0 | AU15: 0 | AV15: 53 | AW15: 1 | AX15: 6 | AY15: 0 | AZ15: 0 | BA15: 79 | BB15: 5 | BC15: 0 | BD15: 1 | BE15: 2 | BF15: 16 | BG15: 0 | BH15: 0 | BI15: 0 | BJ15: 0
A16: AM | B16: 0.35416667 | C16: 139 | D16: 1 | E16: 1 | F16: 0 | G16: 0 | H16: 173 | I16: 1 | J16: 2 | K16: 0 | L16: 1 | M16: 107 | N16: 0 | O16: 3 | P16: 0 | Q16: 1 | R16: 11 | S16: 0 | T16: 1 | U16: 0 | V16: 0 | W16: 39 | X16: 4 | Y16: 2 | Z16: 0 | AA16: 4 | AB16: 43 | AC16: 0 | AD16: 1 | AE16: 0 | AF16: 0 | AG16: 13 | AH16: 0 | AI16: 0 | AJ16: 0 | AK16: 0 | AL16: 90 | AM16: 0 | AN16: 1 | AO16: 0 | AP16: 0 | AQ16: 8 | AR16: 0 | AS16: 0 | AT16: 0 | AU16: 0 | AV16: 59 | AW16: 1 | AX16: 1 | AY16: 0 | AZ16: 0 | BA16: 77 | BB16: 2 | BC16: 1 | BD16: 0 | BE16: 2 | BF16: 6 | BG16: 1 | BH16: 0 | BI16: 0 | BJ16: 0
A17: AM | B17: 0.36458333 | C17: 127 | D17: 0 | E17: 2 | F17: 0 | G17: 0 | H17: 153 | I17: 1 | J17: 3 | K17: 0 | L17: 7 | M17: 86 | N17: 1 | O17: 0 | P17: 0 | Q17: 0 | R17: 10 | S17: 0 | T17: 0 | U17: 0 | V17: 0 | W17: 38 | X17: 2 | Y17: 2 | Z17: 0 | AA17: 3 | AB17: 41 | AC17: 0 | AD17: 0 | AE17: 0 | AF17: 0 | AG17: 20 | AH17: 0 | AI17: 0 | AJ17: 0 | AK17: 0 | AL17: 99 | AM17: 1 | AN17: 0 | AO17: 0 | AP17: 0 | AQ17: 7 | AR17: 0 | AS17: 0 | AT17: 0 | AU17: 0 | AV17: 51 | AW17: 1 | AX17: 1 | AY17: 0 | AZ17: 0 | BA17: 81 | BB17: 6 | BC17: 1 | BD17: 0 | BE17: 6 | BF17: 5 | BG17: 0 | BH17: 0 | BI17: 0 | BJ17: 0
A18: AM | B18: 0.375 | C18: 84 | D18: 0 | E18: 2 | F18: 0 | G18: 1 | H18: 108 | I18: 1 | J18: 3 | K18: 1 | L18: 0 | M18: 90 | N18: 0 | O18: 1 | P18: 0 | Q18: 0 | R18: 6 | S18: 0 | T18: 0 | U18: 0 | V18: 0 | W18: 32 | X18: 5 | Y18: 1 | Z18: 0 | AA18: 0 | AB18: 47 | AC18: 0 | AD18: 0 | AE18: 0 | AF18: 0 | AG18: 13 | AH18: 0 | AI18: 0 | AJ18: 0 | AK18: 0 | AL18: 54 | AM18: 0 | AN18: 5 | AO18: 0 | AP18: 0 | AQ18: 6 | AR18: 0 | AS18: 0 | AT18: 0 | AU18: 0 | AV18: 56 | AW18: 0 | AX18: 3 | AY18: 0 | AZ18: 0 | BA18: 63 | BB18: 5 | BC18: 1 | BD18: 0 | BE18: 0 | BF18: 11 | BG18: 0 | BH18: 0 | BI18: 0 | BJ18: 0
A19: AM | B19: 0.38541667 | C19: 77 | D19: 0 | E19: 1 | F19: 0 | G19: 1 | H19: 89 | I19: 0 | J19: 2 | K19: 0 | L19: 0 | M19: 58 | N19: 1 | O19: 1 | P19: 0 | Q19: 0 | R19: 10 | S19: 0 | T19: 0 | U19: 0 | V19: 0 | W19: 29 | X19: 1 | Y19: 2 | Z19: 0 | AA19: 0 | AB19: 23 | AC19: 0 | AD19: 1 | AE19: 0 | AF19: 0 | AG19: 19 | AH19: 0 | AI19: 0 | AJ19: 0 | AK19: 0 | AL19: 87 | AM19: 0 | AN19: 3 | AO19: 0 | AP19: 0 | AQ19: 16 | AR19: 0 | AS19: 1 | AT19: 0 | AU19: 0 | AV19: 58 | AW19: 1 | AX19: 2 | AY19: 0 | AZ19: 1 | BA19: 68 | BB19: 3 | BC19: 1 | BD19: 0 | BE19: 0 | BF19: 6 | BG19: 0 | BH19: 2 | BI19: 0 | BJ19: 0
... A47: PM | B47: 0.76041667 | C47: 55 | D47: 0 | E47: 0 | F47: 0 | G47: 0 | H47: 67 | I47: 0 | J47: 1 | K47: 0 | L47: 0 | M47: 53 | N47: 0 | O47: 0 | P47: 0 | Q47: 0 | R47: 7 | S47: 0 | T47: 0 | U47: 0 | V47: 0 | W47: 41 | X47: 5 | Y47: 0 | Z47: 0 | AA47: 0 | AB47: 43 | AC47: 0 | AD47: 0 | AE47: 0 | AF47: 0 | AG47: 25 | AH47: 0 | AI47: 0 | AJ47: 0 | AK47: 0 | AL47: 85 | AM47: 0 | AN47: 0 | AO47: 0 | AP47: 0 | AQ47: 7 | AR47: 0 | AS47: 0 | AT47: 0 | AU47: 0 | AV47: 75 | AW47: 0 | AX47: 0 | AY47: 0 | AZ47: 2 | BA47: 52 | BB47: 2 | BC47: 2 | BD47: 0 | BE47: 1 | BF47: 17 | BG47: 0 | BH47: 0 | BI47: 0 | BJ47: 0

Sheet PivotData
A1: Approach | B1: Movement | C1: Exit | D1: Vehicle | E1: Survey Period | F1: Time | G1: Count | H1: Time Grouped | I1: Peak Marker
A2: Deans Avenue North | B2: Left into Riccarton Avenue East | C2: Riccarton Avenue East | D2: Lights | E2: AM | F2: 0.27083333 | G2: 52 | H2: =FLOOR(tblPivotData[[#This Row],[Time]],Summary!$B$6/1440) -> 0.27083333 | I2: =INDEX(PeakCalc!$L$10:$L$303,MATCH(tblPivotData[[#This Row],[Time]],PeakCalc!$G$10:$G$303,0)) -> 0
A3: Deans Avenue North | B3: Left into Riccarton Avenue East | C3: Riccarton Avenue East | D3: Lights | E3: AM | F3: 0.28125 | G3: 61 | H3: =FLOOR(tblPivotData[[#This Row],[Time]],Summary!$B$6/1440) -> 0.28125 | I3: =INDEX(PeakCalc!$L$10:$L$303,MATCH(tblPivotData[[#This Row],[Time]],PeakCalc!$G$10:$G$303,0)) -> 0
A4: Deans Avenue North | B4: Left into Riccarton Avenue East | C4: Riccarton Avenue East | D4: Lights | E4: AM | F4: 0.29166667 | G4: 69 | H4: =FLOOR(tblPivotData[[#This Row],[Time]],Summary!$B$6/1440) -> 0.29166667 | I4: =INDEX(PeakCalc!$L$10:$L$303,MATCH(tblPivotData[[#This Row],[Time]],PeakCalc!$G$10:$G$303,0)) -> 0
A5: Deans Avenue North | B5: Left into Riccarton Avenue East | C5: Riccarton Avenue East | D5: Lights | E5: AM | F5: 0.30208333 | G5: 99 | H5: =FLOOR(tblPivotData[[#This Row],[Time]],Summary!$B$6/1440) -> 0.30208333 | I5: =INDEX(PeakCalc!$L$10:$L$303,MATCH(tblPivotData[[#This Row],[Time]],PeakCalc!$G$10:$G$303,0)) -> 0
A6: Deans Avenue North | B6: Left into Riccarton Avenue East | C6: Riccarton Avenue East | D6: Lights | E6: AM | F6: 0.3125 | G6: 127 | H6: =FLOOR(tblPivotData[[#This Row],[Time]],Summary!$B$6/1440) -> 0.3125 | I6: =INDEX(PeakCalc!$L$10:$L$303,MATCH(tblPivotData[[#This Row],[Time]],PeakCalc!$G$10:$G$303,0)) -> 0
A7: Deans Avenue North | B7: Left into Riccarton Avenue East | C7: Riccarton Avenue East | D7: Lights | E7: AM | F7: 0.32291667 | G7: 125 | H7: =FLOOR(tblPivotData[[#This Row],[Time]],Summary!$B$6/1440) -> 0.32291667 | I7: =INDEX(PeakCalc!$L$10:$L$303,MATCH(tblPivotData[[#This Row],[Time]],PeakCalc!$G$10:$G$303,0)) -> 1
A8: Deans Avenue North | B8: Left into Riccarton Avenue East | C8: Riccarton Avenue East | D8: Lights | E8: AM | F8: 0.33333333 | G8: 129 | H8: =FLOOR(tblPivotData[[#This Row],[Time]],Summary!$B$6/1440) -> 0.33333333 | I8: =INDEX(PeakCalc!$L$10:$L$303,MATCH(tblPivotData[[#This Row],[Time]],PeakCalc!$G$10:$G$303,0)) -> 1
A9: Deans Avenue North | B9: Left into Riccarton Avenue East | C9: Riccarton Avenue East | D9: Lights | E9: AM | F9: 0.34375 | G9: 130 | H9: =FLOOR(tblPivotData[[#This Row],[Time]],Summary!$B$6/1440) -> 0.34375 | I9: =INDEX(PeakCalc!$L$10:$L$303,MATCH(tblPivotData[[#This Row],[Time]],PeakCalc!$G$10:$G$303,0)) -> 1
A10: Deans Avenue North | B10: Left into Riccarton Avenue East | C10: Riccarton Avenue East | D10: Lights | E10: AM | F10: 0.35416667 | G10: 139 | H10: =FLOOR(tblPivotData[[#This Row],[Time]],Summary!$B$6/1440) -> 0.35416667 | I10: =INDEX(PeakCalc!$L$10:$L$303,MATCH(tblPivotData[[#This Row],[Time]],PeakCalc!$G$10:$G$303,0)) -> 1
A11: Deans Avenue North | B11: Left into Riccarton Avenue East | C11: Riccarton Avenue East | D11: Lights | E11: AM | F11: 0.36458333 | G11: 127 | H11: =FLOOR(tblPivotData[[#This Row],[Time]],Summary!$B$6/1440) -> 0.36458333 | I11: =INDEX(PeakCalc!$L$10:$L$303,MATCH(tblPivotData[[#This Row],[Time]],PeakCalc!$G$10:$G$303,0)) -> 0
A12: Deans Avenue North | B12: Left into Riccarton Avenue East | C12: Riccarton Avenue East | D12: Lights | E12: AM | F12: 0.375 | G12: 84 | H12: =FLOOR(tblPivotData[[#This Row],[Time]],Summary!$B$6/1440) -> 0.375 | I12: =INDEX(PeakCalc!$L$10:$L$303,MATCH(tblPivotData[[#This Row],[Time]],PeakCalc!$G$10:$G$303,0)) -> 0
A13: Deans Avenue North | B13: Left into Riccarton Avenue East | C13: Riccarton Avenue East | D13: Lights | E13: AM | F13: 0.38541667 | G13: 77 | H13: =FLOOR(tblPivotData[[#This Row],[Time]],Summary!$B$6/1440) -> 0.38541667 | I13: =INDEX(PeakCalc!$L$10:$L$303,MATCH(tblPivotData[[#This Row],[Time]],PeakCalc!$G$10:$G$303,0)) -> 0
... A2281: Riccarton Road West | B2281: Right into Deans Avenue South | C2281: Deans Avenue South | D2281: Bicycles On Road | E2281: PM | F2281: 0.76041667 | G2281: 0 | H2281: =FLOOR(tblPivotData[[#This Row],[Time]],Summary!$B$6/1440) -> 0.76041667 | I2281: =INDEX(PeakCalc!$L$10:$L$303,MATCH(tblPivotData[[#This Row],[Time]],PeakCalc!$G$10:$G$303,0)) -> 0

Sheet SummaryCalc
B2: Interval | C2: =rngCountInterval -> 15
B5: Options to group time by
B7: Existing intervals | E7: Selection
B8: 5 | C8: 15 | E8: =C2 -> 15
B10: 5 | C10: 15 | E10: =INDEX($B10:$C10,1,MATCH(E$8,$B$8:$C$8,0)) -> 15
B11: 10 | C11: 30 | E11: =INDEX($B11:$C11,1,MATCH(E$8,$B$8:$C$8,0)) -> 30
B12: 15 | C12: 60 | E12: =INDEX($B12:$C12,1,MATCH(E$8,$B$8:$C$8,0)) -> 60
B13: 20 | C13: - | E13: =INDEX($B13:$C13,1,MATCH(E$8,$B$8:$C$8,0)) -> -
B14: 30 | C14: - | E14: =INDEX($B14:$C14,1,MATCH(E$8,$B$8:$C$8,0)) -> -
B15: 60 | C15: - | E15: =INDEX($B15:$C15,1,MATCH(E$8,$B$8:$C$8,0)) -> -

Sheet Summary
B2: Summary Table
B4: Select time interval to group by
B6: 15 | C6: minutes
B8: Then right click on any cell in the table, and click Refresh
C11: Deans Avenue North | U11: Deans Avenue North Total | V11: Riccarton Avenue East | AN11: Riccarton Avenue East Total | AO11: Deans Avenue South | BG11: Deans Avenue South Total | BH11: Riccarton Road West | BZ11: Riccarton Road West Total | CA11: Grand Total
C12: Left into Riccarton Avenue East | H12: Left into Riccarton Avenue East Total | I12: Thru to Deans Avenue South | N12: Thru to Deans Avenue South Total | O12: Right into Riccarton Road West | T12: Right into Riccarton Road West Total | V12: Left into Deans Avenue South | AA12: Left into Deans Avenue South Total | AB12: Thru to Riccarton Road West | AG12: Thru to Riccarton Road West Total | AH12: Right into Deans Avenue North | AM12: Right into Deans Avenue North Total | AO12: Left into Riccarton Road West | AT12: Left into Riccarton Road West Total | AU12: Thru to Deans Avenue North | AZ12: Thru to Deans Avenue North Total | BA12: Right into Riccarton Avenue East | BF12: Right into Riccarton Avenue East Total | BH12: Left into Deans Avenue North | BM12: Left into Deans Avenue North Total | BN12: Thru to Riccarton Avenue East | BS12: Thru to Riccarton Avenue East Total | BT12: Right into Deans Avenue South | BY12: Right into Deans Avenue South Total
C13: Lights | D13: Buses | E13: Single-Unit Trucks | F13: Articulated Trucks | G13: Bicycles On Road | I13: Lights | J13: Buses | K13: Single-Unit Trucks | L13: Articulated Trucks | M13: Bicycles On Road | O13: Lights | P13: Buses | Q13: Single-Unit Trucks | R13: Articulated Trucks | S13: Bicycles On Road | V13: Lights | W13: Buses | X13: Single-Unit Trucks | Y13: Articulated Trucks | Z13: Bicycles On Road | AB13: Lights | AC13: Buses | AD13: Single-Unit Trucks | AE13: Articulated Trucks | AF13: Bicycles On Road | AH13: Lights | AI13: Buses | AJ13: Single-Unit Trucks | AK13: Articulated Trucks | AL13: Bicycles On Road | AO13: Lights | AP13: Buses | AQ13: Single-Unit Trucks | AR13: Articulated Trucks | AS13: Bicycles On Road | AU13: Lights | AV13: Buses | AW13: Single-Unit Trucks | AX13: Articulated Trucks | AY13: Bicycles On Road | BA13: Lights | BB13: Buses | BC13: Single-Unit Trucks | BD13: Articulated Trucks | BE13: Bicycles On Road | BH13: Lights | BI13: Buses | BJ13: Single-Unit Trucks | BK13: Articulated Trucks | BL13: Bicycles On Road | BN13: Lights | BO13: Buses | BP13: Single-Unit Trucks | BQ13: Articulated Trucks | BR13: Bicycles On Road | BT13: Lights | BU13: Buses | BV13: Single-Unit Trucks | BW13: Articulated Trucks | BX13: Bicycles On Road
B14: AM | C14: 1219 | D14: 2 | E14: 9 | F14: 0 | G14: 16 | H14: 1246 | I14: 1509 | J14: 3 | K14: 33 | L14: 2 | M14: 9 | N14: 1556 | O14: 888 | P14: 6 | Q14: 9 | R14: 0 | S14: 2 | T14: 905 | U14: 3707 | V14: 113 | W14: 0 | X14: 2 | Y14: 0 | Z14: 0 | AA14: 115 | AB14: 362 | AC14: 39 | AD14: 14 | AE14: 0 | AF14: 15 | AG14: 430 | AH14: 453 | AI14: 3 | AJ14: 4 | AK14: 0 | AL14: 0 | AM14: 460 | AN14: 1005 | AO14: 132 | AP14: 0 | AQ14: 3 | AR14: 1 | AS14: 1 | AT14: 137 | AU14: 925 | AV14: 2 | AW14: 22 | AX14: 2 | AY14: 0 | AZ14: 951 | BA14: 112 | BB14: 0 | BC14: 2 | BD14: 0 | BE14: 0 | BF14: 114 | BG14: 1202 | BH14: 565 | BI14: 7 | BJ14: 21 | BK14: 0 | BL14: 1 | BM14: 594 | BN14: 805 | BO14: 45 | BP14: 11 | BQ14: 1 | BR14: 48 | BS14: 910 | BT14: 112 | BU14: 1 | BV14: 2 | BW14: 0 | BX14: 0 | BY14: 115 | BZ14: 1619 | CA14: 7533
B15: 0.27083333 | C15: 52 | D15: 0 | E15: 0 | F15: 0 | G15: 1 | H15: 53 | I15: 63 | J15: 0 | K15: 2 | L15: 0 | M15: 0 | N15: 65 | O15: 28 | P15: 0 | Q15: 0 | R15: 0 | S15: 0 | T15: 28 | U15: 146 | V15: 8 | W15: 0 | X15: 1 | Y15: 0 | Z15: 0 | AA15: 9 | AB15: 20 | AC15: 2 | AD15: 0 | AE15: 0 | AF15: 0 | AG15: 22 | AH15: 16 | AI15: 0 | AJ15: 0 | AK15: 0 | AL15: 0 | AM15: 16 | AN15: 47 | AO15: 3 | AP15: 0 | AQ15: 0 | AR15: 1 | AS15: 0 | AT15: 4 | AU15: 44 | AV15: 0 | AW15: 2 | AX15: 1 | AY15: 0 | AZ15: 47 | BA15: 4 | BB15: 0 | BC15: 0 | BD15: 0 | BE15: 0 | BF15: 4 | BG15: 55 | BH15: 19 | BI15: 0 | BJ15: 0 | BK15: 0 | BL15: 0 | BM15: 19 | BN15: 31 | BO15: 2 | BP15: 1 | BQ15: 0 | BR15: 0 | BS15: 34 | BT15: 7 | BU15: 0 | BV15: 0 | BW15: 0 | BX15: 0 | BY15: 7 | BZ15: 60 | CA15: 308
B16: 0.28125 | C16: 61 | D16: 0 | E16: 1 | F16: 0 | G16: 0 | H16: 62 | I16: 87 | J16: 0 | K16: 3 | L16: 0 | M16: 0 | N16: 90 | O16: 49 | P16: 1 | Q16: 1 | R16: 0 | S16: 0 | T16: 51 | U16: 203 | V16: 7 | W16: 0 | X16: 0 | Y16: 0 | Z16: 0 | AA16: 7 | AB16: 16 | AC16: 3 | AD16: 0 | AE16: 0 | AF16: 0 | AG16: 19 | AH16: 18 | AI16: 0 | AJ16: 1 | AK16: 0 | AL16: 0 | AM16: 19 | AN16: 45 | AO16: 3 | AP16: 0 | AQ16: 0 | AR16: 0 | AS16: 0 | AT16: 3 | AU16: 29 | AV16: 0 | AW16: 1 | AX16: 0 | AY16: 0 | AZ16: 30 | BA16: 4 | BB16: 0 | BC16: 0 | BD16: 0 | BE16: 0 | BF16: 4 | BG16: 37 | BH16: 36 | BI16: 2 | BJ16: 1 | BK16: 0 | BL16: 0 | BM16: 39 | BN16: 43 | BO16: 2 | BP16: 0 | BQ16: 0 | BR16: 1 | BS16: 46 | BT16: 4 | BU16: 0 | BV16: 0 | BW16: 0 | BX16: 0 | BY16: 4 | BZ16: 89 | CA16: 374
B17: 0.29166667 | C17: 69 | D17: 0 | E17: 1 | F17: 0 | G17: 0 | H17: 70 | I17: 79 | J17: 0 | K17: 4 | L17: 0 | M17: 0 | N17: 83 | O17: 56 | P17: 0 | Q17: 0 | R17: 0 | S17: 0 | T17: 56 | U17: 209 | V17: 14 | W17: 0 | X17: 0 | Y17: 0 | Z17: 0 | AA17: 14 | AB17: 19 | AC17: 3 | AD17: 0 | AE17: 0 | AF17: 0 | AG17: 22 | AH17: 32 | AI17: 0 | AJ17: 0 | AK17: 0 | AL17: 0 | AM17: 32 | AN17: 68 | AO17: 3 | AP17: 0 | AQ17: 0 | AR17: 0 | AS17: 1 | AT17: 4 | AU17: 46 | AV17: 0 | AW17: 0 | AX17: 0 | AY17: 0 | AZ17: 46 | BA17: 7 | BB17: 0 | BC17: 0 | BD17: 0 | BE17: 0 | BF17: 7 | BG17: 57 | BH17: 28 | BI17: 0 | BJ17: 0 | BK17: 0 | BL17: 0 | BM17: 28 | BN17: 52 | BO17: 4 | BP17: 0 | BQ17: 0 | BR17: 2 | BS17: 58 | BT17: 10 | BU17: 0 | BV17: 0 | BW17: 0 | BX17: 0 | BY17: 10 | BZ17: 96 | CA17: 430
B18: 0.30208333 | C18: 99 | D18: 0 | E18: 0 | F18: 0 | G18: 0 | H18: 99 | I18: 99 | J18: 0 | K18: 4 | L18: 0 | M18: 0 | N18: 103 | O18: 72 | P18: 1 | Q18: 0 | R18: 0 | S18: 0 | T18: 73 | U18: 275 | V18: 10 | W18: 0 | X18: 0 | Y18: 0 | Z18: 0 | AA18: 10 | AB18: 24 | AC18: 3 | AD18: 2 | AE18: 0 | AF18: 0 | AG18: 29 | AH18: 35 | AI18: 1 | AJ18: 0 | AK18: 0 | AL18: 0 | AM18: 36 | AN18: 75 | AO18: 8 | AP18: 0 | AQ18: 0 | AR18: 0 | AS18: 0 | AT18: 8 | AU18: 75 | AV18: 0 | AW18: 2 | AX18: 0 | AY18: 0 | AZ18: 77 | BA18: 10 | BB18: 0 | BC18: 0 | BD18: 0 | BE18: 0 | BF18: 10 | BG18: 95 | BH18: 43 | BI18: 0 | BJ18: 4 | BK18: 0 | BL18: 0 | BM18: 47 | BN18: 48 | BO18: 3 | BP18: 0 | BQ18: 0 | BR18: 7 | BS18: 58 | BT18: 12 | BU18: 0 | BV18: 0 | BW18: 0 | BX18: 0 | BY18: 12 | BZ18: 117 | CA18: 562
B19: 0.3125 | C19: 127 | D19: 0 | E19: 0 | F19: 0 | G19: 6 | H19: 133 | I19: 174 | J19: 0 | K19: 1 | L19: 0 | M19: 0 | N19: 175 | O19: 74 | P19: 0 | Q19: 3 | R19: 0 | S19: 0 | T19: 77 | U19: 385 | V19: 10 | W19: 0 | X19: 0 | Y19: 0 | Z19: 0 | AA19: 10 | AB19: 28 | AC19: 4 | AD19: 0 | AE19: 0 | AF19: 1 | AG19: 33 | AH19: 43 | AI19: 0 | AJ19: 0 | AK19: 0 | AL19: 0 | AM19: 43 | AN19: 86 | AO19: 15 | AP19: 0 | AQ19: 0 | AR19: 0 | AS19: 0 | AT19: 15 | AU19: 94 | AV19: 0 | AW19: 2 | AX19: 0 | AY19: 0 | AZ19: 96 | BA19: 4 | BB19: 0 | BC19: 0 | BD19: 0 | BE19: 0 | BF19: 4 | BG19: 115 | BH19: 46 | BI19: 0 | BJ19: 0 | BK19: 0 | BL19: 0 | BM19: 46 | BN19: 64 | BO19: 3 | BP19: 5 | BQ19: 0 | BR19: 9 | BS19: 81 | BT19: 10 | BU19: 0 | BV19: 0 | BW19: 0 | BX19: 0 | BY19: 10 | BZ19: 137 | CA19: 723
B20: 0.32291667 | C20: 125 | D20: 0 | E20: 0 | F20: 0 | G20: 4 | H20: 129 | I20: 169 | J20: 0 | K20: 3 | L20: 0 | M20: 1 | N20: 173 | O20: 88 | P20: 1 | Q20: 0 | R20: 0 | S20: 1 | T20: 90 | U20: 392 | V20: 11 | W20: 0 | X20: 0 | Y20: 0 | Z20: 0 | AA20: 11 | AB20: 45 | AC20: 4 | AD20: 1 | AE20: 0 | AF20: 2 | AG20: 52 | AH20: 57 | AI20: 1 | AJ20: 0 | AK20: 0 | AL20: 0 | AM20: 58 | AN20: 121 | AO20: 11 | AP20: 0 | AQ20: 2 | AR20: 0 | AS20: 0 | AT20: 13 | AU20: 86 | AV20: 0 | AW20: 5 | AX20: 1 | AY20: 0 | AZ20: 92 | BA20: 13 | BB20: 0 | BC20: 0 | BD20: 0 | BE20: 0 | BF20: 13 | BG20: 118 | BH20: 49 | BI20: 0 | BJ20: 2 | BK20: 0 | BL20: 0 | BM20: 51 | BN20: 98 | BO20: 5 | BP20: 1 | BQ20: 0 | BR20: 11 | BS20: 115 | BT20: 7 | BU20: 0 | BV20: 0 | BW20: 0 | BX20: 0 | BY20: 7 | BZ20: 173 | CA20: 804
B21: 0.33333333 | C21: 129 | D21: 1 | E21: 0 | F21: 0 | G21: 1 | H21: 131 | I21: 149 | J21: 0 | K21: 2 | L21: 0 | M21: 0 | N21: 151 | O21: 86 | P21: 0 | Q21: 0 | R21: 0 | S21: 0 | T21: 86 | U21: 368 | V21: 10 | W21: 0 | X21: 0 | Y21: 0 | Z21: 0 | AA21: 10 | AB21: 28 | AC21: 3 | AD21: 3 | AE21: 0 | AF21: 4 | AG21: 38 | AH21: 41 | AI21: 0 | AJ21: 0 | AK21: 0 | AL21: 0 | AM21: 41 | AN21: 89 | AO21: 8 | AP21: 0 | AQ21: 1 | AR21: 0 | AS21: 0 | AT21: 9 | AU21: 99 | AV21: 0 | AW21: 1 | AX21: 0 | AY21: 0 | AZ21: 100 | BA21: 16 | BB21: 0 | BC21: 0 | BD21: 0 | BE21: 0 | BF21: 16 | BG21: 125 | BH21: 67 | BI21: 1 | BJ21: 1 | BK21: 0 | BL21: 0 | BM21: 69 | BN21: 101 | BO21: 5 | BP21: 0 | BQ21: 0 | BR21: 8 | BS21: 114 | BT21: 18 | BU21: 0 | BV21: 0 | BW21: 0 | BX21: 0 | BY21: 18 | BZ21: 201 | CA21: 783
B22: 0.34375 | C22: 130 | D22: 0 | E22: 1 | F22: 0 | G22: 2 | H22: 133 | I22: 166 | J22: 0 | K22: 4 | L22: 1 | M22: 0 | N22: 171 | O22: 94 | P22: 1 | Q22: 0 | R22: 0 | S22: 0 | T22: 95 | U22: 399 | V22: 6 | W22: 0 | X22: 0 | Y22: 0 | Z22: 0 | AA22: 6 | AB22: 44 | AC22: 5 | AD22: 1 | AE22: 0 | AF22: 1 | AG22: 51 | AH22: 57 | AI22: 1 | AJ22: 1 | AK22: 0 | AL22: 0 | AM22: 59 | AN22: 116 | AO22: 16 | AP22: 0 | AQ22: 0 | AR22: 0 | AS22: 0 | AT22: 16 | AU22: 122 | AV22: 1 | AW22: 0 | AX22: 0 | AY22: 0 | AZ22: 123 | BA22: 17 | BB22: 0 | BC22: 1 | BD22: 0 | BE22: 0 | BF22: 18 | BG22: 157 | BH22: 53 | BI22: 1 | BJ22: 6 | BK22: 0 | BL22: 0 | BM22: 60 | BN22: 79 | BO22: 5 | BP22: 0 | BQ22: 1 | BR22: 2 | BS22: 87 | BT22: 16 | BU22: 0 | BV22: 0 | BW22: 0 | BX22: 0 | BY22: 16 | BZ22: 163 | CA22: 835
B23: 0.35416667 | C23: 139 | D23: 1 | E23: 1 | F23: 0 | G23: 0 | H23: 141 | I23: 173 | J23: 1 | K23: 2 | L23: 0 | M23: 1 | N23: 177 | O23: 107 | P23: 0 | Q23: 3 | R23: 0 | S23: 1 | T23: 111 | U23: 429 | V23: 11 | W23: 0 | X23: 1 | Y23: 0 | Z23: 0 | AA23: 12 | AB23: 39 | AC23: 4 | AD23: 2 | AE23: 0 | AF23: 4 | AG23: 49 | AH23: 43 | AI23: 0 | AJ23: 1 | AK23: 0 | AL23: 0 | AM23: 44 | AN23: 105 | AO23: 13 | AP23: 0 | AQ23: 0 | AR23: 0 | AS23: 0 | AT23: 13 | AU23: 90 | AV23: 0 | AW23: 1 | AX23: 0 | AY23: 0 | AZ23: 91 | BA23: 8 | BB23: 0 | BC23: 0 | BD23: 0 | BE23: 0 | BF23: 8 | BG23: 112 | BH23: 59 | BI23: 1 | BJ23: 1 | BK23: 0 | BL23: 0 | BM23: 61 | BN23: 77 | BO23: 2 | BP23: 1 | BQ23: 0 | BR23: 2 | BS23: 82 | BT23: 6 | BU23: 1 | BV23: 0 | BW23: 0 | BX23: 0 | BY23: 7 | BZ23: 150 | CA23: 796
B24: 0.36458333 | C24: 127 | D24: 0 | E24: 2 | F24: 0 | G24: 0 | H24: 129 | I24: 153 | J24: 1 | K24: 3 | L24: 0 | M24: 7 | N24: 164 | O24: 86 | P24: 1 | Q24: 0 | R24: 0 | S24: 0 | T24: 87 | U24: 380 | V24: 10 | W24: 0 | X24: 0 | Y24: 0 | Z24: 0 | AA24: 10 | AB24: 38 | AC24: 2 | AD24: 2 | AE24: 0 | AF24: 3 | AG24: 45 | AH24: 41 | AI24: 0 | AJ24: 0 | AK24: 0 | AL24: 0 | AM24: 41 | AN24: 96 | AO24: 20 | AP24: 0 | AQ24: 0 | AR24: 0 | AS24: 0 | AT24: 20 | AU24: 99 | AV24: 1 | AW24: 0 | AX24: 0 | AY24: 0 | AZ24: 100 | BA24: 7 | BB24: 0 | BC24: 0 | BD24: 0 | BE24: 0 | BF24: 7 | BG24: 127 | BH24: 51 | BI24: 1 | BJ24: 1 | BK24: 0 | BL24: 0 | BM24: 53 | BN24: 81 | BO24: 6 | BP24: 1 | BQ24: 0 | BR24: 6 | BS24: 94 | BT24: 5 | BU24: 0 | BV24: 0 | BW24: 0 | BX24: 0 | BY24: 5 | BZ24: 152 | CA24: 755
B25: 0.375 | C25: 84 | D25: 0 | E25: 2 | F25: 0 | G25: 1 | H25: 87 | I25: 108 | J25: 1 | K25: 3 | L25: 1 | M25: 0 | N25: 113 | O25: 90 | P25: 0 | Q25: 1 | R25: 0 | S25: 0 | T25: 91 | U25: 291 | V25: 6 | W25: 0 | X25: 0 | Y25: 0 | Z25: 0 | AA25: 6 | AB25: 32 | AC25: 5 | AD25: 1 | AE25: 0 | AF25: 0 | AG25: 38 | AH25: 47 | AI25: 0 | AJ25: 0 | AK25: 0 | AL25: 0 | AM25: 47 | AN25: 91 | AO25: 13 | AP25: 0 | AQ25: 0 | AR25: 0 | AS25: 0 | AT25: 13 | AU25: 54 | AV25: 0 | AW25: 5 | AX25: 0 | AY25: 0 | AZ25: 59 | BA25: 6 | BB25: 0 | BC25: 0 | BD25: 0 | BE25: 0 | BF25: 6 | BG25: 78 | BH25: 56 | BI25: 0 | BJ25: 3 | BK25: 0 | BL25: 0 | BM25: 59 | BN25: 63 | BO25: 5 | BP25: 1 | BQ25: 0 | BR25: 0 | BS25: 69 | BT25: 11 | BU25: 0 | BV25: 0 | BW25: 0 | BX25: 0 | BY25: 11 | BZ25: 139 | CA25: 599
B26: 0.38541667 | C26: 77 | D26: 0 | E26: 1 | F26: 0 | G26: 1 | H26: 79 | I26: 89 | J26: 0 | K26: 2 | L26: 0 | M26: 0 | N26: 91 | O26: 58 | P26: 1 | Q26: 1 | R26: 0 | S26: 0 | T26: 60 | U26: 230 | V26: 10 | W26: 0 | X26: 0 | Y26: 0 | Z26: 0 | AA26: 10 | AB26: 29 | AC26: 1 | AD26: 2 | AE26: 0 | AF26: 0 | AG26: 32 | AH26: 23 | AI26: 0 | AJ26: 1 | AK26: 0 | AL26: 0 | AM26: 24 | AN26: 66 | AO26: 19 | AP26: 0 | AQ26: 0 | AR26: 0 | AS26: 0 | AT26: 19 | AU26: 87 | AV26: 0 | AW26: 3 | AX26: 0 | AY26: 0 | AZ26: 90 | BA26: 16 | BB26: 0 | BC26: 1 | BD26: 0 | BE26: 0 | BF26: 17 | BG26: 126 | BH26: 58 | BI26: 1 | BJ26: 2 | BK26: 0 | BL26: 1 | BM26: 62 | BN26: 68 | BO26: 3 | BP26: 1 | BQ26: 0 | BR26: 0 | BS26: 72 | BT26: 6 | BU26: 0 | BV26: 2 | BW26: 0 | BX26: 0 | BY26: 8 | BZ26: 142 | CA26: 564
B27: PM | C27: 1197 | D27: 3 | E27: 17 | F27: 1 | G27: 1 | H27: 1219 | I27: 1312 | J27: 6 | K27: 13 | L27: 1 | M27: 1 | N27: 1333 | O27: 913 | P27: 6 | Q27: 7 | R27: 0 | S27: 0 | T27: 926 | U27: 3478 | V27: 171 | W27: 2 | X27: 6 | Y27: 0 | Z27: 0 | AA27: 179 | AB27: 833 | AC27: 54 | AD27: 6 | AE27: 0 | AF27: 19 | AG27: 912 | AH27: 1156 | AI27: 1 | AJ27: 7 | AK27: 0 | AL27: 1 | AM27: 1165 | AN27: 2256 | AO27: 280 | AP27: 1 | AQ27: 3 | AR27: 0 | AS27: 1 | AT27: 285 | AU27: 1921 | AV27: 0 | AW27: 11 | AX27: 0 | AY27: 4 | AZ27: 1936 | BA27: 171 | BB27: 3 | BC27: 3 | BD27: 0 | BE27: 0 | BF27: 177 | BG27: 2398 | BH27: 1229 | BI27: 8 | BJ27: 11 | BK27: 0 | BL27: 6 | BM27: 1254 | BN27: 890 | BO27: 60 | BP27: 8 | BQ27: 0 | BR27: 13 | BS27: 971 | BT27: 214 | BU27: 0 | BV27: 3 | BW27: 0 | BX27: 0 | BY27: 217 | BZ27: 2442 | CA27: 10574
B28: 0.625 | C28: 86 | D28: 0 | E28: 0 | F28: 0 | G28: 0 | H28: 86 | I28: 81 | J28: 1 | K28: 3 | L28: 0 | M28: 0 | N28: 85 | O28: 50 | P28: 0 | Q28: 0 | R28: 0 | S28: 0 | T28: 50 | U28: 221 | V28: 22 | W28: 0 | X28: 1 | Y28: 0 | Z28: 0 | AA28: 23 | AB28: 57 | AC28: 3 | AD28: 0 | AE28: 0 | AF28: 1 | AG28: 61 | AH28: 74 | AI28: 1 | AJ28: 0 | AK28: 0 | AL28: 0 | AM28: 75 | AN28: 159 | AO28: 20 | AP28: 0 | AQ28: 0 | AR28: 0 | AS28: 1 | AT28: 21 | AU28: 150 | AV28: 0 | AW28: 0 | AX28: 0 | AY28: 0 | AZ28: 150 | BA28: 10 | BB28: 1 | BC28: 0 | BD28: 0 | BE28: 0 | BF28: 11 | BG28: 182 | BH28: 87 | BI28: 0 | BJ28: 1 | BK28: 0 | BL28: 0 | BM28: 88 | BN28: 62 | BO28: 5 | BP28: 2 | BQ28: 0 | BR28: 2 | BS28: 71 | BT28: 8 | BU28: 0 | BV28: 2 | BW28: 0 | BX28: 0 | BY28: 10 | BZ28: 169 | CA28: 731
B29: 0.63541667 | C29: 97 | D29: 1 | E29: 1 | F29: 0 | G29: 0 | H29: 99 | I29: 108 | J29: 2 | K29: 1 | L29: 0 | M29: 0 | N29: 111 | O29: 68 | P29: 0 | Q29: 0 | R29: 0 | S29: 0 | T29: 68 | U29: 278 | V29: 18 | W29: 0 | X29: 2 | Y29: 0 | Z29: 0 | AA29: 20 | AB29: 64 | AC29: 5 | AD29: 1 | AE29: 0 | AF29: 0 | AG29: 70 | AH29: 74 | AI29: 0 | AJ29: 0 | AK29: 0 | AL29: 0 | AM29: 74 | AN29: 164 | AO29: 23 | AP29: 0 | AQ29: 0 | AR29: 0 | AS29: 0 | AT29: 23 | AU29: 120 | AV29: 0 | AW29: 2 | AX29: 0 | AY29: 0 | AZ29: 122 | BA29: 19 | BB29: 1 | BC29: 0 | BD29: 0 | BE29: 0 | BF29: 20 | BG29: 165 | BH29: 68 | BI29: 1 | BJ29: 4 | BK29: 0 | BL29: 1 | BM29: 74 | BN29: 86 | BO29: 1 | BP29: 0 | BQ29: 0 | BR29: 3 | BS29: 90 | BT29: 17 | BU29: 0 | BV29: 0 | BW29: 0 | BX29: 0 | BY29: 17 | BZ29: 181 | CA29: 788
B30: 0.64583333 | C30: 82 | D30: 0 | E30: 0 | F30: 0 | G30: 0 | H30: 82 | I30: 74 | J30: 0 | K30: 2 | L30: 1 | M30: 0 | N30: 77 | O30: 79 | P30: 1 | Q30: 0 | R30: 0 | S30: 0 | T30: 80 | U30: 239 | V30: 16 | W30: 0 | X30: 0 | Y30: 0 | Z30: 0 | AA30: 16 | AB30: 53 | AC30: 2 | AD30: 0 | AE30: 0 | AF30: 1 | AG30: 56 | AH30: 61 | AI30: 0 | AJ30: 1 | AK30: 0 | AL30: 0 | AM30: 62 | AN30: 134 | AO30: 23 | AP30: 0 | AQ30: 0 | AR30: 0 | AS30: 0 | AT30: 23 | AU30: 123 | AV30: 0 | AW30: 0 | AX30: 0 | AY30: 0 | AZ30: 123 | BA30: 14 | BB30: 0 | BC30: 0 | BD30: 0 | BE30: 0 | BF30: 14 | BG30: 160 | BH30: 86 | BI30: 1 | BJ30: 2 | BK30: 0 | BL30: 0 | BM30: 89 | BN30: 64 | BO30: 5 | BP30: 0 | BQ30: 0 | BR30: 1 | BS30: 70 | BT30: 13 | BU30: 0 | BV30: 1 | BW30: 0 | BX30: 0 | BY30: 14 | BZ30: 173 | CA30: 706
B31: 0.65625 | C31: 92 | D31: 0 | E31: 0 | F31: 0 | G31: 0 | H31: 92 | I31: 109 | J31: 2 | K31: 1 | L31: 0 | M31: 1 | N31: 113 | O31: 89 | P31: 0 | Q31: 2 | R31: 0 | S31: 0 | T31: 91 | U31: 296 | V31: 9 | W31: 0 | X31: 0 | Y31: 0 | Z31: 0 | AA31: 9 | AB31: 51 | AC31: 5 | AD31: 0 | AE31: 0 | AF31: 0 | AG31: 56 | AH31: 74 | AI31: 0 | AJ31: 1 | AK31: 0 | AL31: 0 | AM31: 75 | AN31: 140 | AO31: 19 | AP31: 0 | AQ31: 0 | AR31: 0 | AS31: 0 | AT31: 19 | AU31: 136 | AV31: 0 | AW31: 1 | AX31: 0 | AY31: 0 | AZ31: 137 | BA31: 11 | BB31: 1 | BC31: 1 | BD31: 0 | BE31: 0 | BF31: 13 | BG31: 169 | BH31: 92 | BI31: 0 | BJ31: 2 | BK31: 0 | BL31: 0 | BM31: 94 | BN31: 52 | BO31: 3 | BP31: 0 | BQ31: 0 | BR31: 1 | BS31: 56 | BT31: 14 | BU31: 0 | BV31: 0 | BW31: 0 | BX31: 0 | BY31: 14 | BZ31: 164 | CA31: 769
B32: 0.66666667 | C32: 89 | D32: 0 | E32: 0 | F32: 0 | G32: 1 | H32: 90 | I32: 86 | J32: 0 | K32: 0 | L32: 0 | M32: 0 | N32: 86 | O32: 52 | P32: 1 | Q32: 3 | R32: 0 | S32: 0 | T32: 56 | U32: 232 | V32: 13 | W32: 0 | X32: 0 | Y32: 0 | Z32: 0 | AA32: 13 | AB32: 50 | AC32: 5 | AD32: 0 | AE32: 0 | AF32: 0 | AG32: 55 | AH32: 88 | AI32: 0 | AJ32: 1 | AK32: 0 | AL32: 1 | AM32: 90 | AN32: 158 | AO32: 19 | AP32: 0 | AQ32: 1 | AR32: 0 | AS32: 0 | AT32: 20 | AU32: 136 | AV32: 0 | AW32: 0 | AX32: 0 | AY32: 1 | AZ32: 137 | BA32: 12 | BB32: 0 | BC32: 0 | BD32: 0 | BE32: 0 | BF32: 12 | BG32: 169 | BH32: 82 | BI32: 0 | BJ32: 0 | BK32: 0 | BL32: 0 | BM32: 82 | BN32: 71 | BO32: 6 | BP32: 1 | BQ32: 0 | BR32: 0 | BS32: 78 | BT32: 15 | BU32: 0 | BV32: 0 | BW32: 0 | BX32: 0 | BY32: 15 | BZ32: 175 | CA32: 734
B33: 0.67708333 | C33: 96 | D33: 0 | E33: 4 | F33: 0 | G33: 0 | H33: 100 | I33: 79 | J33: 0 | K33: 0 | L33: 0 | M33: 0 | N33: 79 | O33: 60 | P33: 1 | Q33: 1 | R33: 0 | S33: 0 | T33: 62 | U33: 241 | V33: 12 | W33: 0 | X33: 0 | Y33: 0 | Z33: 0 | AA33: 12 | AB33: 61 | AC33: 2 | AD33: 0 | AE33: 0 | AF33: 2 | AG33: 65 | AH33: 84 | AI33: 0 | AJ33: 0 | AK33: 0 | AL33: 0 | AM33: 84 | AN33: 161 | AO33: 26 | AP33: 0 | AQ33: 0 | AR33: 0 | AS33: 0 | AT33: 26 | AU33: 171 | AV33: 0 | AW33: 0 | AX33: 0 | AY33: 1 | AZ33: 172 | BA33: 12 | BB33: 0 | BC33: 0 | BD33: 0 | BE33: 0 | BF33: 12 | BG33: 210 | BH33: 71 | BI33: 1 | BJ33: 1 | BK33: 0 | BL33: 1 | BM33: 74 | BN33: 57 | BO33: 7 | BP33: 0 | BQ33: 0 | BR33: 0 | BS33: 64 | BT33: 16 | BU33: 0 | BV33: 0 | BW33: 0 | BX33: 0 | BY33: 16 | BZ33: 154 | CA33: 766
B34: 0.6875 | C34: 94 | D34: 0 | E34: 1 | F34: 0 | G34: 0 | H34: 95 | I34: 93 | J34: 0 | K34: 1 | L34: 0 | M34: 0 | N34: 94 | O34: 71 | P34: 0 | Q34: 1 | R34: 0 | S34: 0 | T34: 72 | U34: 261 | V34: 11 | W34: 0 | X34: 0 | Y34: 0 | Z34: 0 | AA34: 11 | AB34: 83 | AC34: 4 | AD34: 0 | AE34: 0 | AF34: 0 | AG34: 87 | AH34: 119 | AI34: 0 | AJ34: 0 | AK34: 0 | AL34: 0 | AM34: 119 | AN34: 217 | AO34: 21 | AP34: 0 | AQ34: 0 | AR34: 0 | AS34: 0 | AT34: 21 | AU34: 179 | AV34: 0 | AW34: 1 | AX34: 0 | AY34: 0 | AZ34: 180 | BA34: 16 | BB34: 0 | BC34: 0 | BD34: 0 | BE34: 0 | BF34: 16 | BG34: 217 | BH34: 98 | BI34: 2 | BJ34: 0 | BK34: 0 | BL34: 1 | BM34: 101 | BN34: 65 | BO34: 7 | BP34: 1 | BQ34: 0 | BR34: 0 | BS34: 73 | BT34: 15 | BU34: 0 | BV34: 0 | BW34: 0 | BX34: 0 | BY34: 15 | BZ34: 189 | CA34: 884
B35: 0.69791667 | C35: 99 | D35: 0 | E35: 1 | F35: 0 | G35: 0 | H35: 100 | I35: 120 | J35: 0 | K35: 2 | L35: 0 | M35: 0 | N35: 122 | O35: 50 | P35: 1 | Q35: 0 | R35: 0 | S35: 0 | T35: 51 | U35: 273 | V35: 11 | W35: 1 | X35: 0 | Y35: 0 | Z35: 0 | AA35: 12 | AB35: 72 | AC35: 6 | AD35: 1 | AE35: 0 | AF35: 0 | AG35: 79 | AH35: 99 | AI35: 0 | AJ35: 1 | AK35: 0 | AL35: 0 | AM35: 100 | AN35: 191 | AO35: 24 | AP35: 1 | AQ35: 0 | AR35: 0 | AS35: 0 | AT35: 25 | AU35: 151 | AV35: 0 | AW35: 1 | AX35: 0 | AY35: 0 | AZ35: 152 | BA35: 8 | BB35: 0 | BC35: 0 | BD35: 0 | BE35: 0 | BF35: 8 | BG35: 185 | BH35: 114 | BI35: 0 | BJ35: 1 | BK35: 0 | BL35: 1 | BM35: 116 | BN35: 68 | BO35: 8 | BP35: 1 | BQ35: 0 | BR35: 0 | BS35: 77 | BT35: 12 | BU35: 0 | BV35: 0 | BW35: 0 | BX35: 0 | BY35: 12 | BZ35: 205 | CA35: 854
B36: 0.70833333 | C36: 85 | D36: 0 | E36: 3 | F36: 1 | G36: 0 | H36: 89 | I36: 106 | J36: 1 | K36: 1 | L36: 0 | M36: 0 | N36: 108 | O36: 73 | P36: 0 | Q36: 0 | R36: 0 | S36: 0 | T36: 73 | U36: 270 | V36: 8 | W36: 1 | X36: 1 | Y36: 0 | Z36: 0 | AA36: 10 | AB36: 74 | AC36: 3 | AD36: 2 | AE36: 0 | AF36: 8 | AG36: 87 | AH36: 113 | AI36: 0 | AJ36: 1 | AK36: 0 | AL36: 0 | AM36: 114 | AN36: 211 | AO36: 13 | AP36: 0 | AQ36: 0 | AR36: 0 | AS36: 0 | AT36: 13 | AU36: 142 | AV36: 0 | AW36: 3 | AX36: 0 | AY36: 0 | AZ36: 145 | BA36: 10 | BB36: 0 | BC36: 0 | BD36: 0 | BE36: 0 | BF36: 10 | BG36: 168 | BH36: 93 | BI36: 0 | BJ36: 0 | BK36: 0 | BL36: 0 | BM36: 93 | BN36: 86 | BO36: 3 | BP36: 0 | BQ36: 0 | BR36: 0 | BS36: 89 | BT36: 13 | BU36: 0 | BV36: 0 | BW36: 0 | BX36: 0 | BY36: 13 | BZ36: 195 | CA36: 844
B37: 0.71875 | C37: 98 | D37: 2 | E37: 2 | F37: 0 | G37: 0 | H37: 102 | I37: 111 | J37: 0 | K37: 1 | L37: 0 | M37: 0 | N37: 112 | O37: 63 | P37: 1 | Q37: 0 | R37: 0 | S37: 0 | T37: 64 | U37: 278 | V37: 13 | W37: 0 | X37: 0 | Y37: 0 | Z37: 0 | AA37: 13 | AB37: 90 | AC37: 5 | AD37: 1 | AE37: 0 | AF37: 3 | AG37: 99 | AH37: 105 | AI37: 0 | AJ37: 0 | AK37: 0 | AL37: 0 | AM37: 105 | AN37: 217 | AO37: 18 | AP37: 0 | AQ37: 0 | AR37: 0 | AS37: 0 | AT37: 18 | AU37: 155 | AV37: 0 | AW37: 0 | AX37: 0 | AY37: 1 | AZ37: 156 | BA37: 17 | BB37: 0 | BC37: 1 | BD37: 0 | BE37: 0 | BF37: 18 | BG37: 192 | BH37: 95 | BI37: 0 | BJ37: 0 | BK37: 0 | BL37: 0 | BM37: 95 | BN37: 51 | BO37: 3 | BP37: 0 | BQ37: 0 | BR37: 2 | BS37: 56 | BT37: 17 | BU37: 0 | BV37: 0 | BW37: 0 | BX37: 0 | BY37: 17 | BZ37: 168 | CA37: 855
B38: 0.72916667 | C38: 85 | D38: 0 | E38: 3 | F38: 0 | G38: 0 | H38: 88 | I38: 95 | J38: 0 | K38: 0 | L38: 0 | M38: 0 | N38: 95 | O38: 76 | P38: 0 | Q38: 0 | R38: 0 | S38: 0 | T38: 76 | U38: 259 | V38: 15 | W38: 0 | X38: 0 | Y38: 0 | Z38: 0 | AA38: 15 | AB38: 66 | AC38: 2 | AD38: 1 | AE38: 0 | AF38: 1 | AG38: 70 | AH38: 105 | AI38: 0 | AJ38: 0 | AK38: 0 | AL38: 0 | AM38: 105 | AN38: 190 | AO38: 13 | AP38: 0 | AQ38: 0 | AR38: 0 | AS38: 0 | AT38: 13 | AU38: 170 | AV38: 0 | AW38: 0 | AX38: 0 | AY38: 0 | AZ38: 170 | BA38: 15 | BB38: 0 | BC38: 1 | BD38: 0 | BE38: 0 | BF38: 16 | BG38: 199 | BH38: 88 | BI38: 1 | BJ38: 0 | BK38: 0 | BL38: 0 | BM38: 89 | BN38: 63 | BO38: 5 | BP38: 0 | BQ38: 0 | BR38: 1 | BS38: 69 | BT38: 17 | BU38: 0 | BV38: 0 | BW38: 0 | BX38: 0 | BY38: 17 | BZ38: 175 | CA38: 823
B39: 0.73958333 | C39: 83 | D39: 0 | E39: 2 | F39: 0 | G39: 0 | H39: 85 | I39: 114 | J39: 0 | K39: 0 | L39: 0 | M39: 0 | N39: 114 | O39: 61 | P39: 1 | Q39: 0 | R39: 0 | S39: 0 | T39: 62 | U39: 261 | V39: 11 | W39: 0 | X39: 1 | Y39: 0 | Z39: 0 | AA39: 12 | AB39: 39 | AC39: 4 | AD39: 0 | AE39: 0 | AF39: 3 | AG39: 46 | AH39: 63 | AI39: 0 | AJ39: 0 | AK39: 0 | AL39: 0 | AM39: 63 | AN39: 121 | AO39: 23 | AP39: 0 | AQ39: 2 | AR39: 0 | AS39: 0 | AT39: 25 | AU39: 108 | AV39: 0 | AW39: 0 | AX39: 0 | AY39: 0 | AZ39: 108 | BA39: 13 | BB39: 0 | BC39: 0 | BD39: 0 | BE39: 0 | BF39: 13 | BG39: 146 | BH39: 83 | BI39: 1 | BJ39: 0 | BK39: 0 | BL39: 0 | BM39: 84 | BN39: 65 | BO39: 3 | BP39: 0 | BQ39: 0 | BR39: 2 | BS39: 70 | BT39: 20 | BU39: 0 | BV39: 0 | BW39: 0 | BX39: 0 | BY39: 20 | BZ39: 174 | CA39: 702
... B41: 0.76041667 | C41: 55 | D41: 0 | E41: 0 | F41: 0 | G41: 0 | H41: 55 | I41: 67 | J41: 0 | K41: 1 | L41: 0 | M41: 0 | N41: 68 | O41: 53 | P41: 0 | Q41: 0 | R41: 0 | S41: 0 | T41: 53 | U41: 176 | V41: 7 | W41: 0 | X41: 0 | Y41: 0 | Z41: 0 | AA41: 7 | AB41: 41 | AC41: 5 | AD41: 0 | AE41: 0 | AF41: 0 | AG41: 46 | AH41: 43 | AI41: 0 | AJ41: 0 | AK41: 0 | AL41: 0 | AM41: 43 | AN41: 96 | AO41: 25 | AP41: 0 | AQ41: 0 | AR41: 0 | AS41: 0 | AT41: 25 | AU41: 85 | AV41: 0 | AW41: 0 | AX41: 0 | AY41: 0 | AZ41: 85 | BA41: 7 | BB41: 0 | BC41: 0 | BD41: 0 | BE41: 0 | BF41: 7 | BG41: 117 | BH41: 75 | BI41: 0 | BJ41: 0 | BK41: 0 | BL41: 2 | BM41: 77 | BN41: 52 | BO41: 2 | BP41: 2 | BQ41: 0 | BR41: 1 | BS41: 57 | BT41: 17 | BU41: 0 | BV41: 0 | BW41: 0 | BX41: 0 | BY41: 17 | BZ41: 151 | CA41: 540
B42: INT | C42: 826 | D42: 2 | E42: 22 | F42: 1 | G42: 2 | H42: 853 | I42: 1134 | J42: 18 | K42: 13 | L42: 2 | M42: 1 | N42: 1168 | O42: 782 | P42: 7 | Q42: 12 | R42: 0 | S42: 1 | T42: 802 | U42: 2823 | V42: 149 | W42: 9 | X42: 1 | Y42: 0 | Z42: 1 | AA42: 160 | AB42: 525 | AC42: 35 | AD42: 7 | AE42: 1 | AF42: 6 | AG42: 574 | AH42: 562 | AI42: 2 | AJ42: 12 | AK42: 0 | AL42: 0 | AM42: 576 | AN42: 1310 | AO42: 310 | AP42: 0 | AQ42: 6 | AR42: 0 | AS42: 0 | AT42: 316 | AU42: 1143 | AV42: 5 | AW42: 19 | AX42: 2 | AY42: 0 | AZ42: 1169 | BA42: 150 | BB42: 0 | BC42: 2 | BD42: 0 | BE42: 0 | BF42: 152 | BG42: 1637 | BH42: 805 | BI42: 10 | BJ42: 17 | BK42: 2 | BL42: 2 | BM42: 836 | BN42: 690 | BO42: 35 | BP42: 8 | BQ42: 0 | BR42: 14 | BS42: 747 | BT42: 212 | BU42: 5 | BV42: 5 | BW42: 0 | BX42: 0 | BY42: 222 | BZ42: 1805 | CA42: 7575
B43: 0.45833333 | C43: 49 | D43: 1 | E43: 2 | F43: 1 | G43: 0 | H43: 53 | I43: 91 | J43: 0 | K43: 1 | L43: 0 | M43: 0 | N43: 92 | O43: 55 | P43: 0 | Q43: 1 | R43: 0 | S43: 0 | T43: 56 | U43: 201 | V43: 14 | W43: 0 | X43: 0 | Y43: 0 | Z43: 1 | AA43: 15 | AB43: 42 | AC43: 3 | AD43: 0 | AE43: 0 | AF43: 0 | AG43: 45 | AH43: 40 | AI43: 0 | AJ43: 0 | AK43: 0 | AL43: 0 | AM43: 40 | AN43: 100 | AO43: 22 | AP43: 0 | AQ43: 0 | AR43: 0 | AS43: 0 | AT43: 22 | AU43: 84 | AV43: 0 | AW43: 0 | AX43: 1 | AY43: 0 | AZ43: 85 | BA43: 14 | BB43: 0 | BC43: 0 | BD43: 0 | BE43: 0 | BF43: 14 | BG43: 121 | BH43: 54 | BI43: 0 | BJ43: 2 | BK43: 0 | BL43: 0 | BM43: 56 | BN43: 44 | BO43: 3 | BP43: 0 | BQ43: 0 | BR43: 0 | BS43: 47 | BT43: 18 | BU43: 0 | BV43: 0 | BW43: 0 | BX43: 0 | BY43: 18 | BZ43: 121 | CA43: 543
B44: 0.46875 | C44: 72 | D44: 0 | E44: 1 | F44: 0 | G44: 0 | H44: 73 | I44: 96 | J44: 0 | K44: 0 | L44: 0 | M44: 0 | N44: 96 | O44: 63 | P44: 1 | Q44: 1 | R44: 0 | S44: 0 | T44: 65 | U44: 234 | V44: 11 | W44: 0 | X44: 0 | Y44: 0 | Z44: 0 | AA44: 11 | AB44: 33 | AC44: 2 | AD44: 0 | AE44: 0 | AF44: 0 | AG44: 35 | AH44: 45 | AI44: 0 | AJ44: 0 | AK44: 0 | AL44: 0 | AM44: 45 | AN44: 91 | AO44: 19 | AP44: 0 | AQ44: 1 | AR44: 0 | AS44: 0 | AT44: 20 | AU44: 79 | AV44: 0 | AW44: 2 | AX44: 1 | AY44: 0 | AZ44: 82 | BA44: 8 | BB44: 0 | BC44: 0 | BD44: 0 | BE44: 0 | BF44: 8 | BG44: 110 | BH44: 71 | BI44: 1 | BJ44: 2 | BK44: 1 | BL44: 0 | BM44: 75 | BN44: 51 | BO44: 3 | BP44: 0 | BQ44: 0 | BR44: 1 | BS44: 55 | BT44: 12 | BU44: 1 | BV44: 2 | BW44: 0 | BX44: 0 | BY44: 15 | BZ44: 145 | CA44: 580
B45: 0.47916667 | C45: 74 | D45: 0 | E45: 5 | F45: 0 | G45: 0 | H45: 79 | I45: 75 | J45: 0 | K45: 2 | L45: 0 | M45: 0 | N45: 77 | O45: 70 | P45: 0 | Q45: 3 | R45: 0 | S45: 0 | T45: 73 | U45: 229 | V45: 15 | W45: 0 | X45: 0 | Y45: 0 | Z45: 0 | AA45: 15 | AB45: 38 | AC45: 3 | AD45: 1 | AE45: 0 | AF45: 0 | AG45: 42 | AH45: 46 | AI45: 0 | AJ45: 4 | AK45: 0 | AL45: 0 | AM45: 50 | AN45: 107 | AO45: 20 | AP45: 0 | AQ45: 1 | AR45: 0 | AS45: 0 | AT45: 21 | AU45: 88 | AV45: 0 | AW45: 2 | AX45: 0 | AY45: 0 | AZ45: 90 | BA45: 8 | BB45: 0 | BC45: 0 | BD45: 0 | BE45: 0 | BF45: 8 | BG45: 119 | BH45: 53 | BI45: 0 | BJ45: 0 | BK45: 0 | BL45: 1 | BM45: 54 | BN45: 52 | BO45: 3 | BP45: 1 | BQ45: 0 | BR45: 2 | BS45: 58 | BT45: 15 | BU45: 0 | BV45: 1 | BW45: 0 | BX45: 0 | BY45: 16 | BZ45: 128 | CA45: 583
B46: 0.48958333 | C46: 72 | D46: 0 | E46: 3 | F46: 0 | G46: 0 | H46: 75 | I46: 110 | J46: 0 | K46: 3 | L46: 1 | M46: 0 | N46: 114 | O46: 76 | P46: 1 | Q46: 3 | R46: 0 | S46: 0 | T46: 80 | U46: 269 | V46: 16 | W46: 0 | X46: 0 | Y46: 0 | Z46: 0 | AA46: 16 | AB46: 40 | AC46: 4 | AD46: 0 | AE46: 0 | AF46: 0 | AG46: 44 | AH46: 37 | AI46: 0 | AJ46: 1 | AK46: 0 | AL46: 0 | AM46: 38 | AN46: 98 | AO46: 36 | AP46: 0 | AQ46: 1 | AR46: 0 | AS46: 0 | AT46: 37 | AU46: 114 | AV46: 0 | AW46: 3 | AX46: 0 | AY46: 0 | AZ46: 117 | BA46: 11 | BB46: 0 | BC46: 0 | BD46: 0 | BE46: 0 | BF46: 11 | BG46: 165 | BH46: 60 | BI46: 1 | BJ46: 2 | BK46: 0 | BL46: 0 | BM46: 63 | BN46: 69 | BO46: 3 | BP46: 0 | BQ46: 0 | BR46: 1 | BS46: 73 | BT46: 13 | BU46: 0 | BV46: 0 | BW46: 0 | BX46: 0 | BY46: 13 | BZ46: 149 | CA46: 681
B47: 0.5 | C47: 60 | D47: 0 | E47: 1 | F47: 0 | G47: 0 | H47: 61 | I47: 89 | J47: 0 | K47: 0 | L47: 0 | M47: 0 | N47: 89 | O47: 61 | P47: 0 | Q47: 0 | R47: 0 | S47: 0 | T47: 61 | U47: 211 | V47: 10 | W47: 0 | X47: 1 | Y47: 0 | Z47: 0 | AA47: 11 | AB47: 42 | AC47: 4 | AD47: 0 | AE47: 0 | AF47: 0 | AG47: 46 | AH47: 61 | AI47: 0 | AJ47: 3 | AK47: 0 | AL47: 0 | AM47: 64 | AN47: 121 | AO47: 25 | AP47: 0 | AQ47: 1 | AR47: 0 | AS47: 0 | AT47: 26 | AU47: 98 | AV47: 3 | AW47: 0 | AX47: 0 | AY47: 0 | AZ47: 101 | BA47: 11 | BB47: 0 | BC47: 0 | BD47: 0 | BE47: 0 | BF47: 11 | BG47: 138 | BH47: 70 | BI47: 0 | BJ47: 0 | BK47: 0 | BL47: 0 | BM47: 70 | BN47: 57 | BO47: 3 | BP47: 0 | BQ47: 0 | BR47: 2 | BS47: 62 | BT47: 21 | BU47: 0 | BV47: 0 | BW47: 0 | BX47: 0 | BY47: 21 | BZ47: 153 | CA47: 623
...

Sheet PeakCalc
A1: Time interval | B1: =A12-A11 -> 0.010416667 | H1: Hourly totals | N1: Graph data
B3: Period 1 | C3: Period 2 | D3: Period 3 | E3: Period 4 | H3: Period 1 | I3: Period 2 | J3: Period 3 | K3: Period 4
G5: Max Qty | H5: =MAX(H11:H303) -> 3218 | I5: =MAX(I11:I303) -> 2646 | J5: =MAX(J11:J303) -> 3437 | K5: =MAX(K11:K303) -> 0 | N5: Max Qty | O5: =INDEX($H5:$K5,1,MATCH($O$4,$H$10:$K$10,0)) -> 0
G6: Max Start Time | H6: =IF(H5=0,0,H7-1/24) -> 0.32291667 | I6: =IF(I5=0,0,I7-1/24) -> 0.52083333 | J6: =IF(J5=0,0,J7-1/24) -> 0.6875 | K6: =IF(K5=0,0,K7-1/24) -> 0 | N6: Max Start Time | O6: =INDEX($H6:$K6,1,MATCH($O$4,$H$10:$K$10,0)) -> 0
G7: Max End Time | H7: =IF(H5=0,0,INDEX($G$11:$G$303,MATCH(H$5,H$11:H$303,0))+$B$1) -> 0.36458333 | I7: =IF(I5=0,0,INDEX($G$11:$G$303,MATCH(I$5,I$11:I$303,0))+$B$1) -> 0.5625 | J7: =IF(J5=0,0,INDEX($G$11:$G$303,MATCH(J$5,J$11:J$303,0))+$B$1) -> 0.72916667 | K7: =IF(K5=0,0,INDEX($G$11:$G$303,MATCH(K$5,K$11:K$303,0))+$B$1) -> 0 | N7: Max End Time | O7: =INDEX($H7:$K7,1,MATCH($O$4,$H$10:$K$10,0)) -> 0
G8: Sentence | H8: =IF(H5=0,"","The peak hour for " &H10&" is "&H5&" vehicles between " & TEXT(H6, "hh:mm")& " and " &TEXT(H7,"hh:mm")) -> The peak hour for AM is 3218 vehicles between 07:45 and 08:45 | I8: =IF(I5=0,"","The peak hour for " &I10&" is "&I5&" vehicles between " & TEXT(I6, "hh:mm")& " and " &TEXT(I7,"hh:mm")) -> The peak hour for INT is 2646 vehicles between 12:30 and 13:30 | J8: =IF(J5=0,"","The peak hour for " &J10&" is "&J5&" vehicles between " & TEXT(J6, "hh:mm")& " and " &TEXT(J7,"hh:mm")) -> The peak hour for PM is 3437 vehicles between 16:30 and 17:30 | K8: =IF(K5=0,"","The peak hour for " &K10&" is "&K5&" vehicles between " & TEXT(K6, "hh:mm")& " and " &TEXT(K7,"hh:mm")) | N8: Graph Title | O8: ="Vehicle Count and Peak Hour "&U8 -> Vehicle Count and Peak Hour for AM Period | S8: Survey Period | T8: AM | U8: =IF(T8="(All)","","for "&T8&" Period") -> for AM Period
A9: Sum of Count | B9: Column Labels
A10: Row Labels | B10: AM | C10: INT | D10: PM | H10: =B10 -> AM | I10: =C10 -> INT | J10: =D10 -> PM | K10: =E10 -> 0 | L10: Peak marker | N10: Survey Period | O10: Time | P10: Total | Q10: Peak | S10: Row Labels | T10: Overall | U10: Peak Hour
A11: 0.27083333 | B11: 308 | G11: =A11 -> 0.27083333 | H11: =IF(B11<>0,SUMIF($G$11:$G11,">"&$G11-1/24,B$11:B11),0) -> 308 | I11: =IF(C11<>0,SUMIF($G$11:$G11,">"&$G11-1/24,C$11:C11),0) -> 0 | J11: =IF(D11<>0,SUMIF($G$11:$G11,">"&$G11-1/24,D$11:D11),0) -> 0 | K11: =IF(E11<>0,SUMIF($G$11:$G11,">"&$G11-1/24,E$11:E11),0) -> 0 | L11: =IF(OR(AND(G11>=$H$6-0.0001,G11<$H$7-0.0001),AND(G11>=$I$6-0.0001,G11<$I$7-0.0001),AND(G11>=$J$6-0.0001,G11<$J$7-0.0001),AND(G11>=$K$6-0.0001,G11<$K$7-0.0001)),1,0) -> 0 | N11: =IFERROR(INDEX($B$10:$E$10,1,MATCH(999999,$B11:$E11)),"-") -> AM | O11: =IF(G11=0,"",G11) -> 0.27083333 | P11: =SUM(B11:E11) -> 308 | Q11: =P11*L11 -> 0 | S11: 0.27083333 | T11: 308 | U11: 0
A12: 0.28125 | B12: 374 | G12: =A12 -> 0.28125 | H12: =IF(B12<>0,SUMIF($G$11:$G12,">"&$G12-1/24,B$11:B12),0) -> 682 | I12: =IF(C12<>0,SUMIF($G$11:$G12,">"&$G12-1/24,C$11:C12),0) -> 0 | J12: =IF(D12<>0,SUMIF($G$11:$G12,">"&$G12-1/24,D$11:D12),0) -> 0 | K12: =IF(E12<>0,SUMIF($G$11:$G12,">"&$G12-1/24,E$11:E12),0) -> 0 | L12: =IF(OR(AND(G12>=$H$6-0.0001,G12<$H$7-0.0001),AND(G12>=$I$6-0.0001,G12<$I$7-0.0001),AND(G12>=$J$6-0.0001,G12<$J$7-0.0001),AND(G12>=$K$6-0.0001,G12<$K$7-0.0001)),1,0) -> 0 | N12: =IFERROR(INDEX($B$10:$E$10,1,MATCH(999999,$B12:$E12)),"-") -> AM | O12: =IF(G12=0,"",G12) -> 0.28125 | P12: =SUM(B12:E12) -> 374 | Q12: =P12*L12 -> 0 | S12: 0.28125 | T12: 374 | U12: 0
A13: 0.29166667 | B13: 430 | G13: =A13 -> 0.29166667 | H13: =IF(B13<>0,SUMIF($G$11:$G13,">"&$G13-1/24,B$11:B13),0) -> 1112 | I13: =IF(C13<>0,SUMIF($G$11:$G13,">"&$G13-1/24,C$11:C13),0) -> 0 | J13: =IF(D13<>0,SUMIF($G$11:$G13,">"&$G13-1/24,D$11:D13),0) -> 0 | K13: =IF(E13<>0,SUMIF($G$11:$G13,">"&$G13-1/24,E$11:E13),0) -> 0 | L13: =IF(OR(AND(G13>=$H$6-0.0001,G13<$H$7-0.0001),AND(G13>=$I$6-0.0001,G13<$I$7-0.0001),AND(G13>=$J$6-0.0001,G13<$J$7-0.0001),AND(G13>=$K$6-0.0001,G13<$K$7-0.0001)),1,0) -> 0 | N13: =IFERROR(INDEX($B$10:$E$10,1,MATCH(999999,$B13:$E13)),"-") -> AM | O13: =IF(G13=0,"",G13) -> 0.29166667 | P13: =SUM(B13:E13) -> 430 | Q13: =P13*L13 -> 0 | S13: 0.29166667 | T13: 430 | U13: 0
A14: 0.30208333 | B14: 562 | G14: =A14 -> 0.30208333 | H14: =IF(B14<>0,SUMIF($G$11:$G14,">"&$G14-1/24,B$11:B14),0) -> 1674 | I14: =IF(C14<>0,SUMIF($G$11:$G14,">"&$G14-1/24,C$11:C14),0) -> 0 | J14: =IF(D14<>0,SUMIF($G$11:$G14,">"&$G14-1/24,D$11:D14),0) -> 0 | K14: =IF(E14<>0,SUMIF($G$11:$G14,">"&$G14-1/24,E$11:E14),0) -> 0 | L14: =IF(OR(AND(G14>=$H$6-0.0001,G14<$H$7-0.0001),AND(G14>=$I$6-0.0001,G14<$I$7-0.0001),AND(G14>=$J$6-0.0001,G14<$J$7-0.0001),AND(G14>=$K$6-0.0001,G14<$K$7-0.0001)),1,0) -> 0 | N14: =IFERROR(INDEX($B$10:$E$10,1,MATCH(999999,$B14:$E14)),"-") -> AM | O14: =IF(G14=0,"",G14) -> 0.30208333 | P14: =SUM(B14:E14) -> 562 | Q14: =P14*L14 -> 0 | S14: 0.30208333 | T14: 562 | U14: 0
A15: 0.3125 | B15: 723 | G15: =A15 -> 0.3125 | H15: =IF(B15<>0,SUMIF($G$11:$G15,">"&$G15-1/24,B$11:B15),0) -> 2089 | I15: =IF(C15<>0,SUMIF($G$11:$G15,">"&$G15-1/24,C$11:C15),0) -> 0 | J15: =IF(D15<>0,SUMIF($G$11:$G15,">"&$G15-1/24,D$11:D15),0) -> 0 | K15: =IF(E15<>0,SUMIF($G$11:$G15,">"&$G15-1/24,E$11:E15),0) -> 0 | L15: =IF(OR(AND(G15>=$H$6-0.0001,G15<$H$7-0.0001),AND(G15>=$I$6-0.0001,G15<$I$7-0.0001),AND(G15>=$J$6-0.0001,G15<$J$7-0.0001),AND(G15>=$K$6-0.0001,G15<$K$7-0.0001)),1,0) -> 0 | N15: =IFERROR(INDEX($B$10:$E$10,1,MATCH(999999,$B15:$E15)),"-") -> AM | O15: =IF(G15=0,"",G15) -> 0.3125 | P15: =SUM(B15:E15) -> 723 | Q15: =P15*L15 -> 0 | S15: 0.3125 | T15: 723 | U15: 0
A16: 0.32291667 | B16: 804 | G16: =A16 -> 0.32291667 | H16: =IF(B16<>0,SUMIF($G$11:$G16,">"&$G16-1/24,B$11:B16),0) -> 2519 | I16: =IF(C16<>0,SUMIF($G$11:$G16,">"&$G16-1/24,C$11:C16),0) -> 0 | J16: =IF(D16<>0,SUMIF($G$11:$G16,">"&$G16-1/24,D$11:D16),0) -> 0 | K16: =IF(E16<>0,SUMIF($G$11:$G16,">"&$G16-1/24,E$11:E16),0) -> 0 | L16: =IF(OR(AND(G16>=$H$6-0.0001,G16<$H$7-0.0001),AND(G16>=$I$6-0.0001,G16<$I$7-0.0001),AND(G16>=$J$6-0.0001,G16<$J$7-0.0001),AND(G16>=$K$6-0.0001,G16<$K$7-0.0001)),1,0) -> 1 | N16: =IFERROR(INDEX($B$10:$E$10,1,MATCH(999999,$B16:$E16)),"-") -> AM | O16: =IF(G16=0,"",G16) -> 0.32291667 | P16: =SUM(B16:E16) -> 804 | Q16: =P16*L16 -> 804 | S16: 0.32291667 | T16: 804 | U16: 804
A17: 0.33333333 | B17: 783 | G17: =A17 -> 0.33333333 | H17: =IF(B17<>0,SUMIF($G$11:$G17,">"&$G17-1/24,B$11:B17),0) -> 2872 | I17: =IF(C17<>0,SUMIF($G$11:$G17,">"&$G17-1/24,C$11:C17),0) -> 0 | J17: =IF(D17<>0,SUMIF($G$11:$G17,">"&$G17-1/24,D$11:D17),0) -> 0 | K17: =IF(E17<>0,SUMIF($G$11:$G17,">"&$G17-1/24,E$11:E17),0) -> 0 | L17: =IF(OR(AND(G17>=$H$6-0.0001,G17<$H$7-0.0001),AND(G17>=$I$6-0.0001,G17<$I$7-0.0001),AND(G17>=$J$6-0.0001,G17<$J$7-0.0001),AND(G17>=$K$6-0.0001,G17<$K$7-0.0001)),1,0) -> 1 | N17: =IFERROR(INDEX($B$10:$E$10,1,MATCH(999999,$B17:$E17)),"-") -> AM | O17: =IF(G17=0,"",G17) -> 0.33333333 | P17: =SUM(B17:E17) -> 783 | Q17: =P17*L17 -> 783 | S17: 0.33333333 | T17: 783 | U17: 783
A18: 0.34375 | B18: 835 | G18: =A18 -> 0.34375 | H18: =IF(B18<>0,SUMIF($G$11:$G18,">"&$G18-1/24,B$11:B18),0) -> 3145 | I18: =IF(C18<>0,SUMIF($G$11:$G18,">"&$G18-1/24,C$11:C18),0) -> 0 | J18: =IF(D18<>0,SUMIF($G$11:$G18,">"&$G18-1/24,D$11:D18),0) -> 0 | K18: =IF(E18<>0,SUMIF($G$11:$G18,">"&$G18-1/24,E$11:E18),0) -> 0 | L18: =IF(OR(AND(G18>=$H$6-0.0001,G18<$H$7-0.0001),AND(G18>=$I$6-0.0001,G18<$I$7-0.0001),AND(G18>=$J$6-0.0001,G18<$J$7-0.0001),AND(G18>=$K$6-0.0001,G18<$K$7-0.0001)),1,0) -> 1 | N18: =IFERROR(INDEX($B$10:$E$10,1,MATCH(999999,$B18:$E18)),"-") -> AM | O18: =IF(G18=0,"",G18) -> 0.34375 | P18: =SUM(B18:E18) -> 835 | Q18: =P18*L18 -> 835 | S18: 0.34375 | T18: 835 | U18: 835
A19: 0.35416667 | B19: 796 | G19: =A19 -> 0.35416667 | H19: =IF(B19<>0,SUMIF($G$11:$G19,">"&$G19-1/24,B$11:B19),0) -> 3218 | I19: =IF(C19<>0,SUMIF($G$11:$G19,">"&$G19-1/24,C$11:C19),0) -> 0 | J19: =IF(D19<>0,SUMIF($G$11:$G19,">"&$G19-1/24,D$11:D19),0) -> 0 | K19: =IF(E19<>0,SUMIF($G$11:$G19,">"&$G19-1/24,E$11:E19),0) -> 0 | L19: =IF(OR(AND(G19>=$H$6-0.0001,G19<$H$7-0.0001),AND(G19>=$I$6-0.0001,G19<$I$7-0.0001),AND(G19>=$J$6-0.0001,G19<$J$7-0.0001),AND(G19>=$K$6-0.0001,G19<$K$7-0.0001)),1,0) -> 1 | N19: =IFERROR(INDEX($B$10:$E$10,1,MATCH(999999,$B19:$E19)),"-") -> AM | O19: =IF(G19=0,"",G19) -> 0.35416667 | P19: =SUM(B19:E19) -> 796 | Q19: =P19*L19 -> 796 | S19: 0.35416667 | T19: 796 | U19: 796
A20: 0.36458333 | B20: 755 | G20: =A20 -> 0.36458333 | H20: =IF(B20<>0,SUMIF($G$11:$G20,">"&$G20-1/24,B$11:B20),0) -> 3169 | I20: =IF(C20<>0,SUMIF($G$11:$G20,">"&$G20-1/24,C$11:C20),0) -> 0 | J20: =IF(D20<>0,SUMIF($G$11:$G20,">"&$G20-1/24,D$11:D20),0) -> 0 | K20: =IF(E20<>0,SUMIF($G$11:$G20,">"&$G20-1/24,E$11:E20),0) -> 0 | L20: =IF(OR(AND(G20>=$H$6-0.0001,G20<$H$7-0.0001),AND(G20>=$I$6-0.0001,G20<$I$7-0.0001),AND(G20>=$J$6-0.0001,G20<$J$7-0.0001),AND(G20>=$K$6-0.0001,G20<$K$7-0.0001)),1,0) -> 0 | N20: =IFERROR(INDEX($B$10:$E$10,1,MATCH(999999,$B20:$E20)),"-") -> AM | O20: =IF(G20=0,"",G20) -> 0.36458333 | P20: =SUM(B20:E20) -> 755 | Q20: =P20*L20 -> 0 | S20: 0.36458333 | T20: 755 | U20: 0
A21: 0.375 | B21: 599 | G21: =A21 -> 0.375 | H21: =IF(B21<>0,SUMIF($G$11:$G21,">"&$G21-1/24,B$11:B21),0) -> 2985 | I21: =IF(C21<>0,SUMIF($G$11:$G21,">"&$G21-1/24,C$11:C21),0) -> 0 | J21: =IF(D21<>0,SUMIF($G$11:$G21,">"&$G21-1/24,D$11:D21),0) -> 0 | K21: =IF(E21<>0,SUMIF($G$11:$G21,">"&$G21-1/24,E$11:E21),0) -> 0 | L21: =IF(OR(AND(G21>=$H$6-0.0001,G21<$H$7-0.0001),AND(G21>=$I$6-0.0001,G21<$I$7-0.0001),AND(G21>=$J$6-0.0001,G21<$J$7-0.0001),AND(G21>=$K$6-0.0001,G21<$K$7-0.0001)),1,0) -> 0 | N21: =IFERROR(INDEX($B$10:$E$10,1,MATCH(999999,$B21:$E21)),"-") -> AM | O21: =IF(G21=0,"",G21) -> 0.375 | P21: =SUM(B21:E21) -> 599 | Q21: =P21*L21 -> 0 | S21: 0.375 | T21: 599 | U21: 0
