Workbook
Name rngApproaches: Ranges!$B$4:$H$4
Name rngBasicInfo: Input!$C$9:$C$11
Name rngCountInterval: Input!$I$9
Name rngExits: Ranges!$B$18:$H$24
Name rngMovements: Ranges!$B$8:$H$14
Name rngSurveyPeriods: Input!$I$12:$L$14
Name rngVehicleTypes: Input!$E$10:$F$16
Name Slicer_Survey_Period: #N/A
Name Slicer_Survey_Period1: #N/A

Sheet Input
B2: Turning Count Template
B4: Fill in blue cells. Leave blank if not required.
B7: Basic Info | E7: Vehicle Types | H7: Time Periods
B9: Intersection: | C9: Colombo Street_Moorhouse Avenue_Intersection | E9: Vehicle Type | F9: HCV? | H9: Count Interval | I9: 15 | J9: minutes
B10: Conditions: | C10: Fine | D10: 1 | E10: Bicycles On Crosswalk
B11: Date: | C11: 44712 | D11: 2 | E11: Pedestrians | I11: Survey Period 1 | J11: Survey Period 2 | K11: Survey Period 3 | L11: Survey Period 4
D12: 3 | H12: Name | I12: AM | J12: INT | K12: PM
C13: Note: do not use "/" in Intersection Name | D13: 4 | H13: Start Time | I13: 0.27083333 | J13: 0.45833333 | K13: 0.625
D14: 5 | H14: End Time | I14: 0.38541667 | J14: 0.57291667 | K14: 0.76041667
D15: 6
D16: 7
B18: Movements
B20: Approach 1 | C20: Colombo Street North
B22: Movement 1 | C22: Peds CCW | D22: Exit to:
B23: Movement 2 | C23: Peds CW | D23: Exit to:
B24: Movement 3 | D24: Exit to:
B25: Movement 4 | D25: Exit to:
B26: Movement 5 | D26: Exit to:
B27: Movement 6 | D27: Exit to:
B28: Movement 7 | D28: Exit to:
B31: Approach 2 | C31: Moorhouse Avenue East
B33: Movement 1 | C33: Peds CCW | D33: Exit to:
B34: Movement 2 | C34: Peds CW | D34: Exit to:
B35: Movement 3 | D35: Exit to:
B36: Movement 4 | D36: Exit to:
B37: Movement 5 | D37: Exit to:
B38: Movement 6 | D38: Exit to:
B39: Movement 7 | D39: Exit to:
B42: Approach 3 | C42: Colombo Street South
B44: Movement 1 | C44: Peds CCW | D44: Exit to:
B45: Movement 2 | C45: Peds CW | D45: Exit to:
B46: Movement 3 | D46: Exit to:
B47: Movement 4 | D47: Exit to:
B48: Movement 5 | D48: Exit to:
B49: Movement 6 | D49: Exit to:
B50: Movement 7 | D50: Exit to:
B53: Approach 4 | C53: Moorhouse Avenue West
B55: Movement 1 | C55: Peds CCW | D55: Exit to:
B56: Movement 2 | C56: Peds CW | D56: Exit to:
B57: Movement 3 | D57: Exit to:
...

Sheet Ranges
B2: Approaches
B4: =Input!C20 -> Colombo Street North | C4: =Input!C31 -> Moorhouse Avenue East | D4: =Input!C42 -> Colombo Street South | E4: =Input!C53 -> Moorhouse Avenue West | F4: =Input!C64 -> 0 | G4: =Input!C75 -> 0 | H4: =Input!C86 -> 0
B6: Movements
B8: =Input!C22 -> Peds CCW | C8: =Input!C33 -> Peds CCW | D8: =Input!C44 -> Peds CCW | E8: =Input!C55 -> Peds CCW | F8: =Input!C66 -> 0 | G8: =Input!C77 -> 0 | H8: =Input!C88 -> 0
B9: =Input!C23 -> Peds CW | C9: =Input!C34 -> Peds CW | D9: =Input!C45 -> Peds CW | E9: =Input!C56 -> Peds CW | F9: =Input!C67 -> 0 | G9: =Input!C78 -> 0 | H9: =Input!C89 -> 0
B10: =Input!C24 -> 0 | C10: =Input!C35 -> 0 | D10: =Input!C46 -> 0 | E10: =Input!C57 -> 0 | F10: =Input!C68 -> 0 | G10: =Input!C79 -> 0 | H10: =Input!C90 -> 0
B11: =Input!C25 -> 0 | C11: =Input!C36 -> 0 | D11: =Input!C47 -> 0 | E11: =Input!C58 -> 0 | F11: =Input!C69 -> 0 | G11: =Input!C80 -> 0 | H11: =Input!C91 -> 0
B12: =Input!C26 -> 0 | C12: =Input!C37 -> 0 | D12: =Input!C48 -> 0 | E12: =Input!C59 -> 0 | F12: =Input!C70 -> 0 | G12: =Input!C81 -> 0 | H12: =Input!C92 -> 0
B13: =Input!C27 -> 0 | C13: =Input!C38 -> 0 | D13: =Input!C49 -> 0 | E13: =Input!C60 -> 0 | F13: =Input!C71 -> 0 | G13: =Input!C82 -> 0 | H13: =Input!C93 -> 0
B14: =Input!C28 -> 0 | C14: =Input!C39 -> 0 | D14: =Input!C50 -> 0 | E14: =Input!C61 -> 0 | F14: =Input!C72 -> 0 | G14: =Input!C83 -> 0 | H14: =Input!C94 -> 0
B16: Exits
B18: =Input!E22 -> 0 | C18: =Input!E33 -> 0 | D18: =Input!E44 -> 0 | E18: =Input!E55 -> 0 | F18: =Input!E66 -> 0 | G18: =Input!E77 -> 0 | H18: =Input!E88 -> 0
B19: =Input!E23 -> 0 | C19: =Input!E34 -> 0 | D19: =Input!E45 -> 0 | E19: =Input!E56 -> 0 | F19: =Input!E67 -> 0 | G19: =Input!E78 -> 0 | H19: =Input!E89 -> 0
B20: =Input!E24 -> 0 | C20: =Input!E35 -> 0 | D20: =Input!E46 -> 0 | E20: =Input!E57 -> 0 | F20: =Input!E68 -> 0 | G20: =Input!E79 -> 0 | H20: =Input!E90 -> 0
B21: =Input!E25 -> 0 | C21: =Input!E36 -> 0 | D21: =Input!E47 -> 0 | E21: =Input!E58 -> 0 | F21: =Input!E69 -> 0 | G21: =Input!E80 -> 0 | H21: =Input!E91 -> 0
B22: =Input!E26 -> 0 | C22: =Input!E37 -> 0 | D22: =Input!E48 -> 0 | E22: =Input!E59 -> 0 | F22: =Input!E70 -> 0 | G22: =Input!E81 -> 0 | H22: =Input!E92 -> 0
B23: =Input!E27 -> 0 | C23: =Input!E38 -> 0 | D23: =Input!E49 -> 0 | E23: =Input!E60 -> 0 | F23: =Input!E71 -> 0 | G23: =Input!E82 -> 0 | H23: =Input!E93 -> 0
B24: =Input!E28 -> 0 | C24: =Input!E39 -> 0 | D24: =Input!E50 -> 0 | E24: =Input!E61 -> 0 | F24: =Input!E72 -> 0 | G24: =Input!E83 -> 0 | H24: =Input!E94 -> 0

Sheet Table
A1: Colombo Street_Moorhouse Avenue_Intersection Fine 31/05/2022
C5: Colombo Street North | G5: Moorhouse Avenue East | K5: Colombo Street South | O5: Moorhouse Avenue West
C6: Peds CCW | E6: Peds CW | G6: Peds CCW | I6: Peds CW | K6: Peds CCW | M6: Peds CW | O6: Peds CCW | Q6: Peds CW
A7: Period | B7: Time | C7: Bicycles On Crosswalk | D7: Pedestrians | E7: Bicycles On Crosswalk | F7: Pedestrians | G7: Bicycles On Crosswalk | H7: Pedestrians | I7: Bicycles On Crosswalk | J7: Pedestrians | K7: Bicycles On Crosswalk | L7: Pedestrians | M7: Bicycles On Crosswalk | N7: Pedestrians | O7: Bicycles On Crosswalk | P7: Pedestrians | Q7: Bicycles On Crosswalk | R7: Pedestrians
A8: AM | B8: 0.27083333 | C8: 0 | D8: 0 | E8: 1 | F8: 2 | G8: 0 | H8: 2 | I8: 0 | J8: 0 | K8: 0 | L8: 1 | M8: 0 | N8: 2 | O8: 0 | P8: 0 | Q8: 0 | R8: 1
A9: AM | B9: 0.28125 | C9: 0 | D9: 0 | E9: 1 | F9: 1 | G9: 0 | H9: 8 | I9: 0 | J9: 1 | K9: 0 | L9: 0 | M9: 0 | N9: 0 | O9: 0 | P9: 0 | Q9: 0 | R9: 0
A10: AM | B10: 0.29166667 | C10: 1 | D10: 0 | E10: 0 | F10: 0 | G10: 0 | H10: 9 | I10: 3 | J10: 4 | K10: 0 | L10: 2 | M10: 0 | N10: 2 | O10: 0 | P10: 0 | Q10: 1 | R10: 4
A11: AM | B11: 0.30208333 | C11: 0 | D11: 1 | E11: 0 | F11: 0 | G11: 0 | H11: 6 | I11: 0 | J11: 3 | K11: 0 | L11: 1 | M11: 0 | N11: 0 | O11: 0 | P11: 1 | Q11: 0 | R11: 5
A12: AM | B12: 0.3125 | C12: 0 | D12: 1 | E12: 1 | F12: 0 | G12: 0 | H12: 3 | I12: 1 | J12: 0 | K12: 1 | L12: 1 | M12: 0 | N12: 1 | O12: 0 | P12: 2 | Q12: 0 | R12: 7
A13: AM | B13: 0.32291667 | C13: 1 | D13: 0 | E13: 0 | F13: 0 | G13: 1 | H13: 17 | I13: 6 | J13: 1 | K13: 0 | L13: 1 | M13: 0 | N13: 0 | O13: 1 | P13: 0 | Q13: 1 | R13: 8
A14: AM | B14: 0.33333333 | C14: 0 | D14: 0 | E14: 0 | F14: 0 | G14: 1 | H14: 14 | I14: 8 | J14: 2 | K14: 0 | L14: 0 | M14: 0 | N14: 0 | O14: 0 | P14: 1 | Q14: 0 | R14: 10
A15: AM | B15: 0.34375 | C15: 1 | D15: 0 | E15: 1 | F15: 0 | G15: 1 | H15: 8 | I15: 4 | J15: 0 | K15: 0 | L15: 2 | M15: 0 | N15: 0 | O15: 0 | P15: 1 | Q15: 0 | R15: 7
A16: AM | B16: 0.35416667 | C16: 1 | D16: 0 | E16: 1 | F16: 3 | G16: 1 | H16: 12 | I16: 1 | J16: 0 | K16: 0 | L16: 0 | M16: 0 | N16: 3 | O16: 0 | P16: 1 | Q16: 0 | R16: 4
A17: AM | B17: 0.36458333 | C17: 0 | D17: 1 | E17: 0 | F17: 1 | G17: 1 | H17: 11 | I17: 1 | J17: 1 | K17: 0 | L17: 0 | M17: 0 | N17: 2 | O17: 0 | P17: 1 | Q17: 1 | R17: 7
A18: AM | B18: 0.375 | C18: 1 | D18: 5 | E18: 0 | F18: 2 | G18: 0 | H18: 3 | I18: 0 | J18: 2 | K18: 0 | L18: 2 | M18: 0 | N18: 0 | O18: 0 | P18: 4 | Q18: 0 | R18: 4
A19: AM | B19: 0.38541667 | C19: 1 | D19: 1 | E19: 0 | F19: 1 | G19: 0 | H19: 3 | I19: 0 | J19: 3 | K19: 0 | L19: 1 | M19: 0 | N19: 4 | O19: 0 | P19: 0 | Q19: 0 | R19: 4
... A47: PM | B47: 0.76041667 | C47: 0 | D47: 2 | E47: 1 | F47: 4 | G47: 0 | H47: 3 | I47: 8 | J47: 3 | K47: 0 | L47: 0 | M47: 0 | N47: 2 | O47: 0 | P47: 1 | Q47: 0 | R47: 3

Sheet PivotData
A1: Approach | B1: Movement | C1: Exit | D1: Vehicle | E1: Survey Period | F1: Time | G1: Count | H1: Time Grouped | I1: Peak Marker
A2: Colombo Street North | B2: Peds CCW | C2: 0 | D2: Bicycles On Crosswalk | E2: AM | F2: 0.27083333 | G2: 0 | H2: =FLOOR(tblPivotData[[#This Row],[Time]],Summary!$B$6/1440) -> 0.27083333 | I2: =INDEX(PeakCalc!$L$10:$L$303,MATCH(tblPivotData[[#This Row],[Time]],PeakCalc!$G$10:$G$303,0)) -> 0
A3: Colombo Street North | B3: Peds CCW | C3: 0 | D3: Bicycles On Crosswalk | E3: AM | F3: 0.28125 | G3: 0 | H3: =FLOOR(tblPivotData[[#This Row],[Time]],Summary!$B$6/1440) -> 0.28125 | I3: =INDEX(PeakCalc!$L$10:$L$303,MATCH(tblPivotData[[#This Row],[Time]],PeakCalc!$G$10:$G$303,0)) -> 0
A4: Colombo Street North | B4: Peds CCW | C4: 0 | D4: Bicycles On Crosswalk | E4: AM | F4: 0.29166667 | G4: 1 | H4: =FLOOR(tblPivotData[[#This Row],[Time]],Summary!$B$6/1440) -> 0.29166667 | I4: =INDEX(PeakCalc!$L$10:$L$303,MATCH(tblPivotData[[#This Row],[Time]],PeakCalc!$G$10:$G$303,0)) -> 0
A5: Colombo Street North | B5: Peds CCW | C5: 0 | D5: Bicycles On Crosswalk | E5: AM | F5: 0.30208333 | G5: 0 | H5: =FLOOR(tblPivotData[[#This Row],[Time]],Summary!$B$6/1440) -> 0.30208333 | I5: =INDEX(PeakCalc!$L$10:$L$303,MATCH(tblPivotData[[#This Row],[Time]],PeakCalc!$G$10:$G$303,0)) -> 0
A6: Colombo Street North | B6: Peds CCW | C6: 0 | D6: Bicycles On Crosswalk | E6: AM | F6: 0.3125 | G6: 0 | H6: =FLOOR(tblPivotData[[#This Row],[Time]],Summary!$B$6/1440) -> 0.3125 | I6: =INDEX(PeakCalc!$L$10:$L$303,MATCH(tblPivotData[[#This Row],[Time]],PeakCalc!$G$10:$G$303,0)) -> 0
A7: Colombo Street North | B7: Peds CCW | C7: 0 | D7: Bicycles On Crosswalk | E7: AM | F7: 0.32291667 | G7: 1 | H7: =FLOOR(tblPivotData[[#This Row],[Time]],Summary!$B$6/1440) -> 0.32291667 | I7: =INDEX(PeakCalc!$L$10:$L$303,MATCH(tblPivotData[[#This Row],[Time]],PeakCalc!$G$10:$G$303,0)) -> 1
A8: Colombo Street North | B8: Peds CCW | C8: 0 | D8: Bicycles On Crosswalk | E8: AM | F8: 0.33333333 | G8: 0 | H8: =FLOOR(tblPivotData[[#This Row],[Time]],Summary!$B$6/1440) -> 0.33333333 | I8: =INDEX(PeakCalc!$L$10:$L$303,MATCH(tblPivotData[[#This Row],[Time]],PeakCalc!$G$10:$G$303,0)) -> 1
A9: Colombo Street North | B9: Peds CCW | C9: 0 | D9: Bicycles On Crosswalk | E9: AM | F9: 0.34375 | G9: 1 | H9: =FLOOR(tblPivotData[[#This Row],[Time]],Summary!$B$6/1440) -> 0.34375 | I9: =INDEX(PeakCalc!$L$10:$L$303,MATCH(tblPivotData[[#This Row],[Time]],PeakCalc!$G$10:$G$303,0)) -> 1
A10: Colombo Street North | B10: Peds CCW | C10: 0 | D10: Bicycles On Crosswalk | E10: AM | F10: 0.35416667 | G10: 1 | H10: =FLOOR(tblPivotData[[#This Row],[Time]],Summary!$B$6/1440) -> 0.35416667 | I10: =INDEX(PeakCalc!$L$10:$L$303,MATCH(tblPivotData[[#This Row],[Time]],PeakCalc!$G$10:$G$303,0)) -> 1
A11: Colombo Street North | B11: Peds CCW | C11: 0 | D11: Bicycles On Crosswalk | E11: AM | F11: 0.36458333 | G11: 0 | H11: =FLOOR(tblPivotData[[#This Row],[Time]],Summary!$B$6/1440) -> 0.36458333 | I11: =INDEX(PeakCalc!$L$10:$L$303,MATCH(tblPivotData[[#This Row],[Time]],PeakCalc!$G$10:$G$303,0)) -> 0
A12: Colombo Street North | B12: Peds CCW | C12: 0 | D12: Bicycles On Crosswalk | E12: AM | F12: 0.375 | G12: 1 | H12: =FLOOR(tblPivotData[[#This Row],[Time]],Summary!$B$6/1440) -> 0.375 | I12: =INDEX(PeakCalc!$L$10:$L$303,MATCH(tblPivotData[[#This Row],[Time]],PeakCalc!$G$10:$G$303,0)) -> 0
A13: Colombo Street North | B13: Peds CCW | C13: 0 | D13: Bicycles On Crosswalk | E13: AM | F13: 0.38541667 | G13: 1 | H13: =FLOOR(tblPivotData[[#This Row],[Time]],Summary!$B$6/1440) -> 0.38541667 | I13: =INDEX(PeakCalc!$L$10:$L$303,MATCH(tblPivotData[[#This Row],[Time]],PeakCalc!$G$10:$G$303,0)) -> 0
... A609: Moorhouse Avenue West | B609: Peds CW | C609: 0 | D609: Pedestrians | E609: PM | F609: 0.76041667 | G609: 3 | H609: =FLOOR(tblPivotData[[#This Row],[Time]],Summary!$B$6/1440) -> 0.76041667 | I609: =INDEX(PeakCalc!$L$10:$L$303,MATCH(tblPivotData[[#This Row],[Time]],PeakCalc!$G$10:$G$303,0)) -> 0

Sheet SummaryCalc
B2: Interval | C2: =rngCountInterval -> 15
B5: Options to group time by
B7: Existing intervals | E7: Selection
B8: 5 | C8: 15 | E8: =C2 -> 15
B10: 5 | C10: 15 | E10: =INDEX($B10:$C10,1,MATCH(E$8,$B$8:$C$8,0)) -> 15
B11: 10 | C11: 30 | E11: =INDEX($B11:$C11,1,MATCH(E$8,$B$8:$C$8,0)) -> 30
B12: 15 | C12: 60 | E12: =INDEX($B12:$C12,1,MATCH(E$8,$B$8:$C$8,0)) -> 60
B13: 20 | C13: - | E13: =INDEX($B13:$C13,1,MATCH(E$8,$B$8:$C$8,0)) -> -
B14: 30 | C14: - | E14: =INDEX($B14:$C14,1,MATCH(E$8,$B$8:$C$8,0)) -> -
B15: 60 | C15: - | E15: =INDEX($B15:$C15,1,MATCH(E$8,$B$8:$C$8,0)) -> -

Sheet Summary
B2: Summary Table
B4: Select time interval to group by
B6: 15 | C6: minutes
B8: Then right click on any cell in the table, and click Refresh
C11: Colombo Street North | I11: Colombo Street North Total | J11: Moorhouse Avenue East | P11: Moorhouse Avenue East Total | Q11: Colombo Street South | W11: Colombo Street South Total | X11: Moorhouse Avenue West | AD11: Moorhouse Avenue West Total | AE11: Grand Total
C12: Peds CCW | E12: Peds CCW Total | F12: Peds CW | H12: Peds CW Total | J12: Peds CCW | L12: Peds CCW Total | M12: Peds CW | O12: Peds CW Total | Q12: Peds CCW | S12: Peds CCW Total | T12: Peds CW | V12: Peds CW Total | X12: Peds CCW | Z12: Peds CCW Total | AA12: Peds CW | AC12: Peds CW Total
C13: Bicycles On Crosswalk | D13: Pedestrians | F13: Bicycles On Crosswalk | G13: Pedestrians | J13: Bicycles On Crosswalk | K13: Pedestrians | M13: Bicycles On Crosswalk | N13: Pedestrians | Q13: Bicycles On Crosswalk | R13: Pedestrians | T13: Bicycles On Crosswalk | U13: Pedestrians | X13: Bicycles On Crosswalk | Y13: Pedestrians | AA13: Bicycles On Crosswalk | AB13: Pedestrians
B14: AM | C14: 6 | D14: 9 | E14: 15 | F14: 5 | G14: 10 | H14: 15 | I14: 30 | J14: 5 | K14: 96 | L14: 101 | M14: 24 | N14: 17 | O14: 41 | P14: 142 | Q14: 1 | R14: 11 | S14: 12 | T14: 0 | U14: 14 | V14: 14 | W14: 26 | X14: 1 | Y14: 11 | Z14: 12 | AA14: 3 | AB14: 61 | AC14: 64 | AD14: 76 | AE14: 274
B15: 0.27083333 | C15: 0 | D15: 0 | E15: 0 | F15: 1 | G15: 2 | H15: 3 | I15: 3 | J15: 0 | K15: 2 | L15: 2 | M15: 0 | N15: 0 | O15: 0 | P15: 2 | Q15: 0 | R15: 1 | S15: 1 | T15: 0 | U15: 2 | V15: 2 | W15: 3 | X15: 0 | Y15: 0 | Z15: 0 | AA15: 0 | AB15: 1 | AC15: 1 | AD15: 1 | AE15: 9
B16: 0.28125 | C16: 0 | D16: 0 | E16: 0 | F16: 1 | G16: 1 | H16: 2 | I16: 2 | J16: 0 | K16: 8 | L16: 8 | M16: 0 | N16: 1 | O16: 1 | P16: 9 | Q16: 0 | R16: 0 | S16: 0 | T16: 0 | U16: 0 | V16: 0 | W16: 0 | X16: 0 | Y16: 0 | Z16: 0 | AA16: 0 | AB16: 0 | AC16: 0 | AD16: 0 | AE16: 11
B17: 0.29166667 | C17: 1 | D17: 0 | E17: 1 | F17: 0 | G17: 0 | H17: 0 | I17: 1 | J17: 0 | K17: 9 | L17: 9 | M17: 3 | N17: 4 | O17: 7 | P17: 16 | Q17: 0 | R17: 2 | S17: 2 | T17: 0 | U17: 2 | V17: 2 | W17: 4 | X17: 0 | Y17: 0 | Z17: 0 | AA17: 1 | AB17: 4 | AC17: 5 | AD17: 5 | AE17: 26
B18: 0.30208333 | C18: 0 | D18: 1 | E18: 1 | F18: 0 | G18: 0 | H18: 0 | I18: 1 | J18: 0 | K18: 6 | L18: 6 | M18: 0 | N18: 3 | O18: 3 | P18: 9 | Q18: 0 | R18: 1 | S18: 1 | T18: 0 | U18: 0 | V18: 0 | W18: 1 | X18: 0 | Y18: 1 | Z18: 1 | AA18: 0 | AB18: 5 | AC18: 5 | AD18: 6 | AE18: 17
B19: 0.3125 | C19: 0 | D19: 1 | E19: 1 | F19: 1 | G19: 0 | H19: 1 | I19: 2 | J19: 0 | K19: 3 | L19: 3 | M19: 1 | N19: 0 | O19: 1 | P19: 4 | Q19: 1 | R19: 1 | S19: 2 | T19: 0 | U19: 1 | V19: 1 | W19: 3 | X19: 0 | Y19: 2 | Z19: 2 | AA19: 0 | AB19: 7 | AC19: 7 | AD19: 9 | AE19: 18
B20: 0.32291667 | C20: 1 | D20: 0 | E20: 1 | F20: 0 | G20: 0 | H20: 0 | I20: 1 | J20: 1 | K20: 17 | L20: 18 | M20: 6 | N20: 1 | O20: 7 | P20: 25 | Q20: 0 | R20: 1 | S20: 1 | T20: 0 | U20: 0 | V20: 0 | W20: 1 | X20: 1 | Y20: 0 | Z20: 1 | AA20: 1 | AB20: 8 | AC20: 9 | AD20: 10 | AE20: 37
B21: 0.33333333 | C21: 0 | D21: 0 | E21: 0 | F21: 0 | G21: 0 | H21: 0 | I21: 0 | J21: 1 | K21: 14 | L21: 15 | M21: 8 | N21: 2 | O21: 10 | P21: 25 | Q21: 0 | R21: 0 | S21: 0 | T21: 0 | U21: 0 | V21: 0 | W21: 0 | X21: 0 | Y21: 1 | Z21: 1 | AA21: 0 | AB21: 10 | AC21: 10 | AD21: 11 | AE21: 36
B22: 0.34375 | C22: 1 | D22: 0 | E22: 1 | F22: 1 | G22: 0 | H22: 1 | I22: 2 | J22: 1 | K22: 8 | L22: 9 | M22: 4 | N22: 0 | O22: 4 | P22: 13 | Q22: 0 | R22: 2 | S22: 2 | T22: 0 | U22: 0 | V22: 0 | W22: 2 | X22: 0 | Y22: 1 | Z22: 1 | AA22: 0 | AB22: 7 | AC22: 7 | AD22: 8 | AE22: 25
B23: 0.35416667 | C23: 1 | D23: 0 | E23: 1 | F23: 1 | G23: 3 | H23: 4 | I23: 5 | J23: 1 | K23: 12 | L23: 13 | M23: 1 | N23: 0 | O23: 1 | P23: 14 | Q23: 0 | R23: 0 | S23: 0 | T23: 0 | U23: 3 | V23: 3 | W23: 3 | X23: 0 | Y23: 1 | Z23: 1 | AA23: 0 | AB23: 4 | AC23: 4 | AD23: 5 | AE23: 27
B24: 0.36458333 | C24: 0 | D24: 1 | E24: 1 | F24: 0 | G24: 1 | H24: 1 | I24: 2 | J24: 1 | K24: 11 | L24: 12 | M24: 1 | N24: 1 | O24: 2 | P24: 14 | Q24: 0 | R24: 0 | S24: 0 | T24: 0 | U24: 2 | V24: 2 | W24: 2 | X24: 0 | Y24: 1 | Z24: 1 | AA24: 1 | AB24: 7 | AC24: 8 | AD24: 9 | AE24: 27
B25: 0.375 | C25: 1 | D25: 5 | E25: 6 | F25: 0 | G25: 2 | H25: 2 | I25: 8 | J25: 0 | K25: 3 | L25: 3 | M25: 0 | N25: 2 | O25: 2 | P25: 5 | Q25: 0 | R25: 2 | S25: 2 | T25: 0 | U25: 0 | V25: 0 | W25: 2 | X25: 0 | Y25: 4 | Z25: 4 | AA25: 0 | AB25: 4 | AC25: 4 | AD25: 8 | AE25: 23
B26: 0.38541667 | C26: 1 | D26: 1 | E26: 2 | F26: 0 | G26: 1 | H26: 1 | I26: 3 | J26: 0 | K26: 3 | L26: 3 | M26: 0 | N26: 3 | O26: 3 | P26: 6 | Q26: 0 | R26: 1 | S26: 1 | T26: 0 | U26: 4 | V26: 4 | W26: 5 | X26: 0 | Y26: 0 | Z26: 0 | AA26: 0 | AB26: 4 | AC26: 4 | AD26: 4 | AE26: 18
B27: PM | C27: 5 | D27: 33 | E27: 38 | F27: 2 | G27: 42 | H27: 44 | I27: 82 | J27: 9 | K27: 30 | L27: 39 | M27: 212 | N27: 129 | O27: 341 | P27: 380 | Q27: 0 | R27: 23 | S27: 23 | T27: 0 | U27: 27 | V27: 27 | W27: 50 | X27: 3 | Y27: 75 | Z27: 78 | AA27: 7 | AB27: 51 | AC27: 58 | AD27: 136 | AE27: 648
B28: 0.625 | C28: 0 | D28: 1 | E28: 1 | F28: 0 | G28: 6 | H28: 6 | I28: 7 | J28: 5 | K28: 3 | L28: 8 | M28: 8 | N28: 8 | O28: 16 | P28: 24 | Q28: 0 | R28: 2 | S28: 2 | T28: 0 | U28: 2 | V28: 2 | W28: 4 | X28: 0 | Y28: 4 | Z28: 4 | AA28: 0 | AB28: 1 | AC28: 1 | AD28: 5 | AE28: 40
B29: 0.63541667 | C29: 0 | D29: 5 | E29: 5 | F29: 0 | G29: 0 | H29: 0 | I29: 5 | J29: 0 | K29: 1 | L29: 1 | M29: 10 | N29: 9 | O29: 19 | P29: 20 | Q29: 0 | R29: 0 | S29: 0 | T29: 0 | U29: 1 | V29: 1 | W29: 1 | X29: 0 | Y29: 10 | Z29: 10 | AA29: 0 | AB29: 6 | AC29: 6 | AD29: 16 | AE29: 42
B30: 0.64583333 | C30: 0 | D30: 7 | E30: 7 | F30: 0 | G30: 5 | H30: 5 | I30: 12 | J30: 1 | K30: 3 | L30: 4 | M30: 7 | N30: 13 | O30: 20 | P30: 24 | Q30: 0 | R30: 0 | S30: 0 | T30: 0 | U30: 2 | V30: 2 | W30: 2 | X30: 0 | Y30: 5 | Z30: 5 | AA30: 0 | AB30: 3 | AC30: 3 | AD30: 8 | AE30: 46
B31: 0.65625 | C31: 0 | D31: 3 | E31: 3 | F31: 1 | G31: 1 | H31: 2 | I31: 5 | J31: 0 | K31: 2 | L31: 2 | M31: 14 | N31: 9 | O31: 23 | P31: 25 | Q31: 0 | R31: 0 | S31: 0 | T31: 0 | U31: 0 | V31: 0 | W31: 0 | X31: 1 | Y31: 8 | Z31: 9 | AA31: 3 | AB31: 2 | AC31: 5 | AD31: 14 | AE31: 44
B32: 0.66666667 | C32: 0 | D32: 3 | E32: 3 | F32: 0 | G32: 3 | H32: 3 | I32: 6 | J32: 0 | K32: 2 | L32: 2 | M32: 12 | N32: 12 | O32: 24 | P32: 26 | Q32: 0 | R32: 0 | S32: 0 | T32: 0 | U32: 0 | V32: 0 | W32: 0 | X32: 0 | Y32: 7 | Z32: 7 | AA32: 0 | AB32: 5 | AC32: 5 | AD32: 12 | AE32: 44
B33: 0.67708333 | C33: 1 | D33: 7 | E33: 8 | F33: 0 | G33: 1 | H33: 1 | I33: 9 | J33: 0 | K33: 0 | L33: 0 | M33: 17 | N33: 5 | O33: 22 | P33: 22 | Q33: 0 | R33: 1 | S33: 1 | T33: 0 | U33: 1 | V33: 1 | W33: 2 | X33: 0 | Y33: 4 | Z33: 4 | AA33: 0 | AB33: 4 | AC33: 4 | AD33: 8 | AE33: 41
B34: 0.6875 | C34: 1 | D34: 1 | E34: 2 | F34: 0 | G34: 6 | H34: 6 | I34: 8 | J34: 1 | K34: 7 | L34: 8 | M34: 12 | N34: 10 | O34: 22 | P34: 30 | Q34: 0 | R34: 2 | S34: 2 | T34: 0 | U34: 0 | V34: 0 | W34: 2 | X34: 1 | Y34: 11 | Z34: 12 | AA34: 0 | AB34: 6 | AC34: 6 | AD34: 18 | AE34: 58
B35: 0.69791667 | C35: 0 | D35: 2 | E35: 2 | F35: 0 | G35: 1 | H35: 1 | I35: 3 | J35: 1 | K35: 0 | L35: 1 | M35: 28 | N35: 7 | O35: 35 | P35: 36 | Q35: 0 | R35: 2 | S35: 2 | T35: 0 | U35: 2 | V35: 2 | W35: 4 | X35: 0 | Y35: 4 | Z35: 4 | AA35: 0 | AB35: 4 | AC35: 4 | AD35: 8 | AE35: 51
B36: 0.70833333 | C36: 1 | D36: 1 | E36: 2 | F36: 0 | G36: 6 | H36: 6 | I36: 8 | J36: 0 | K36: 1 | L36: 1 | M36: 25 | N36: 14 | O36: 39 | P36: 40 | Q36: 0 | R36: 2 | S36: 2 | T36: 0 | U36: 5 | V36: 5 | W36: 7 | X36: 0 | Y36: 7 | Z36: 7 | AA36: 2 | AB36: 6 | AC36: 8 | AD36: 15 | AE36: 70
B37: 0.71875 | C37: 0 | D37: 1 | E37: 1 | F37: 0 | G37: 4 | H37: 4 | I37: 5 | J37: 1 | K37: 4 | L37: 5 | M37: 30 | N37: 20 | O37: 50 | P37: 55 | Q37: 0 | R37: 4 | S37: 4 | T37: 0 | U37: 3 | V37: 3 | W37: 7 | X37: 0 | Y37: 4 | Z37: 4 | AA37: 1 | AB37: 4 | AC37: 5 | AD37: 9 | AE37: 76
B38: 0.72916667 | C38: 1 | D38: 0 | E38: 1 | F38: 0 | G38: 3 | H38: 3 | I38: 4 | J38: 0 | K38: 1 | L38: 1 | M38: 24 | N38: 9 | O38: 33 | P38: 34 | Q38: 0 | R38: 6 | S38: 6 | T38: 0 | U38: 2 | V38: 2 | W38: 8 | X38: 0 | Y38: 6 | Z38: 6 | AA38: 0 | AB38: 4 | AC38: 4 | AD38: 10 | AE38: 56
B39: 0.73958333 | C39: 0 | D39: 0 | E39: 0 | F39: 0 | G39: 2 | H39: 2 | I39: 2 | J39: 0 | K39: 1 | L39: 1 | M39: 5 | N39: 3 | O39: 8 | P39: 9 | Q39: 0 | R39: 3 | S39: 3 | T39: 0 | U39: 4 | V39: 4 | W39: 7 | X39: 1 | Y39: 3 | Z39: 4 | AA39: 1 | AB39: 3 | AC39: 4 | AD39: 8 | AE39: 26
... B41: 0.76041667 | C41: 0 | D41: 2 | E41: 2 | F41: 1 | G41: 4 | H41: 5 | I41: 7 | J41: 0 | K41: 3 | L41: 3 | M41: 8 | N41: 3 | O41: 11 | P41: 14 | Q41: 0 | R41: 0 | S41: 0 | T41: 0 | U41: 2 | V41: 2 | W41: 2 | X41: 0 | Y41: 1 | Z41: 1 | AA41: 0 | AB41: 3 | AC41: 3 | AD41: 4 | AE41: 27
B42: INT | C42: 6 | D42: 33 | E42: 39 | F42: 4 | G42: 23 | H42: 27 | I42: 66 | J42: 1 | K42: 39 | L42: 40 | M42: 12 | N42: 32 | O42: 44 | P42: 84 | Q42: 0 | R42: 18 | S42: 18 | T42: 0 | U42: 16 | V42: 16 | W42: 34 | X42: 2 | Y42: 57 | Z42: 59 | AA42: 2 | AB42: 58 | AC42: 60 | AD42: 119 | AE42: 303
B43: 0.45833333 | C43: 0 | D43: 6 | E43: 6 | F43: 1 | G43: 4 | H43: 5 | I43: 11 | J43: 0 | K43: 0 | L43: 0 | M43: 0 | N43: 3 | O43: 3 | P43: 3 | Q43: 0 | R43: 6 | S43: 6 | T43: 0 | U43: 1 | V43: 1 | W43: 7 | X43: 0 | Y43: 5 | Z43: 5 | AA43: 0 | AB43: 5 | AC43: 5 | AD43: 10 | AE43: 31
B44: 0.46875 | C44: 1 | D44: 2 | E44: 3 | F44: 0 | G44: 2 | H44: 2 | I44: 5 | J44: 0 | K44: 2 | L44: 2 | M44: 2 | N44: 0 | O44: 2 | P44: 4 | Q44: 0 | R44: 0 | S44: 0 | T44: 0 | U44: 0 | V44: 0 | W44: 0 | X44: 0 | Y44: 6 | Z44: 6 | AA44: 0 | AB44: 7 | AC44: 7 | AD44: 13 | AE44: 22
B45: 0.47916667 | C45: 0 | D45: 3 | E45: 3 | F45: 1 | G45: 0 | H45: 1 | I45: 4 | J45: 0 | K45: 3 | L45: 3 | M45: 0 | N45: 2 | O45: 2 | P45: 5 | Q45: 0 | R45: 0 | S45: 0 | T45: 0 | U45: 1 | V45: 1 | W45: 1 | X45: 1 | Y45: 2 | Z45: 3 | AA45: 0 | AB45: 0 | AC45: 0 | AD45: 3 | AE45: 13
B46: 0.48958333 | C46: 2 | D46: 1 | E46: 3 | F46: 0 | G46: 2 | H46: 2 | I46: 5 | J46: 0 | K46: 1 | L46: 1 | M46: 0 | N46: 1 | O46: 1 | P46: 2 | Q46: 0 | R46: 2 | S46: 2 | T46: 0 | U46: 2 | V46: 2 | W46: 4 | X46: 1 | Y46: 5 | Z46: 6 | AA46: 0 | AB46: 5 | AC46: 5 | AD46: 11 | AE46: 22
B47: 0.5 | C47: 0 | D47: 3 | E47: 3 | F47: 0 | G47: 1 | H47: 1 | I47: 4 | J47: 0 | K47: 4 | L47: 4 | M47: 1 | N47: 1 | O47: 2 | P47: 6 | Q47: 0 | R47: 1 | S47: 1 | T47: 0 | U47: 2 | V47: 2 | W47: 3 | X47: 0 | Y47: 5 | Z47: 5 | AA47: 1 | AB47: 2 | AC47: 3 | AD47: 8 | AE47: 21
...

Sheet PeakCalc
A1: Time interval | B1: =A12-A11 -> 0.010416667 | H1: Hourly totals | N1: Graph data
B3: Period 1 | C3: Period 2 | D3: Period 3 | E3: Period 4 | H3: Period 1 | I3: Period 2 | J3: Period 3 | K3: Period 4
G5: Max Qty | H5: =MAX(H11:H303) -> 125 | I5: =MAX(I11:I303) -> 115 | J5: =MAX(J11:J303) -> 255 | K5: =MAX(K11:K303) -> 0 | N5: Max Qty | O5: =INDEX($H5:$K5,1,MATCH($O$4,$H$10:$K$10,0)) -> 0
G6: Max Start Time | H6: =IF(H5=0,0,H7-1/24) -> 0.32291667 | I6: =IF(I5=0,0,I7-1/24) -> 0.52083333 | J6: =IF(J5=0,0,J7-1/24) -> 0.6875 | K6: =IF(K5=0,0,K7-1/24) -> 0 | N6: Max Start Time | O6: =INDEX($H6:$K6,1,MATCH($O$4,$H$10:$K$10,0)) -> 0
G7: Max End Time | H7: =IF(H5=0,0,INDEX($G$11:$G$303,MATCH(H$5,H$11:H$303,0))+$B$1) -> 0.36458333 | I7: =IF(I5=0,0,INDEX($G$11:$G$303,MATCH(I$5,I$11:I$303,0))+$B$1) -> 0.5625 | J7: =IF(J5=0,0,INDEX($G$11:$G$303,MATCH(J$5,J$11:J$303,0))+$B$1) -> 0.72916667 | K7: =IF(K5=0,0,INDEX($G$11:$G$303,MATCH(K$5,K$11:K$303,0))+$B$1) -> 0 | N7: Max End Time | O7: =INDEX($H7:$K7,1,MATCH($O$4,$H$10:$K$10,0)) -> 0
G8: Sentence | H8: =IF(H5=0,"","The peak hour for " &H10&" is "&H5&" vehicles between " & TEXT(H6, "hh:mm")& " and " &TEXT(H7,"hh:mm")) -> The peak hour for AM is 125 vehicles between 07:45 and 08:45 | I8: =IF(I5=0,"","The peak hour for " &I10&" is "&I5&" vehicles between " & TEXT(I6, "hh:mm")& " and " &TEXT(I7,"hh:mm")) -> The peak hour for INT is 115 vehicles between 12:30 and 13:30 | J8: =IF(J5=0,"","The peak hour for " &J10&" is "&J5&" vehicles between " & TEXT(J6, "hh:mm")& " and " &TEXT(J7,"hh:mm")) -> The peak hour for PM is 255 vehicles between 16:30 and 17:30 | K8: =IF(K5=0,"","The peak hour for " &K10&" is "&K5&" vehicles between " & TEXT(K6, "hh:mm")& " and " &TEXT(K7,"hh:mm")) | N8: Graph Title | O8: ="Vehicle Count and Peak Hour "&U8 -> Vehicle Count and Peak Hour for AM Period | S8: Survey Period | T8: AM | U8: =IF(T8="(All)","","for "&T8&" Period") -> for AM Period
A9: Sum of Count | B9: Column Labels
A10: Row Labels | B10: AM | C10: INT | D10: PM | H10: =B10 -> AM | I10: =C10 -> INT | J10: =D10 -> PM | K10: =E10 -> 0 | L10: Peak marker | N10: Survey Period | O10: Time | P10: Total | Q10: Peak | S10: Row Labels | T10: Overall | U10: Peak Hour
A11: 0.27083333 | B11: 9 | G11: =A11 -> 0.27083333 | H11: =IF(B11<>0,SUMIF($G$11:$G11,">"&$G11-1/24,B$11:B11),0) -> 9 | I11: =IF(C11<>0,SUMIF($G$11:$G11,">"&$G11-1/24,C$11:C11),0) -> 0 | J11: =IF(D11<>0,SUMIF($G$11:$G11,">"&$G11-1/24,D$11:D11),0) -> 0 | K11: =IF(E11<>0,SUMIF($G$11:$G11,">"&$G11-1/24,E$11:E11),0) -> 0 | L11: =IF(OR(AND(G11>=$H$6-0.0001,G11<$H$7-0.0001),AND(G11>=$I$6-0.0001,G11<$I$7-0.0001),AND(G11>=$J$6-0.0001,G11<$J$7-0.0001),AND(G11>=$K$6-0.0001,G11<$K$7-0.0001)),1,0) -> 0 | N11: =IFERROR(INDEX($B$10:$E$10,1,MATCH(999999,$B11:$E11)),"-") -> AM | O11: =IF(G11=0,"",G11) -> 0.27083333 | P11: =SUM(B11:E11) -> 9 | Q11: =P11*L11 -> 0 | S11: 0.27083333 | T11: 9 | U11: 0
A12: 0.28125 | B12: 11 | G12: =A12 -> 0.28125 | H12: =IF(B12<>0,SUMIF($G$11:$G12,">"&$G12-1/24,B$11:B12),0) -> 20 | I12: =IF(C12<>0,SUMIF($G$11:$G12,">"&$G12-1/24,C$11:C12),0) -> 0 | J12: =IF(D12<>0,SUMIF($G$11:$G12,">"&$G12-1/24,D$11:D12),0) -> 0 | K12: =IF(E12<>0,SUMIF($G$11:$G12,">"&$G12-1/24,E$11:E12),0) -> 0 | L12: =IF(OR(AND(G12>=$H$6-0.0001,G12<$H$7-0.0001),AND(G12>=$I$6-0.0001,G12<$I$7-0.0001),AND(G12>=$J$6-0.0001,G12<$J$7-0.0001),AND(G12>=$K$6-0.0001,G12<$K$7-0.0001)),1,0) -> 0 | N12: =IFERROR(INDEX($B$10:$E$10,1,MATCH(999999,$B12:$E12)),"-") -> AM | O12: =IF(G12=0,"",G12) -> 0.28125 | P12: =SUM(B12:E12) -> 11 | Q12: =P12*L12 -> 0 | S12: 0.28125 | T12: 11 | U12: 0
A13: 0.29166667 | B13: 26 | G13: =A13 -> 0.29166667 | H13: =IF(B13<>0,SUMIF($G$11:$G13,">"&$G13-1/24,B$11:B13),0) -> 46 | I13: =IF(C13<>0,SUMIF($G$11:$G13,">"&$G13-1/24,C$11:C13),0) -> 0 | J13: =IF(D13<>0,SUMIF($G$11:$G13,">"&$G13-1/24,D$11:D13),0) -> 0 | K13: =IF(E13<>0,SUMIF($G$11:$G13,">"&$G13-1/24,E$11:E13),0) -> 0 | L13: =IF(OR(AND(G13>=$H$6-0.0001,G13<$H$7-0.0001),AND(G13>=$I$6-0.0001,G13<$I$7-0.0001),AND(G13>=$J$6-0.0001,G13<$J$7-0.0001),AND(G13>=$K$6-0.0001,G13<$K$7-0.0001)),1,0) -> 0 | N13: =IFERROR(INDEX($B$10:$E$10,1,MATCH(999999,$B13:$E13)),"-") -> AM | O13: =IF(G13=0,"",G13) -> 0.29166667 | P13: =SUM(B13:E13) -> 26 | Q13: =P13*L13 -> 0 | S13: 0.29166667 | T13: 26 | U13: 0
A14: 0.30208333 | B14: 17 | G14: =A14 -> 0.30208333 | H14: =IF(B14<>0,SUMIF($G$11:$G14,">"&$G14-1/24,B$11:B14),0) -> 63 | I14: =IF(C14<>0,SUMIF($G$11:$G14,">"&$G14-1/24,C$11:C14),0) -> 0 | J14: =IF(D14<>0,SUMIF($G$11:$G14,">"&$G14-1/24,D$11:D14),0) -> 0 | K14: =IF(E14<>0,SUMIF($G$11:$G14,">"&$G14-1/24,E$11:E14),0) -> 0 | L14: =IF(OR(AND(G14>=$H$6-0.0001,G14<$H$7-0.0001),AND(G14>=$I$6-0.0001,G14<$I$7-0.0001),AND(G14>=$J$6-0.0001,G14<$J$7-0.0001),AND(G14>=$K$6-0.0001,G14<$K$7-0.0001)),1,0) -> 0 | N14: =IFERROR(INDEX($B$10:$E$10,1,MATCH(999999,$B14:$E14)),"-") -> AM | O14: =IF(G14=0,"",G14) -> 0.30208333 | P14: =SUM(B14:E14) -> 17 | Q14: =P14*L14 -> 0 | S14: 0.30208333 | T14: 17 | U14: 0
A15: 0.3125 | B15: 18 | G15: =A15 -> 0.3125 | H15: =IF(B15<>0,SUMIF($G$11:$G15,">"&$G15-1/24,B$11:B15),0) -> 72 | I15: =IF(C15<>0,SUMIF($G$11:$G15,">"&$G15-1/24,C$11:C15),0) -> 0 | J15: =IF(D15<>0,SUMIF($G$11:$G15,">"&$G15-1/24,D$11:D15),0) -> 0 | K15: =IF(E15<>0,SUMIF($G$11:$G15,">"&$G15-1/24,E$11:E15),0) -> 0 | L15: =IF(OR(AND(G15>=$H$6-0.0001,G15<$H$7-0.0001),AND(G15>=$I$6-0.0001,G15<$I$7-0.0001),AND(G15>=$J$6-0.0001,G15<$J$7-0.0001),AND(G15>=$K$6-0.0001,G15<$K$7-0.0001)),1,0) -> 0 | N15: =IFERROR(INDEX($B$10:$E$10,1,MATCH(999999,$B15:$E15)),"-") -> AM | O15: =IF(G15=0,"",G15) -> 0.3125 | P15: =SUM(B15:E15) -> 18 | Q15: =P15*L15 -> 0 | S15: 0.3125 | T15: 18 | U15: 0
A16: 0.32291667 | B16: 37 | G16: =A16 -> 0.32291667 | H16: =IF(B16<>0,SUMIF($G$11:$G16,">"&$G16-1/24,B$11:B16),0) -> 98 | I16: =IF(C16<>0,SUMIF($G$11:$G16,">"&$G16-1/24,C$11:C16),0) -> 0 | J16: =IF(D16<>0,SUMIF($G$11:$G16,">"&$G16-1/24,D$11:D16),0) -> 0 | K16: =IF(E16<>0,SUMIF($G$11:$G16,">"&$G16-1/24,E$11:E16),0) -> 0 | L16: =IF(OR(AND(G16>=$H$6-0.0001,G16<$H$7-0.0001),AND(G16>=$I$6-0.0001,G16<$I$7-0.0001),AND(G16>=$J$6-0.0001,G16<$J$7-0.0001),AND(G16>=$K$6-0.0001,G16<$K$7-0.0001)),1,0) -> 1 | N16: =IFERROR(INDEX($B$10:$E$10,1,MATCH(999999,$B16:$E16)),"-") -> AM | O16: =IF(G16=0,"",G16) -> 0.32291667 | P16: =SUM(B16:E16) -> 37 | Q16: =P16*L16 -> 37 | S16: 0.32291667 | T16: 37 | U16: 37
A17: 0.33333333 | B17: 36 | G17: =A17 -> 0.33333333 | H17: =IF(B17<>0,SUMIF($G$11:$G17,">"&$G17-1/24,B$11:B17),0) -> 108 | I17: =IF(C17<>0,SUMIF($G$11:$G17,">"&$G17-1/24,C$11:C17),0) -> 0 | J17: =IF(D17<>0,SUMIF($G$11:$G17,">"&$G17-1/24,D$11:D17),0) -> 0 | K17: =IF(E17<>0,SUMIF($G$11:$G17,">"&$G17-1/24,E$11:E17),0) -> 0 | L17: =IF(OR(AND(G17>=$H$6-0.0001,G17<$H$7-0.0001),AND(G17>=$I$6-0.0001,G17<$I$7-0.0001),AND(G17>=$J$6-0.0001,G17<$J$7-0.0001),AND(G17>=$K$6-0.0001,G17<$K$7-0.0001)),1,0) -> 1 | N17: =IFERROR(INDEX($B$10:$E$10,1,MATCH(999999,$B17:$E17)),"-") -> AM | O17: =IF(G17=0,"",G17) -> 0.33333333 | P17: =SUM(B17:E17) -> 36 | Q17: =P17*L17 -> 36 | S17: 0.33333333 | T17: 36 | U17: 36
A18: 0.34375 | B18: 25 | G18: =A18 -> 0.34375 | H18: =IF(B18<>0,SUMIF($G$11:$G18,">"&$G18-1/24,B$11:B18),0) -> 116 | I18: =IF(C18<>0,SUMIF($G$11:$G18,">"&$G18-1/24,C$11:C18),0) -> 0 | J18: =IF(D18<>0,SUMIF($G$11:$G18,">"&$G18-1/24,D$11:D18),0) -> 0 | K18: =IF(E18<>0,SUMIF($G$11:$G18,">"&$G18-1/24,E$11:E18),0) -> 0 | L18: =IF(OR(AND(G18>=$H$6-0.0001,G18<$H$7-0.0001),AND(G18>=$I$6-0.0001,G18<$I$7-0.0001),AND(G18>=$J$6-0.0001,G18<$J$7-0.0001),AND(G18>=$K$6-0.0001,G18<$K$7-0.0001)),1,0) -> 1 | N18: =IFERROR(INDEX($B$10:$E$10,1,MATCH(999999,$B18:$E18)),"-") -> AM | O18: =IF(G18=0,"",G18) -> 0.34375 | P18: =SUM(B18:E18) -> 25 | Q18: =P18*L18 -> 25 | S18: 0.34375 | T18: 25 | U18: 25
A19: 0.35416667 | B19: 27 | G19: =A19 -> 0.35416667 | H19: =IF(B19<>0,SUMIF($G$11:$G19,">"&$G19-1/24,B$11:B19),0) -> 125 | I19: =IF(C19<>0,SUMIF($G$11:$G19,">"&$G19-1/24,C$11:C19),0) -> 0 | J19: =IF(D19<>0,SUMIF($G$11:$G19,">"&$G19-1/24,D$11:D19),0) -> 0 | K19: =IF(E19<>0,SUMIF($G$11:$G19,">"&$G19-1/24,E$11:E19),0) -> 0 | L19: =IF(OR(AND(G19>=$H$6-0.0001,G19<$H$7-0.0001),AND(G19>=$I$6-0.0001,G19<$I$7-0.0001),AND(G19>=$J$6-0.0001,G19<$J$7-0.0001),AND(G19>=$K$6-0.0001,G19<$K$7-0.0001)),1,0) -> 1 | N19: =IFERROR(INDEX($B$10:$E$10,1,MATCH(999999,$B19:$E19)),"-") -> AM | O19: =IF(G19=0,"",G19) -> 0.35416667 | P19: =SUM(B19:E19) -> 27 | Q19: =P19*L19 -> 27 | S19: 0.35416667 | T19: 27 | U19: 27
A20: 0.36458333 | B20: 27 | G20: =A20 -> 0.36458333 | H20: =IF(B20<>0,SUMIF($G$11:$G20,">"&$G20-1/24,B$11:B20),0) -> 115 | I20: =IF(C20<>0,SUMIF($G$11:$G20,">"&$G20-1/24,C$11:C20),0) -> 0 | J20: =IF(D20<>0,SUMIF($G$11:$G20,">"&$G20-1/24,D$11:D20),0) -> 0 | K20: =IF(E20<>0,SUMIF($G$11:$G20,">"&$G20-1/24,E$11:E20),0) -> 0 | L20: =IF(OR(AND(G20>=$H$6-0.0001,G20<$H$7-0.0001),AND(G20>=$I$6-0.0001,G20<$I$7-0.0001),AND(G20>=$J$6-0.0001,G20<$J$7-0.0001),AND(G20>=$K$6-0.0001,G20<$K$7-0.0001)),1,0) -> 0 | N20: =IFERROR(INDEX($B$10:$E$10,1,MATCH(999999,$B20:$E20)),"-") -> AM | O20: =IF(G20=0,"",G20) -> 0.36458333 | P20: =SUM(B20:E20) -> 27 | Q20: =P20*L20 -> 0 | S20: 0.36458333 | T20: 27 | U20: 0
A21: 0.375 | B21: 23 | G21: =A21 -> 0.375 | H21: =IF(B21<>0,SUMIF($G$11:$G21,">"&$G21-1/24,B$11:B21),0) -> 102 | I21: =IF(C21<>0,SUMIF($G$11:$G21,">"&$G21-1/24,C$11:C21),0) -> 0 | J21: =IF(D21<>0,SUMIF($G$11:$G21,">"&$G21-1/24,D$11:D21),0) -> 0 | K21: =IF(E21<>0,SUMIF($G$11:$G21,">"&$G21-1/24,E$11:E21),0) -> 0 | L21: =IF(OR(AND(G21>=$H$6-0.0001,G21<$H$7-0.0001),AND(G21>=$I$6-0.0001,G21<$I$7-0.0001),AND(G21>=$J$6-0.0001,G21<$J$7-0.0001),AND(G21>=$K$6-0.0001,G21<$K$7-0.0001)),1,0) -> 0 | N21: =IFERROR(INDEX($B$10:$E$10,1,MATCH(999999,$B21:$E21)),"-") -> AM | O21: =IF(G21=0,"",G21) -> 0.375 | P21: =SUM(B21:E21) -> 23 | Q21: =P21*L21 -> 0 | S21: 0.375 | T21: 23 | U21: 0
A22: 0.38541667 | B22: 18 | G22: =A22 -> 0.38541667 | H22: =IF(B22<>0,SUMIF($G$11:$G22,">"&$G22-1/24,B$11:B22),0) -> 95 | I22: =IF(C22<>0,SUMIF($G$11:$G22,">"&$G22-1/24,C$11:C22),0) -> 0 | J22: =IF(D22<>0,SUMIF($G$11:$G22,">"&$G22-1/24,D$11:D22),0) -> 0 | K22: =IF(E22<>0,SUMIF($G$11:$G22,">"&$G22-1/24,E$11:E22),0) -> 0 | L22: =IF(OR(AND(G22>=$H$6-0.0001,G22<$H$7-0.0001),AND(G22>=$I$6-0.0001,G22<$I$7-0.0001),AND(G22>=$J$6-0.0001,G22<$J$7-0.0001),AND(G22>=$K$6-0.0001,G22<$K$7-0.0001)),1,0) -> 0 | N22: =IFERROR(INDEX($B$10:$E$10,1,MATCH(999999,$B22:$E22)),"-") -> AM | O22: =IF(G22=0,"",G22) -> 0.38541667 | P22: =SUM(B22:E22) -> 18 | Q22: =P22*L22 -> 0 | S22: 0.38541667 | T22: 18 | U22: 0
A23: 0.45833333 | C23: 31 | G23: =A23 -> 0.45833333 | H23: =IF(B23<>0,SUMIF($G$11:$G23,">"&$G23-1/24,B$11:B23),0) -> 0 | I23: =IF(C23<>0,SUMIF($G$11:$G23,">"&$G23-1/24,C$11:C23),0) -> 31 | J23: =IF(D23<>0,SUMIF($G$11:$G23,">"&$G23-1/24,D$11:D23),0) -> 0 | K23: =IF(E23<>0,SUMIF($G$11:$G23,">"&$G23-1/24,E$11:E23),0) -> 0 | L23: =IF(OR(AND(G23>=$H$6-0.0001,G23<$H$7-0.0001),AND(G23>=$I$6-0.0001,G23<$I$7-0.0001),AND(G23>=$J$6-0.0001,G23<$J$7-0.0001),AND(G23>=$K$6-0.0001,G23<$K$7-0.0001)),1,0) -> 0 | N23: =IFERROR(INDEX($B$10:$E$10,1,MATCH(999999,$B23:$E23)),"-") -> INT | O23: =IF(G23=0,"",G23) -> 0.45833333 | P23: =SUM(B23:E23) -> 31 | Q23: =P23*L23 -> 0 | S23: Grand Total | T23: 274 | U23: 125
A24: 0.46875 | C24: 22 | G24: =A24 -> 0.46875 | H24: =IF(B24<>0,SUMIF($G$11:$G24,">"&$G24-1/24,B$11:B24),0) -> 0 | I24: =IF(C24<>0,SUMIF($G$11:$G24,">"&$G24-1/24,C$11:C24),0) -> 53 | J24: =IF(D24<>0,SUMIF($G$11:$G24,">"&$G24-1/24,D$11:D24),0) -> 0 | K24: =IF(E24<>0,SUMIF($G$11:$G24,">"&$G24-1/24,E$11:E24),0) -> 0 | L24: =IF(OR(AND(G24>=$H$6-0.0001,G24<$H$7-0.0001),AND(G24>=$I$6-0.0001,G24<$I$7-0.0001),AND(G24>=$J$6-0.0001,G24<$J$7-0.0001),AND(G24>=$K$6-0.0001,G24<$K$7-0.0001)),1,0) -> 0 | N24: =IFERROR(INDEX($B$10:$E$10,1,MATCH(999999,$B24:$E24)),"-") -> INT | O24: =IF(G24=0,"",G24) -> 0.46875 | P24: =SUM(B24:E24) -> 22 | Q24: =P24*L24 -> 0
A25: 0.47916667 | C25: 13 | G25: =A25 -> 0.47916667 | H25: =IF(B25<>0,SUMIF($G$11:$G25,">"&$G25-1/24,B$11:B25),0) -> 0 | I25: =IF(C25<>0,SUMIF($G$11:$G25,">"&$G25-1/24,C$11:C25),0) -> 66 | J25: =IF(D25<>0,SUMIF($G$11:$G25,">"&$G25-1/24,D$11:D25),0) -> 0 | K25: =IF(E25<>0,SUMIF($G$11:$G25,">"&$G25-1/24,E$11:E25),0) -> 0 | L25: =IF(OR(AND(G25>=$H$6-0.0001,G25<$H$7-0.0001),AND(G25>=$I$6-0.0001,G25<$I$7-0.0001),AND(G25>=$J$6-0.0001,G25<$J$7-0.0001),AND(G25>=$K$6-0.0001,G25<$K$7-0.0001)),1,0) -> 0 | N25: =IFERROR(INDEX($B$10:$E$10,1,MATCH(999999,$B25:$E25)),"-") -> INT | O25: =IF(G25=0,"",G25) -> 0.47916667 | P25: =SUM(B25:E25) -> 13 | Q25: =P25*L25 -> 0
A26: 0.48958333 | C26: 22 | G26: =A26 -> 0.48958333 | H26: =IF(B26<>0,SUMIF($G$11:$G26,">"&$G26-1/24,B$11:B26),0) -> 0 | I26: =IF(C26<>0,SUMIF($G$11:$G26,">"&$G26-1/24,C$11:C26),0) -> 88 | J26: =IF(D26<>0,SUMIF($G$11:$G26,">"&$G26-1/24,D$11:D26),0) -> 0 | K26: =IF(E26<>0,SUMIF($G$11:$G26,">"&$G26-1/24,E$11:E26),0) -> 0 | L26: =IF(OR(AND(G26>=$H$6-0.0001,G26<$H$7-0.0001),AND(G26>=$I$6-0.0001,G26<$I$7-0.0001),AND(G26>=$J$6-0.0001,G26<$J$7-0.0001),AND(G26>=$K$6-0.0001,G26<$K$7-0.0001)),1,0) -> 0 | N26: =IFERROR(INDEX($B$10:$E$10,1,MATCH(999999,$B26:$E26)),"-") -> INT | O26: =IF(G26=0,"",G26) -> 0.48958333 | P26: =SUM(B26:E26) -> 22 | Q26: =P26*L26 -> 0
A27: 0.5 | C27: 21 | G27: =A27 -> 0.5 | H27: =IF(B27<>0,SUMIF($G$11:$G27,">"&$G27-1/24,B$11:B27),0) -> 0 | I27: =IF(C27<>0,SUMIF($G$11:$G27,">"&$G27-1/24,C$11:C27),0) -> 78 | J27: =IF(D27<>0,SUMIF($G$11:$G27,">"&$G27-1/24,D$11:D27),0) -> 0 | K27: =IF(E27<>0,SUMIF($G$11:$G27,">"&$G27-1/24,E$11:E27),0) -> 0 | L27: =IF(OR(AND(G27>=$H$6-0.0001,G27<$H$7-0.0001),AND(G27>=$I$6-0.0001,G27<$I$7-0.0001),AND(G27>=$J$6-0.0001,G27<$J$7-0.0001),AND(G27>=$K$6-0.0001,G27<$K$7-0.0001)),1,0) -> 0 | N27: =IFERROR(INDEX($B$10:$E$10,1,MATCH(999999,$B27:$E27)),"-") -> INT | O27: =IF(G27=0,"",G27) -> 0.5 | P27: =SUM(B27:E27) -> 21 | Q27: =P27*L27 -> 0
A28: 0.51041667 | C28: 27 | G28: =A28 -> 0.51041667 | H28: =IF(B28<>0,SUMIF($G$11:$G28,">"&$G28-1/24,B$11:B28),0) -> 0 | I28: =IF(C28<>0,SUMIF($G$11:$G28,">"&$G28-1/24,C$11:C28),0) -> 83 | J28: =IF(D28<>0,SUMIF($G$11:$G28,">"&$G28-1/24,D$11:D28),0) -> 0 | K28: =IF(E28<>0,SUMIF($G$11:$G28,">"&$G28-1/24,E$11:E28),0) -> 0 | L28: =IF(OR(AND(G28>=$H$6-0.0001,G28<$H$7-0.0001),AND(G28>=$I$6-0.0001,G28<$I$7-0.0001),AND(G28>=$J$6-0.0001,G28<$J$7-0.0001),AND(G28>=$K$6-0.0001,G28<$K$7-0.0001)),1,0) -> 0 | N28: =IFERROR(INDEX($B$10:$E$10,1,MATCH(999999,$B28:$E28)),"-") -> INT | O28: =IF(G28=0,"",G28) -> 0.51041667 | P28: =SUM(B28:E28) -> 27 | Q28: =P28*L28 -> 0
A29: 0.52083333 | C29: 32 | G29: =A29 -> 0.52083333 | H29: =IF(B29<>0,SUMIF($G$11:$G29,">"&$G29-1/24,B$11:B29),0) -> 0 | I29: =IF(C29<>0,SUMIF($G$11:$G29,">"&$G29-1/24,C$11:C29),0) -> 102 | J29: =IF(D29<>0,SUMIF($G$11:$G29,">"&$G29-1/24,D$11:D29),0) -> 0 | K29: =IF(E29<>0,SUMIF($G$11:$G29,">"&$G29-1/24,E$11:E29),0) -> 0 | L29: =IF(OR(AND(G29>=$H$6-0.0001,G29<$H$7-0.0001),AND(G29>=$I$6-0.0001,G29<$I$7-0.0001),AND(G29>=$J$6-0.0001,G29<$J$7-0.0001),AND(G29>=$K$6-0.0001,G29<$K$7-0.0001)),1,0) -> 1 | N29: =IFERROR(INDEX($B$10:$E$10,1,MATCH(999999,$B29:$E29)),"-") -> INT | O29: =IF(G29=0,"",G29) -> 0.52083333 | P29: =SUM(B29:E29) -> 32 | Q29: =P29*L29 -> 32
A30: 0.53125 | C30: 30 | G30: =A30 -> 0.53125 | H30: =IF(B30<>0,SUMIF($G$11:$G30,">"&$G30-1/24,B$11:B30),0) -> 0 | I30: =IF(C30<>0,SUMIF($G$11:$G30,">"&$G30-1/24,C$11:C30),0) -> 110 | J30: =IF(D30<>0,SUMIF($G$11:$G30,">"&$G30-1/24,D$11:D30),0) -> 0 | K30: =IF(E30<>0,SUMIF($G$11:$G30,">"&$G30-1/24,E$11:E30),0) -> 0 | L30: =IF(OR(AND(G30>=$H$6-0.0001,G30<$H$7-0.0001),AND(G30>=$I$6-0.0001,G30<$I$7-0.0001),AND(G30>=$J$6-0.0001,G30<$J$7-0.0001),AND(G30>=$K$6-0.0001,G30<$K$7-0.0001)),1,0) -> 1 | N30: =IFERROR(INDEX($B$10:$E$10,1,MATCH(999999,$B30:$E30)),"-") -> INT | O30: =IF(G30=0,"",G30) -> 0.53125 | P30: =SUM(B30:E30) -> 30 | Q30: =P30*L30 -> 30
A31: 0.54166667 | C31: 25 | G31: =A31 -> 0.54166667 | H31: =IF(B31<>0,SUMIF($G$11:$G31,">"&$G31-1/24,B$11:B31),0) -> 0 | I31: =IF(C31<>0,SUMIF($G$11:$G31,">"&$G31-1/24,C$11:C31),0) -> 114 | J31: =IF(D31<>0,SUMIF($G$11:$G31,">"&$G31-1/24,D$11:D31),0) -> 0 | K31: =IF(E31<>0,SUMIF($G$11:$G31,">"&$G31-1/24,E$11:E31),0) -> 0 | L31: =IF(OR(AND(G31>=$H$6-0.0001,G31<$H$7-0.0001),AND(G31>=$I$6-0.0001,G31<$I$7-0.0001),AND(G31>=$J$6-0.0001,G31<$J$7-0.0001),AND(G31>=$K$6-0.0001,G31<$K$7-0.0001)),1,0) -> 1 | N31: =IFERROR(INDEX($B$10:$E$10,1,MATCH(999999,$B31:$E31)),"-") -> INT | O31: =IF(G31=0,"",G31) -> 0.54166667 | P31: =SUM(B31:E31) -> 25 | Q31: =P31*L31 -> 25
A32: 0.55208333 | C32: 28 | G32: =A32 -> 0.55208333 | H32: =IF(B32<>0,SUMIF($G$11:$G32,">"&$G32-1/24,B$11:B32),0) -> 0 | I32: =IF(C32<>0,SUMIF($G$11:$G32,">"&$G32-1/24,C$11:C32),0) -> 115 | J32: =IF(D32<>0,SUMIF($G$11:$G32,">"&$G32-1/24,D$11:D32),0) -> 0 | K32: =IF(E32<>0,SUMIF($G$11:$G32,">"&$G32-1/24,E$11:E32),0) -> 0 | L32: =IF(OR(AND(G32>=$H$6-0.0001,G32<$H$7-0.0001),AND(G32>=$I$6-0.0001,G32<$I$7-0.0001),AND(G32>=$J$6-0.0001,G32<$J$7-0.0001),AND(G32>=$K$6-0.0001,G32<$K$7-0.0001)),1,0) -> 1 | N32: =IFERROR(INDEX($B$10:$E$10,1,MATCH(999999,$B32:$E32)),"-") -> INT | O32: =IF(G32=0,"",G32) -> 0.55208333 | P32: =SUM(B32:E32) -> 28 | Q32: =P32*L32 -> 28
A33: 0.5625 | C33: 25 | G33: =A33 -> 0.5625 | H33: =IF(B33<>0,SUMIF($G$11:$G33,">"&$G33-1/24,B$11:B33),0) -> 0 | I33: =IF(C33<>0,SUMIF($G$11:$G33,">"&$G33-1/24,C$11:C33),0) -> 108 | J33: =IF(D33<>0,SUMIF($G$11:$G33,">"&$G33-1/24,D$11:D33),0) -> 0 | K33: =IF(E33<>0,SUMIF($G$11:$G33,">"&$G33-1/24,E$11:E33),0) -> 0 | L33: =IF(OR(AND(G33>=$H$6-0.0001,G33<$H$7-0.0001),AND(G33>=$I$6-0.0001,G33<$I$7-0.0001),AND(G33>=$J$6-0.0001,G33<$J$7-0.0001),AND(G33>=$K$6-0.0001,G33<$K$7-0.0001)),1,0) -> 0 | N33: =IFERROR(INDEX($B$10:$E$10,1,MATCH(999999,$B33:$E33)),"-") -> INT | O33: =IF(G33=0,"",G33) -> 0.5625 | P33: =SUM(B33:E33) -> 25 | Q33: =P33*L33 -> 0
A34: 0.57291667 | C34: 27 | G34: =A34 -> 0.57291667 | H34: =IF(B34<>0,SUMIF($G$11:$G34,">"&$G34-1/24,B$11:B34),0) -> 0 | I34: =IF(C34<>0,SUMIF($G$11:$G34,">"&$G34-1/24,C$11:C34),0) -> 105 | J34: =IF(D34<>0,SUMIF($G$11:$G34,">"&$G34-1/24,D$11:D34),0) -> 0 | K34: =IF(E34<>0,SUMIF($G$11:$G34,">"&$G34-1/24,E$11:E34),0) -> 0 | L34: =IF(OR(AND(G34>=$H$6-0.0001,G34<$H$7-0.0001),AND(G34>=$I$6-0.0001,G34<$I$7-0.0001),AND(G34>=$J$6-0.0001,G34<$J$7-0.0001),AND(G34>=$K$6-0.0001,G34<$K$7-0.0001)),1,0) -> 0 | N34: =IFERROR(INDEX($B$10:$E$10,1,MATCH(999999,$B34:$E34)),"-") -> INT | O34: =IF(G34=0,"",G34) -> 0.57291667 | P34: =SUM(B34:E34) -> 27 | Q34: =P34*L34 -> 0
A35: 0.625 | D35: 40 | G35: =A35 -> 0.625 | H35: =IF(B35<>0,SUMIF($G$11:$G35,">"&$G35-1/24,B$11:B35),0) -> 0 | I35: =IF(C35<>0,SUMIF($G$11:$G35,">"&$G35-1/24,C$11:C35),0) -> 0 | J35: =IF(D35<>0,SUMIF($G$11:$G35,">"&$G35-1/24,D$11:D35),0) -> 40 | K35: =IF(E35<>0,SUMIF($G$11:$G35,">"&$G35-1/24,E$11:E35),0) -> 0 | L35: =IF(OR(AND(G35>=$H$6-0.0001,G35<$H$7-0.0001),AND(G35>=$I$6-0.0001,G35<$I$7-0.0001),AND(G35>=$J$6-0.0001,G35<$J$7-0.0001),AND(G35>=$K$6-0.0001,G35<$K$7-0.0001)),1,0) -> 0 | N35: =IFERROR(INDEX($B$10:$E$10,1,MATCH(999999,$B35:$E35)),"-") -> PM | O35: =IF(G35=0,"",G35) -> 0.625 | P35: =SUM(B35:E35) -> 40 | Q35: =P35*L35 -> 0
A36: 0.63541667 | D36: 42 | G36: =A36 -> 0.63541667 | H36: =IF(B36<>0,SUMIF($G$11:$G36,">"&$G36-1/24,B$11:B36),0) -> 0 | I36: =IF(C36<>0,SUMIF($G$11:$G36,">"&$G36-1/24,C$11:C36),0) -> 0 | J36: =IF(D36<>0,SUMIF($G$11:$G36,">"&$G36-1/24,D$11:D36),0) -> 82 | K36: =IF(E36<>0,SUMIF($G$11:$G36,">"&$G36-1/24,E$11:E36),0) -> 0 | L36: =IF(OR(AND(G36>=$H$6-0.0001,G36<$H$7-0.0001),AND(G36>=$I$6-0.0001,G36<$I$7-0.0001),AND(G36>=$J$6-0.0001,G36<$J$7-0.0001),AND(G36>=$K$6-0.0001,G36<$K$7-0.0001)),1,0) -> 0 | N36: =IFERROR(INDEX($B$10:$E$10,1,MATCH(999999,$B36:$E36)),"-") -> PM | O36: =IF(G36=0,"",G36) -> 0.63541667 | P36: =SUM(B36:E36) -> 42 | Q36: =P36*L36 -> 0
A37: 0.64583333 | D37: 46 | G37: =A37 -> 0.64583333 | H37: =IF(B37<>0,SUMIF($G$11:$G37,">"&$G37-1/24,B$11:B37),0) -> 0 | I37: =IF(C37<>0,SUMIF($G$11:$G37,">"&$G37-1/24,C$11:C37),0) -> 0 | J37: =IF(D37<>0,SUMIF($G$11:$G37,">"&$G37-1/24,D$11:D37),0) -> 128 | K37: =IF(E37<>0,SUMIF($G$11:$G37,">"&$G37-1/24,E$11:E37),0) -> 0 | L37: =IF(OR(AND(G37>=$H$6-0.0001,G37<$H$7-0.0001),AND(G37>=$I$6-0.0001,G37<$I$7-0.0001),AND(G37>=$J$6-0.0001,G37<$J$7-0.0001),AND(G37>=$K$6-0.0001,G37<$K$7-0.0001)),1,0) -> 0 | N37: =IFERROR(INDEX($B$10:$E$10,1,MATCH(999999,$B37:$E37)),"-") -> PM | O37: =IF(G37=0,"",G37) -> 0.64583333 | P37: =SUM(B37:E37) -> 46 | Q37: =P37*L37 -> 0
A38: 0.65625 | D38: 44 | G38: =A38 -> 0.65625 | H38: =IF(B38<>0,SUMIF($G$11:$G38,">"&$G38-1/24,B$11:B38),0) -> 0 | I38: =IF(C38<>0,SUMIF($G$11:$G38,">"&$G38-1/24,C$11:C38),0) -> 0 | J38: =IF(D38<>0,SUMIF($G$11:$G38,">"&$G38-1/24,D$11:D38),0) -> 172 | K38: =IF(E38<>0,SUMIF($G$11:$G38,">"&$G38-1/24,E$11:E38),0) -> 0 | L38: =IF(OR(AND(G38>=$H$6-0.0001,G38<$H$7-0.0001),AND(G38>=$I$6-0.0001,G38<$I$7-0.0001),AND(G38>=$J$6-0.0001,G38<$J$7-0.0001),AND(G38>=$K$6-0.0001,G38<$K$7-0.0001)),1,0) -> 0 | N38: =IFERROR(INDEX($B$10:$E$10,1,MATCH(999999,$B38:$E38)),"-") -> PM | O38: =IF(G38=0,"",G38) -> 0.65625 | P38: =SUM(B38:E38) -> 44 | Q38: =P38*L38 -> 0
A39: 0.66666667 | D39: 44 | G39: =A39 -> 0.66666667 | H39: =IF(B39<>0,SUMIF($G$11:$G39,">"&$G39-1/24,B$11:B39),0) -> 0 | I39: =IF(C39<>0,SUMIF($G$11:$G39,">"&$G39-1/24,C$11:C39),0) -> 0 | J39: =IF(D39<>0,SUMIF($G$11:$G39,">"&$G39-1/24,D$11:D39),0) -> 176 | K39: =IF(E39<>0,SUMIF($G$11:$G39,">"&$G39-1/24,E$11:E39),0) -> 0 | L39: =IF(OR(AND(G39>=$H$6-0.0001,G39<$H$7-0.0001),AND(G39>=$I$6-0.0001,G39<$I$7-0.0001),AND(G39>=$J$6-0.0001,G39<$J$7-0.0001),AND(G39>=$K$6-0.0001,G39<$K$7-0.0001)),1,0) -> 0 | N39: =IFERROR(INDEX($B$10:$E$10,1,MATCH(999999,$B39:$E39)),"-") -> PM | O39: =IF(G39=0,"",G39) -> 0.66666667 | P39: =SUM(B39:E39) -> 44 | Q39: =P39*L39 -> 0
A40: 0.67708333 | D40: 41 | G40: =A40 -> 0.67708333 | H40: =IF(B40<>0,SUMIF($G$11:$G40,">"&$G40-1/24,B$11:B40),0) -> 0 | I40: =IF(C40<>0,SUMIF($G$11:$G40,">"&$G40-1/24,C$11:C40),0) -> 0 | J40: =IF(D40<>0,SUMIF($G$11:$G40,">"&$G40-1/24,D$11:D40),0) -> 175 | K40: =IF(E40<>0,SUMIF($G$11:$G40,">"&$G40-1/24,E$11:E40),0) -> 0 | L40: =IF(OR(AND(G40>=$H$6-0.0001,G40<$H$7-0.0001),AND(G40>=$I$6-0.0001,G40<$I$7-0.0001),AND(G40>=$J$6-0.0001,G40<$J$7-0.0001),AND(G40>=$K$6-0.0001,G40<$K$7-0.0001)),1,0) -> 0 | N40: =IFERROR(INDEX($B$10:$E$10,1,MATCH(999999,$B40:$E40)),"-") -> PM | O40: =IF(G40=0,"",G40) -> 0.67708333 | P40: =SUM(B40:E40) -> 41 | Q40: =P40*L40 -> 0
A41: 0.6875 | D41: 58 | G41: =A41 -> 0.6875 | H41: =IF(B41<>0,SUMIF($G$11:$G41,">"&$G41-1/24,B$11:B41),0) -> 0 | I41: =IF(C41<>0,SUMIF($G$11:$G41,">"&$G41-1/24,C$11:C41),0) -> 0 | J41: =IF(D41<>0,SUMIF($G$11:$G41,">"&$G41-1/24,D$11:D41),0) -> 187 | K41: =IF(E41<>0,SUMIF($G$11:$G41,">"&$G41-1/24,E$11:E41),0) -> 0 | L41: =IF(OR(AND(G41>=$H$6-0.0001,G41<$H$7-0.0001),AND(G41>=$I$6-0.0001,G41<$I$7-0.0001),AND(G41>=$J$6-0.0001,G41<$J$7-0.0001),AND(G41>=$K$6-0.0001,G41<$K$7-0.0001)),1,0) -> 1 | N41: =IFERROR(INDEX($B$10:$E$10,1,MATCH(999999,$B41:$E41)),"-") -> PM | O41: =IF(G41=0,"",G41) -> 0.6875 | P41: =SUM(B41:E41) -> 58 | Q41: =P41*L41 -> 58
A42: 0.69791667 | D42: 51 | G42: =A42 -> 0.69791667 | H42: =IF(B42<>0,SUMIF($G$11:$G42,">"&$G42-1/24,B$11:B42),0) -> 0 | I42: =IF(C42<>0,SUMIF($G$11:$G42,">"&$G42-1/24,C$11:C42),0) -> 0 | J42: =IF(D42<>0,SUMIF($G$11:$G42,">"&$G42-1/24,D$11:D42),0) -> 194 | K42: =IF(E42<>0,SUMIF($G$11:$G42,">"&$G42-1/24,E$11:E42),0) -> 0 | L42: =IF(OR(AND(G42>=$H$6-0.0001,G42<$H$7-0.0001),AND(G42>=$I$6-0.0001,G42<$I$7-0.0001),AND(G42>=$J$6-0.0001,G42<$J$7-0.0001),AND(G42>=$K$6-0.0001,G42<$K$7-0.0001)),1,0) -> 1 | N42: =IFERROR(INDEX($B$10:$E$10,1,MATCH(999999,$B42:$E42)),"-") -> PM | O42: =IF(G42=0,"",G42) -> 0.69791667 | P42: =SUM(B42:E42) -> 51 | Q42: =P42*L42 -> 51
...

Sheet GraphData
B2: Survey Period | C2: AM
E3: ="Vehicle Count for "&$C$2&" Period" -> Vehicle Count for AM Period
B4: Row Labels | C4: Sum of Count | E4: ="Vehicle Count by Approach Leg for "&C2&" Period" -> Vehicle Count by Approach Leg for AM Period
B5: 0.27083333 | C5: 9 | E5: ="Vehicle Count by Exit Leg for "&C2&" Period" -> Vehicle Count by Exit Leg for AM Period
B6: 0.28125 | C6: 11
B7: 0.29166667 | C7: 26
B8: 0.30208333 | C8: 17
B9: 0.3125 | C9: 18
B10: 0.32291667 | C10: 37
B11: 0.33333333 | C11: 36
B12: 0.34375 | C12: 25
B13: 0.35416667 | C13: 27
B14: 0.36458333 | C14: 27
B15: 0.375 | C15: 23
B16: 0.38541667 | C16: 18

Sheet Graphs
B2: Vehicle Counts
B4: Select Survey Period to view
J24: Approach Leg | S24: Exit Leg
C25: Total | K25: Colombo Street North | L25: Colombo Street South | M25: Moorhouse Avenue East | N25: Moorhouse Avenue West | T25: 0
B26: 0.27083333 | C26: 9 | J26: 0.27083333 | K26: 3 | L26: 3 | M26: 2 | N26: 1 | S26: 0.27083333 | T26: 9
B27: 0.28125 | C27: 11 | J27: 0.28125 | K27: 2 | L27: 0 | M27: 9 | N27: 0 | S27: 0.28125 | T27: 11
B28: 0.29166667 | C28: 26 | J28: 0.29166667 | K28: 1 | L28: 4 | M28: 16 | N28: 5 | S28: 0.29166667 | T28: 26
B29: 0.30208333 | C29: 17 | J29: 0.30208333 | K29: 1 | L29: 1 | M29: 9 | N29: 6 | S29: 0.30208333 | T29: 17
B30: 0.3125 | C30: 18 | J30: 0.3125 | K30: 2 | L30: 3 | M30: 4 | N30: 9 | S30: 0.3125 | T30: 18
B31: 0.32291667 | C31: 37 | J31: 0.32291667 | K31: 1 | L31: 1 | M31: 25 | N31: 10 | S31: 0.32291667 | T31: 37
B32: 0.33333333 | C32: 36 | J32: 0.33333333 | K32: 0 | L32: 0 | M32: 25 | N32: 11 | S32: 0.33333333 | T32: 36
B33: 0.34375 | C33: 25 | J33: 0.34375 | K33: 2 | L33: 2 | M33: 13 | N33: 8 | S33: 0.34375 | T33: 25
B34: 0.35416667 | C34: 27 | J34: 0.35416667 | K34: 5 | L34: 3 | M34: 14 | N34: 5 | S34: 0.35416667 | T34: 27
B35: 0.36458333 | C35: 27 | J35: 0.36458333 | K35: 2 | L35: 2 | M35: 14 | N35: 9 | S35: 0.36458333 | T35: 27
B36: 0.375 | C36: 23 | J36: 0.375 | K36: 8 | L36: 2 | M36: 5 | N36: 8 | S36: 0.375 | T36: 23
B37: 0.38541667 | C37: 18 | J37: 0.38541667 | K37: 3 | L37: 5 | M37: 6 | N37: 4 | S37: 0.38541667 | T37: 18
B38: Grand Total | C38: 274 | J38: Grand Total | K38: 30 | L38: 26 | M38: 142 | N38: 76 | S38: Grand Total | T38: 274

Sheet Peak Hour
B2: Peak Hour
B4: =PeakCalc!H8 -> The peak hour for AM is 125 vehicles between 07:45 and 08:45
B5: =PeakCalc!I8 -> The peak hour for INT is 115 vehicles between 12:30 and 13:30
B6: =PeakCalc!J8 -> The peak hour for PM is 255 vehicles between 16:30 and 17:30
B7: =PeakCalc!K8
B9: Select Survey Period to view
B26: Peak Hour Table
B27: Peak Marker | C27: 1
C30: AM | E30: AM Total | F30: PM | H30: PM Total | I30: INT | K30: INT Total
C31: Bicycles On Crosswalk | D31: Pedestrians | F31: Bicycles On Crosswalk | G31: Pedestrians | I31: Bicycles On Crosswalk | J31: Pedestrians
B32: Colombo Street North | C32: 5 | D32: 3 | E32: 8 | F32: 2 | G32: 22 | H32: 24 | I32: 3 | J32: 18 | K32: 21
B33: Peds CCW | C33: 3 | D33: 0 | E33: 3 | F33: 2 | G33: 5 | H33: 7 | I33: 2 | J33: 12 | K33: 14
B34: Peds CW | C34: 2 | D34: 3 | E34: 5 | F34: 0 | G34: 17 | H34: 17 | I34: 1 | J34: 6 | K34: 7
B35: Moorhouse Avenue East | C35: 23 | D35: 54 | E35: 77 | F35: 98 | G35: 63 | H35: 161 | I35: 5 | J35: 32 | K35: 37
B36: Peds CCW | C36: 4 | D36: 51 | E36: 55 | F36: 3 | G36: 12 | H36: 15 | I36: 1 | J36: 16 | K36: 17
B37: Peds CW | C37: 19 | D37: 3 | E37: 22 | F37: 95 | G37: 51 | H37: 146 | I37: 4 | J37: 16 | K37: 20
B38: Colombo Street South | C38: 0 | D38: 6 | E38: 6 | F38: 0 | G38: 20 | H38: 20 | I38: 0 | J38: 16 | K38: 16
B39: Peds CCW | C39: 0 | D39: 3 | E39: 3 | F39: 0 | G39: 10 | H39: 10 | I39: 0 | J39: 8 | K39: 8
B40: Peds CW | C40: 0 | D40: 3 | E40: 3 | F40: 0 | G40: 10 | H40: 10 | I40: 0 | J40: 8 | K40: 8
B41: Moorhouse Avenue West | C41: 2 | D41: 32 | E41: 34 | F41: 4 | G41: 46 | H41: 50 | I41: 0 | J41: 41 | K41: 41
B42: Peds CCW | C42: 1 | D42: 3 | E42: 4 | F42: 1 | G42: 26 | H42: 27 | I42: 0 | J42: 22 | K42: 22
B43: Peds CW | C43: 1 | D43: 29 | E43: 30 | F43: 3 | G43: 20 | H43: 23 | I43: 0 | J43: 19 | K43: 19
B44: Grand Total | C44: 30 | D44: 95 | E44: 125 | F44: 104 | G44: 151 | H44: 255 | I44: 8 | J44: 107 | K44: 115

Sheet Bicycles on Crosswalk
A1: Study Name | C1: CCC I2976 Colombo - Moorhouse
A2: Start Date | C2: 05/31/2022
A3: Start Time | C3: 6:30 AM
A4: Site Code
A5: Project
A10: Type | C10: Crosswalk
A11: Classification | C11: Bicycles on Crosswalk
B12: Colombo St Southbound | E12: n/a | H12: Moorhouse Ave Westbound | K12: n/a | N12: Colombo St Northbound | Q12: n/a | T12: Moorhouse Ave Eastbound | W12: n/a
B13: Southbound | E13: Southwestbound | H13: Westbound | K13: Northwestbound | N13: Northbound | Q13: Northeastbound | T13: Eastbound | W13: Southeastbound
A14: Start Time | B14: Peds CW | C14: Peds CCW | D14: Peds Combined | E14: Peds SEB | F14: Peds NWB | G14: Peds Combined | H14: Peds CW | I14: Peds CCW | J14: Peds Combined | K14: Peds SWB | L14: Peds NEB | M14: Peds Combined | N14: Peds CW | O14: Peds CCW | P14: Peds Combined | Q14: Peds NWB | R14: Peds SEB | S14: Peds Combined | T14: Peds CW | U14: Peds CCW | V14: Peds Combined | W14: Peds NEB | X14: Peds SWB | Y14: Peds Combined
A15: 6:30 AM | B15: 1 | C15: 0 | H15: 0 | I15: 0 | N15: 0 | O15: 0 | T15: 0 | U15: 0
A16: 6:45 AM | B16: 1 | C16: 0 | H16: 0 | I16: 0 | N16: 0 | O16: 0 | T16: 0 | U16: 0
A17: 7:00 AM | B17: 0 | C17: 1 | H17: 3 | I17: 0 | N17: 0 | O17: 0 | T17: 1 | U17: 0
A18: 7:15 AM | B18: 0 | C18: 0 | H18: 0 | I18: 0 | N18: 0 | O18: 0 | T18: 0 | U18: 0
A19: 7:30 AM | B19: 1 | C19: 0 | H19: 1 | I19: 0 | N19: 0 | O19: 1 | T19: 0 | U19: 0
A20: 7:45 AM | B20: 0 | C20: 1 | H20: 6 | I20: 1 | N20: 0 | O20: 0 | T20: 1 | U20: 1
A21: 8:00 AM | B21: 0 | C21: 0 | H21: 8 | I21: 1 | N21: 0 | O21: 0 | T21: 0 | U21: 0
A22: 8:15 AM | B22: 1 | C22: 1 | H22: 4 | I22: 1 | N22: 0 | O22: 0 | T22: 0 | U22: 0
A23: 8:30 AM | B23: 1 | C23: 1 | H23: 1 | I23: 1 | N23: 0 | O23: 0 | T23: 0 | U23: 0
A24: 8:45 AM | B24: 0 | C24: 0 | H24: 1 | I24: 1 | N24: 0 | O24: 0 | T24: 1 | U24: 0
A25: 9:00 AM | B25: 0 | C25: 1 | H25: 0 | I25: 0 | N25: 0 | O25: 0 | T25: 0 | U25: 0
A26: 9:15 AM | B26: 0 | C26: 1 | H26: 0 | I26: 0 | N26: 0 | O26: 0 | T26: 0 | U26: 0
... A52: 6:15 PM | B52: 1 | C52: 0 | H52: 8 | I52: 0 | N52: 0 | O52: 0 | T52: 0 | U52: 0

Sheet Pedestrians
A1: Study Name | C1: CCC I2976 Colombo - Moorhouse
A2: Start Date | C2: 05/31/2022
A3: Start Time | C3: 6:30 AM
A4: Site Code
A5: Project
A10: Type | C10: Crosswalk
A11: Classification | C11: Pedestrians
B12: Colombo St Southbound | E12: n/a | H12: Moorhouse Ave Westbound | K12: n/a | N12: Colombo St Northbound | Q12: n/a | T12: Moorhouse Ave Eastbound | W12: n/a
B13: Southbound | E13: Southwestbound | H13: Westbound | K13: Northwestbound | N13: Northbound | Q13: Northeastbound | T13: Eastbound | W13: Southeastbound
A14: Start Time | B14: Peds CW | C14: Peds CCW | D14: Peds Combined | E14: Peds SEB | F14: Peds NWB | G14: Peds Combined | H14: Peds CW | I14: Peds CCW | J14: Peds Combined | K14: Peds SWB | L14: Peds NEB | M14: Peds Combined | N14: Peds CW | O14: Peds CCW | P14: Peds Combined | Q14: Peds NWB | R14: Peds SEB | S14: Peds Combined | T14: Peds CW | U14: Peds CCW | V14: Peds Combined | W14: Peds NEB | X14: Peds SWB | Y14: Peds Combined
A15: 6:30 AM | B15: 2 | C15: 0 | H15: 0 | I15: 2 | N15: 1 | O15: 2 | T15: 1 | U15: 0
A16: 6:45 AM | B16: 1 | C16: 0 | H16: 1 | I16: 8 | N16: 0 | O16: 0 | T16: 0 | U16: 0
A17: 7:00 AM | B17: 0 | C17: 0 | H17: 4 | I17: 9 | N17: 2 | O17: 2 | T17: 4 | U17: 0
A18: 7:15 AM | B18: 0 | C18: 1 | H18: 3 | I18: 6 | N18: 1 | O18: 0 | T18: 5 | U18: 1
A19: 7:30 AM | B19: 0 | C19: 1 | H19: 0 | I19: 3 | N19: 1 | O19: 1 | T19: 7 | U19: 2
A20: 7:45 AM | B20: 0 | C20: 0 | H20: 1 | I20: 17 | N20: 1 | O20: 0 | T20: 8 | U20: 0
A21: 8:00 AM | B21: 0 | C21: 0 | H21: 2 | I21: 14 | N21: 0 | O21: 0 | T21: 10 | U21: 1
A22: 8:15 AM | B22: 0 | C22: 0 | H22: 0 | I22: 8 | N22: 2 | O22: 0 | T22: 7 | U22: 1
A23: 8:30 AM | B23: 3 | C23: 0 | H23: 0 | I23: 12 | N23: 0 | O23: 3 | T23: 4 | U23: 1
A24: 8:45 AM | B24: 1 | C24: 1 | H24: 1 | I24: 11 | N24: 0 | O24: 2 | T24: 7 | U24: 1
A25: 9:00 AM | B25: 2 | C25: 5 | H25: 2 | I25: 3 | N25: 2 | O25: 0 | T25: 4 | U25: 4
A26: 9:15 AM | B26: 1 | C26: 1 | H26: 3 | I26: 3 | N26: 1 | O26: 4 | T26: 4 | U26: 0
... A52: 6:15 PM | B52: 4 | C52: 2 | H52: 3 | I52: 3 | N52: 0 | O52: 2 | T52: 3 | U52: 1
